2025-01-13 12:49:57,804 - main - ERROR - 실행 중 에러 발생: name 'GPTAnalysisStore' is not defined
2025-01-13 12:49:57,811 - main - ERROR - Traceback (most recent call last):
  File "C:\Users\oasis\Aibybit_2\src\main.py", line 74, in main
    telegram_bot = TelegramBot(
                   ^^^^^^^^^^^^
  File "C:\Users\oasis\Aibybit_2\src\telegram_bot\bot.py", line 79, in __init__
    self.ai_trader = AITrader(
                     ^^^^^^^^^
  File "C:\Users\oasis\Aibybit_2\src\ai\ai_trader.py", line 34, in __init__
    self.gpt_analyzer = GPTAnalyzer(
                        ^^^^^^^^^^^^
  File "C:\Users\oasis\Aibybit_2\src\ai\gpt_analyzer.py", line 46, in __init__
    self.analysis_store = GPTAnalysisStore()
                          ^^^^^^^^^^^^^^^^
NameError: name 'GPTAnalysisStore' is not defined

2025-01-13 12:52:49,807 - ai.trade_analyzer - ERROR - 거래 패턴 분석 중 오류: 'TradeHistoryService' object has no attribute 'load_trades'
2025-01-13 12:52:49,811 - ai.trade_analyzer - ERROR - 상세 에러: 
Traceback (most recent call last):
  File "C:\Users\oasis\Aibybit_2\src\ai\trade_analyzer.py", line 237, in analyze_patterns
    trades = self.trade_history_service.load_trades()
             ^^^^^^^^^^^^^^^^^^^^^^^^^^^^^^^^^^^^^^
AttributeError: 'TradeHistoryService' object has no attribute 'load_trades'
2025-01-13 12:54:05,252 - ai.ai_trader - ERROR - 시장 분석 중 오류: 'GPTAnalyzer' object has no attribute 'analyze'
2025-01-13 12:54:07,341 - ai.ai_trader - ERROR - 시장 분석 중 오류: 'GPTAnalyzer' object has no attribute 'analyze'
2025-01-13 12:54:09,530 - ai.ai_trader - ERROR - 시장 분석 중 오류: 'GPTAnalyzer' object has no attribute 'analyze'
2025-01-13 12:54:11,711 - ai.ai_trader - ERROR - 시장 분석 중 오류: 'GPTAnalyzer' object has no attribute 'analyze'
2025-01-13 12:59:11,120 - services.trade_store - ERROR - 거래 및 분석 조회 중 오류: No module named 'services.gpt_analysis_store'
2025-01-13 12:59:22,872 - telegram_bot.handlers.analysis_handler - ERROR - 15m 분석 중 오류: AITrader.analyze_market() takes 2 positional arguments but 3 were given
2025-01-13 12:59:25,198 - telegram_bot.handlers.analysis_handler - ERROR - 1h 분석 중 오류: AITrader.analyze_market() takes 2 positional arguments but 3 were given
2025-01-13 12:59:27,340 - telegram_bot.handlers.analysis_handler - ERROR - 4h 분석 중 오류: AITrader.analyze_market() takes 2 positional arguments but 3 were given
2025-01-13 12:59:29,383 - telegram_bot.handlers.analysis_handler - ERROR - 1d 분석 중 오류: AITrader.analyze_market() takes 2 positional arguments but 3 were given
2025-01-13 13:00:00,216 - telegram_bot.monitors.auto_analyzer - ERROR - 15m 분석 중 오류: AITrader.analyze_market() takes 2 positional arguments but 3 were given
2025-01-13 13:00:00,219 - telegram_bot.monitors.auto_analyzer - ERROR - Traceback (most recent call last):
  File "C:\Users\oasis\Aibybit_2\src\telegram_bot\monitors\auto_analyzer.py", line 139, in _run_analysis
    analysis = await self.bot.ai_trader.analyze_market(timeframe, klines)
                     ^^^^^^^^^^^^^^^^^^^^^^^^^^^^^^^^^^^^^^^^^^^^^^^^^^^^
TypeError: AITrader.analyze_market() takes 2 positional arguments but 3 were given

2025-01-13 13:00:00,371 - telegram_bot.monitors.auto_analyzer - ERROR - 1h 분석 중 오류: AITrader.analyze_market() takes 2 positional arguments but 3 were given
2025-01-13 13:00:00,373 - telegram_bot.monitors.auto_analyzer - ERROR - Traceback (most recent call last):
  File "C:\Users\oasis\Aibybit_2\src\telegram_bot\monitors\auto_analyzer.py", line 139, in _run_analysis
    analysis = await self.bot.ai_trader.analyze_market(timeframe, klines)
                     ^^^^^^^^^^^^^^^^^^^^^^^^^^^^^^^^^^^^^^^^^^^^^^^^^^^^
TypeError: AITrader.analyze_market() takes 2 positional arguments but 3 were given

2025-01-13 13:00:00,510 - telegram_bot.monitors.auto_analyzer - ERROR - 4h 분석 중 오류: AITrader.analyze_market() takes 2 positional arguments but 3 were given
2025-01-13 13:00:00,512 - telegram_bot.monitors.auto_analyzer - ERROR - Traceback (most recent call last):
  File "C:\Users\oasis\Aibybit_2\src\telegram_bot\monitors\auto_analyzer.py", line 139, in _run_analysis
    analysis = await self.bot.ai_trader.analyze_market(timeframe, klines)
                     ^^^^^^^^^^^^^^^^^^^^^^^^^^^^^^^^^^^^^^^^^^^^^^^^^^^^
TypeError: AITrader.analyze_market() takes 2 positional arguments but 3 were given

2025-01-13 13:01:41,466 - services.trade_store - ERROR - 거래 및 분석 조회 중 오류: day is out of range for month
2025-01-13 13:01:50,428 - ai.ai_trader - ERROR - 시장 분석 중 오류: 'GPTAnalyzer' object has no attribute 'analyze_market'
2025-01-13 13:01:52,533 - ai.ai_trader - ERROR - 시장 분석 중 오류: 'GPTAnalyzer' object has no attribute 'analyze_market'
2025-01-13 13:01:54,604 - ai.ai_trader - ERROR - 시장 분석 중 오류: 'GPTAnalyzer' object has no attribute 'analyze_market'
2025-01-13 13:01:56,648 - ai.ai_trader - ERROR - 시장 분석 중 오류: 'GPTAnalyzer' object has no attribute 'analyze_market'
2025-01-13 13:42:21,404 - services.trade_store - ERROR - 거래 및 분석 조회 중 오류: day is out of range for month
2025-01-13 13:42:36,071 - ai.ai_trader - ERROR - 시장 분석 중 오류: 'GPTAnalyzer' object has no attribute 'analyze_market'
2025-01-13 13:42:38,103 - ai.ai_trader - ERROR - 시장 분석 중 오류: 'GPTAnalyzer' object has no attribute 'analyze_market'
2025-01-13 13:42:40,134 - ai.ai_trader - ERROR - 시장 분석 중 오류: 'GPTAnalyzer' object has no attribute 'analyze_market'
2025-01-13 13:42:42,175 - ai.ai_trader - ERROR - 시장 분석 중 오류: 'GPTAnalyzer' object has no attribute 'analyze_market'
2025-01-13 13:43:45,080 - services.trade_store - ERROR - 거래 및 분석 조회 중 오류: day is out of range for month
2025-01-13 13:45:13,333 - indicators.technical - ERROR - 지표 계산 중 오류: 'list' object has no attribute 'empty'
2025-01-13 13:45:13,333 - ai.gpt_analyzer - ERROR - 기술적 지표 계산 실패
2025-01-13 13:45:13,334 - telegram_bot.monitors.auto_analyzer - ERROR - 15m 분석 실패
2025-01-13 13:45:41,090 - indicators.technical - ERROR - 지표 계산 중 오류: 'list' object has no attribute 'empty'
2025-01-13 13:45:41,092 - ai.gpt_analyzer - ERROR - 기술적 지표 계산 실패
2025-01-13 13:45:43,163 - indicators.technical - ERROR - 지표 계산 중 오류: 'list' object has no attribute 'empty'
2025-01-13 13:45:43,164 - ai.gpt_analyzer - ERROR - 기술적 지표 계산 실패
2025-01-13 13:45:45,246 - indicators.technical - ERROR - 지표 계산 중 오류: 'list' object has no attribute 'empty'
2025-01-13 13:45:45,247 - ai.gpt_analyzer - ERROR - 기술적 지표 계산 실패
2025-01-13 13:45:47,353 - indicators.technical - ERROR - 지표 계산 중 오류: 'list' object has no attribute 'empty'
2025-01-13 13:45:47,354 - ai.gpt_analyzer - ERROR - 기술적 지표 계산 실패
2025-01-13 13:51:10,338 - indicators.technical - ERROR - 지표 계산 중 오류: 'TechnicalIndicators' object has no attribute '_calculate_rsi'
2025-01-13 13:51:10,340 - indicators.technical - ERROR - Traceback (most recent call last):
  File "C:\Users\oasis\Aibybit_2\src\indicators\technical.py", line 29, in calculate_indicators
    df['rsi'] = self._calculate_rsi(df['close'])
                ^^^^^^^^^^^^^^^^^^^
AttributeError: 'TechnicalIndicators' object has no attribute '_calculate_rsi'. Did you mean: 'calculate_rsi'?

2025-01-13 13:51:10,341 - ai.gpt_analyzer - ERROR - 기술적 지표 계산 실패
2025-01-13 13:51:12,410 - indicators.technical - ERROR - 지표 계산 중 오류: 'TechnicalIndicators' object has no attribute '_calculate_rsi'
2025-01-13 13:51:12,414 - indicators.technical - ERROR - Traceback (most recent call last):
  File "C:\Users\oasis\Aibybit_2\src\indicators\technical.py", line 29, in calculate_indicators
    df['rsi'] = self._calculate_rsi(df['close'])
                ^^^^^^^^^^^^^^^^^^^
AttributeError: 'TechnicalIndicators' object has no attribute '_calculate_rsi'. Did you mean: 'calculate_rsi'?

2025-01-13 13:51:12,417 - ai.gpt_analyzer - ERROR - 기술적 지표 계산 실패
2025-01-13 13:51:14,719 - indicators.technical - ERROR - 지표 계산 중 오류: 'TechnicalIndicators' object has no attribute '_calculate_rsi'
2025-01-13 13:51:14,725 - indicators.technical - ERROR - Traceback (most recent call last):
  File "C:\Users\oasis\Aibybit_2\src\indicators\technical.py", line 29, in calculate_indicators
    df['rsi'] = self._calculate_rsi(df['close'])
                ^^^^^^^^^^^^^^^^^^^
AttributeError: 'TechnicalIndicators' object has no attribute '_calculate_rsi'. Did you mean: 'calculate_rsi'?

2025-01-13 13:51:14,730 - ai.gpt_analyzer - ERROR - 기술적 지표 계산 실패
2025-01-13 13:51:16,798 - indicators.technical - ERROR - 지표 계산 중 오류: 'TechnicalIndicators' object has no attribute '_calculate_rsi'
2025-01-13 13:51:16,800 - indicators.technical - ERROR - Traceback (most recent call last):
  File "C:\Users\oasis\Aibybit_2\src\indicators\technical.py", line 29, in calculate_indicators
    df['rsi'] = self._calculate_rsi(df['close'])
                ^^^^^^^^^^^^^^^^^^^
AttributeError: 'TechnicalIndicators' object has no attribute '_calculate_rsi'. Did you mean: 'calculate_rsi'?

2025-01-13 13:51:16,801 - ai.gpt_analyzer - ERROR - 기술적 지표 계산 실패
2025-01-13 13:54:09,641 - telegram_bot.handlers.stats_handler - ERROR - 통계 처리 중 오류: 'TradeAnalyzer' object has no attribute 'analyze_patterns'
2025-01-13 13:54:19,766 - ai.gpt_analyzer - ERROR - 시장 분석 중 오류: 'GPTAnalyzer' object has no attribute '_determine_trend'
2025-01-13 13:54:19,771 - ai.gpt_analyzer - ERROR - Traceback (most recent call last):
  File "C:\Users\oasis\Aibybit_2\src\ai\gpt_analyzer.py", line 64, in analyze_market
    'trend': self._determine_trend(df_with_indicators),
             ^^^^^^^^^^^^^^^^^^^^^
AttributeError: 'GPTAnalyzer' object has no attribute '_determine_trend'

2025-01-13 13:54:21,825 - ai.gpt_analyzer - ERROR - 시장 분석 중 오류: 'GPTAnalyzer' object has no attribute '_determine_trend'
2025-01-13 13:54:21,830 - ai.gpt_analyzer - ERROR - Traceback (most recent call last):
  File "C:\Users\oasis\Aibybit_2\src\ai\gpt_analyzer.py", line 64, in analyze_market
    'trend': self._determine_trend(df_with_indicators),
             ^^^^^^^^^^^^^^^^^^^^^
AttributeError: 'GPTAnalyzer' object has no attribute '_determine_trend'

2025-01-13 13:54:24,033 - ai.gpt_analyzer - ERROR - 시장 분석 중 오류: 'GPTAnalyzer' object has no attribute '_determine_trend'
2025-01-13 13:54:24,036 - ai.gpt_analyzer - ERROR - Traceback (most recent call last):
  File "C:\Users\oasis\Aibybit_2\src\ai\gpt_analyzer.py", line 64, in analyze_market
    'trend': self._determine_trend(df_with_indicators),
             ^^^^^^^^^^^^^^^^^^^^^
AttributeError: 'GPTAnalyzer' object has no attribute '_determine_trend'

2025-01-13 13:54:26,094 - ai.gpt_analyzer - ERROR - 시장 분석 중 오류: 'GPTAnalyzer' object has no attribute '_determine_trend'
2025-01-13 13:54:26,097 - ai.gpt_analyzer - ERROR - Traceback (most recent call last):
  File "C:\Users\oasis\Aibybit_2\src\ai\gpt_analyzer.py", line 64, in analyze_market
    'trend': self._determine_trend(df_with_indicators),
             ^^^^^^^^^^^^^^^^^^^^^
AttributeError: 'GPTAnalyzer' object has no attribute '_determine_trend'

2025-01-13 13:56:04,970 - telegram_bot.handlers.stats_handler - ERROR - 통계 처리 중 오류: 'TradeAnalyzer' object has no attribute 'analyze_patterns'
2025-01-13 13:56:19,789 - ai.gpt_analyzer - ERROR - 추세 강도 계산 중 오류: 'trend_strength'
2025-01-13 13:56:19,790 - ai.gpt_analyzer - ERROR - 시장 분석 중 오류: 'GPTAnalyzer' object has no attribute '_request_gpt_analysis'
2025-01-13 13:56:19,793 - ai.gpt_analyzer - ERROR - Traceback (most recent call last):
  File "C:\Users\oasis\Aibybit_2\src\ai\gpt_analyzer.py", line 74, in analyze_market
    gpt_response = await self._request_gpt_analysis(technical_analysis)
                         ^^^^^^^^^^^^^^^^^^^^^^^^^^
AttributeError: 'GPTAnalyzer' object has no attribute '_request_gpt_analysis'

2025-01-13 13:56:22,417 - ai.gpt_analyzer - ERROR - 추세 강도 계산 중 오류: 'trend_strength'
2025-01-13 13:56:22,418 - ai.gpt_analyzer - ERROR - 시장 분석 중 오류: 'GPTAnalyzer' object has no attribute '_request_gpt_analysis'
2025-01-13 13:56:22,420 - ai.gpt_analyzer - ERROR - Traceback (most recent call last):
  File "C:\Users\oasis\Aibybit_2\src\ai\gpt_analyzer.py", line 74, in analyze_market
    gpt_response = await self._request_gpt_analysis(technical_analysis)
                         ^^^^^^^^^^^^^^^^^^^^^^^^^^
AttributeError: 'GPTAnalyzer' object has no attribute '_request_gpt_analysis'

2025-01-13 13:56:24,466 - ai.gpt_analyzer - ERROR - 추세 강도 계산 중 오류: 'trend_strength'
2025-01-13 13:56:24,468 - ai.gpt_analyzer - ERROR - 시장 분석 중 오류: 'GPTAnalyzer' object has no attribute '_request_gpt_analysis'
2025-01-13 13:56:24,473 - ai.gpt_analyzer - ERROR - Traceback (most recent call last):
  File "C:\Users\oasis\Aibybit_2\src\ai\gpt_analyzer.py", line 74, in analyze_market
    gpt_response = await self._request_gpt_analysis(technical_analysis)
                         ^^^^^^^^^^^^^^^^^^^^^^^^^^
AttributeError: 'GPTAnalyzer' object has no attribute '_request_gpt_analysis'

2025-01-13 13:56:27,429 - ai.gpt_analyzer - ERROR - 추세 강도 계산 중 오류: 'trend_strength'
2025-01-13 13:56:27,430 - ai.gpt_analyzer - ERROR - 시장 분석 중 오류: 'GPTAnalyzer' object has no attribute '_request_gpt_analysis'
2025-01-13 13:56:27,432 - ai.gpt_analyzer - ERROR - Traceback (most recent call last):
  File "C:\Users\oasis\Aibybit_2\src\ai\gpt_analyzer.py", line 74, in analyze_market
    gpt_response = await self._request_gpt_analysis(technical_analysis)
                         ^^^^^^^^^^^^^^^^^^^^^^^^^^
AttributeError: 'GPTAnalyzer' object has no attribute '_request_gpt_analysis'

2025-01-13 13:58:53,690 - telegram_bot.handlers.stats_handler - ERROR - 통계 처리 중 오류: 'TradeAnalyzer' object has no attribute 'analyze_patterns'
2025-01-13 13:59:03,361 - ai.gpt_analyzer - ERROR - GPT 분석 요청 중 오류: 'GPTClient' object has no attribute 'get_analysis'
2025-01-13 13:59:05,479 - ai.gpt_analyzer - ERROR - GPT 분석 요청 중 오류: 'GPTClient' object has no attribute 'get_analysis'
2025-01-13 13:59:07,578 - ai.gpt_analyzer - ERROR - GPT 분석 요청 중 오류: 'GPTClient' object has no attribute 'get_analysis'
2025-01-13 13:59:09,625 - ai.gpt_analyzer - ERROR - GPT 분석 요청 중 오류: 'GPTClient' object has no attribute 'get_analysis'
2025-01-13 14:00:00,251 - ai.gpt_analyzer - ERROR - GPT 분석 요청 중 오류: 'GPTClient' object has no attribute 'get_analysis'
2025-01-13 14:00:00,252 - telegram_bot.monitors.auto_analyzer - ERROR - 15m 분석 실패
2025-01-13 14:00:00,538 - ai.gpt_analyzer - ERROR - GPT 분석 요청 중 오류: 'GPTClient' object has no attribute 'get_analysis'
2025-01-13 14:00:00,539 - telegram_bot.monitors.auto_analyzer - ERROR - 1h 분석 실패
2025-01-13 14:02:05,313 - telegram_bot.handlers.stats_handler - ERROR - 통계 처리 중 오류: TradeAnalyzer.analyze_trades() got an unexpected keyword argument 'days'
2025-01-13 14:02:27,674 - ai.ai_trader - ERROR - 최종 분석 생성 중 오류: 'GPTAnalyzer' object has no attribute 'analyze_final'
2025-01-13 14:06:32,702 - ai.trade_analyzer - ERROR - 거래 패턴 분석 중 오류: 'TradeHistoryService' object has no attribute 'get_trades'
2025-01-13 14:06:32,709 - ai.trade_analyzer - ERROR - Traceback (most recent call last):
  File "C:\Users\oasis\Aibybit_2\src\ai\trade_analyzer.py", line 242, in analyze_trades
    trades = await self.trade_history_service.get_trades(start_time, end_time)
                   ^^^^^^^^^^^^^^^^^^^^^^^^^^^^^^^^^^^^^
AttributeError: 'TradeHistoryService' object has no attribute 'get_trades'. Did you mean: 'load_trades'?

2025-01-13 14:06:42,071 - ai.gpt_analyzer - ERROR - 분석할 데이터가 없습니다
2025-01-13 14:06:42,073 - ai.ai_trader - ERROR - 최종 분석 생성 실패
2025-01-13 14:12:44,344 - ai.trade_analyzer - ERROR - 거래 패턴 분석 중 오류: TradeHistoryService.load_trades() takes 1 positional argument but 3 were given
2025-01-13 14:12:44,345 - ai.trade_analyzer - ERROR - Traceback (most recent call last):
  File "C:\Users\oasis\Aibybit_2\src\ai\trade_analyzer.py", line 242, in analyze_trades
    trades = await self.trade_history_service.load_trades(start_time, end_time)
                   ^^^^^^^^^^^^^^^^^^^^^^^^^^^^^^^^^^^^^^^^^^^^^^^^^^^^^^^^^^^^
TypeError: TradeHistoryService.load_trades() takes 1 positional argument but 3 were given

2025-01-13 14:20:14,361 - ai.trade_analyzer - ERROR - 거래 패턴 분석 중 오류: 'TradeAnalyzer' object has no attribute 'trade_store'
2025-01-13 14:20:14,363 - ai.trade_analyzer - ERROR - Traceback (most recent call last):
  File "C:\Users\oasis\Aibybit_2\src\ai\trade_analyzer.py", line 246, in analyze_trades
    trades = self.trade_store.get_all_trades()
             ^^^^^^^^^^^^^^^^
AttributeError: 'TradeAnalyzer' object has no attribute 'trade_store'

2025-01-13 14:28:47,133 - ai.trade_analyzer - ERROR - 거래 패턴 분석 중 오류: 'TradeStore' object has no attribute 'get_all_trades'
2025-01-13 14:28:47,135 - ai.trade_analyzer - ERROR - Traceback (most recent call last):
  File "C:\Users\oasis\Aibybit_2\src\ai\trade_analyzer.py", line 256, in analyze_trades
    trades = self.trade_store.get_all_trades()
             ^^^^^^^^^^^^^^^^^^^^^^^^^^^^^^^
AttributeError: 'TradeStore' object has no attribute 'get_all_trades'

2025-01-13 15:11:57,245 - main - ERROR - 실행 중 에러 발생: BybitClient.__init__() got an unexpected keyword argument 'api_key'
2025-01-13 15:11:57,246 - main - ERROR - Traceback (most recent call last):
  File "C:\Users\oasis\Aibybit_2\src\main.py", line 60, in main
    bybit_client = BybitClient(
                   ^^^^^^^^^^^^
TypeError: BybitClient.__init__() got an unexpected keyword argument 'api_key'

2025-01-13 15:13:08,237 - main - ERROR - 실행 중 에러 발생: BybitClient.__init__() got an unexpected keyword argument 'api_secret'
2025-01-13 15:13:08,237 - main - ERROR - Traceback (most recent call last):
  File "C:\Users\oasis\Aibybit_2\src\main.py", line 60, in main
    bybit_client = BybitClient(
                   ^^^^^^^^^^^^
TypeError: BybitClient.__init__() got an unexpected keyword argument 'api_secret'

2025-01-13 15:15:09,576 - main - ERROR - 실행 중 에러 발생: BybitClient.__init__() got an unexpected keyword argument 'api_key'
2025-01-13 15:15:09,577 - main - ERROR - Traceback (most recent call last):
  File "C:\Users\oasis\Aibybit_2\src\main.py", line 60, in main
    bybit_client = BybitClient(
                   ^^^^^^^^^^^^
TypeError: BybitClient.__init__() got an unexpected keyword argument 'api_key'

2025-01-13 15:18:13,062 - services.trade_history_service - ERROR - 거래 내역 초기화 실패: 'TradeStore' object has no attribute 'get_all_trades'
2025-01-13 15:26:00,986 - services.trade_history_service - ERROR - 거래 내역 초기화 실패: 'BybitClient' object has no attribute 'get_closed_trades'
2025-01-13 15:27:51,836 - exchange.bybit_client - ERROR - 거래 내역 조회 API 호출 실패: bybit fetchOrders() requires until/endTime when since is provided.
2025-01-13 15:27:51,839 - exchange.bybit_client - ERROR - 거래 내역 조회 API 호출 실패: bybit fetchOrders() requires until/endTime when since is provided.
2025-01-13 15:27:51,840 - exchange.bybit_client - ERROR - 거래 내역 조회 API 호출 실패: bybit fetchOrders() requires until/endTime when since is provided.
2025-01-13 15:27:51,842 - exchange.bybit_client - ERROR - 거래 내역 조회 API 호출 실패: bybit fetchOrders() requires until/endTime when since is provided.
2025-01-13 15:27:51,843 - exchange.bybit_client - ERROR - 거래 내역 조회 API 호출 실패: bybit fetchOrders() requires until/endTime when since is provided.
2025-01-13 15:27:51,846 - exchange.bybit_client - ERROR - 거래 내역 조회 API 호출 실패: bybit fetchOrders() requires until/endTime when since is provided.
2025-01-13 15:27:51,847 - exchange.bybit_client - ERROR - 거래 내역 조회 API 호출 실패: bybit fetchOrders() requires until/endTime when since is provided.
2025-01-13 15:27:51,849 - exchange.bybit_client - ERROR - 거래 내역 조회 API 호출 실패: bybit fetchOrders() requires until/endTime when since is provided.
2025-01-13 15:27:51,851 - exchange.bybit_client - ERROR - 거래 내역 조회 API 호출 실패: bybit fetchOrders() requires until/endTime when since is provided.
2025-01-13 15:27:51,853 - exchange.bybit_client - ERROR - 거래 내역 조회 API 호출 실패: bybit fetchOrders() requires until/endTime when since is provided.
2025-01-13 15:27:51,855 - exchange.bybit_client - ERROR - 거래 내역 조회 API 호출 실패: bybit fetchOrders() requires until/endTime when since is provided.
2025-01-13 15:27:51,856 - exchange.bybit_client - ERROR - 거래 내역 조회 API 호출 실패: bybit fetchOrders() requires until/endTime when since is provided.
2025-01-13 15:27:51,858 - exchange.bybit_client - ERROR - 거래 내역 조회 API 호출 실패: bybit fetchOrders() requires until/endTime when since is provided.
