2025-03-12 13:35:58,649 - telegram.ext.Updater - ERROR - Error while getting Updates: httpx.ConnectError: [Errno 11001] getaddrinfo failed
2025-03-12 13:35:58,657 - telegram.ext.Updater - ERROR - Exception happened while polling for updates.
Traceback (most recent call last):
  File "C:\Users\oasis\Aibybit_2\.venv\Lib\site-packages\httpx\_transports\default.py", line 66, in map_httpcore_exceptions
    yield
  File "C:\Users\oasis\Aibybit_2\.venv\Lib\site-packages\httpx\_transports\default.py", line 366, in handle_async_request
    resp = await self._pool.handle_async_request(req)
           ^^^^^^^^^^^^^^^^^^^^^^^^^^^^^^^^^^^^^^^^^^
  File "C:\Users\oasis\Aibybit_2\.venv\Lib\site-packages\httpcore\_async\connection_pool.py", line 256, in handle_async_request
    raise exc from None
  File "C:\Users\oasis\Aibybit_2\.venv\Lib\site-packages\httpcore\_async\connection_pool.py", line 236, in handle_async_request
    response = await connection.handle_async_request(
               ^^^^^^^^^^^^^^^^^^^^^^^^^^^^^^^^^^^^^^
  File "C:\Users\oasis\Aibybit_2\.venv\Lib\site-packages\httpcore\_async\connection.py", line 101, in handle_async_request
    raise exc
  File "C:\Users\oasis\Aibybit_2\.venv\Lib\site-packages\httpcore\_async\connection.py", line 78, in handle_async_request
    stream = await self._connect(request)
             ^^^^^^^^^^^^^^^^^^^^^^^^^^^^
  File "C:\Users\oasis\Aibybit_2\.venv\Lib\site-packages\httpcore\_async\connection.py", line 124, in _connect
    stream = await self._network_backend.connect_tcp(**kwargs)
             ^^^^^^^^^^^^^^^^^^^^^^^^^^^^^^^^^^^^^^^^^^^^^^^^^
  File "C:\Users\oasis\Aibybit_2\.venv\Lib\site-packages\httpcore\_backends\auto.py", line 31, in connect_tcp
    return await self._backend.connect_tcp(
           ^^^^^^^^^^^^^^^^^^^^^^^^^^^^^^^^
  File "C:\Users\oasis\Aibybit_2\.venv\Lib\site-packages\httpcore\_backends\anyio.py", line 113, in connect_tcp
    with map_exceptions(exc_map):
  File "C:\Program Files\Python311\Lib\contextlib.py", line 155, in __exit__
    self.gen.throw(typ, value, traceback)
  File "C:\Users\oasis\Aibybit_2\.venv\Lib\site-packages\httpcore\_exceptions.py", line 14, in map_exceptions
    raise to_exc(exc) from exc
httpcore.ConnectError: [Errno 11001] getaddrinfo failed

The above exception was the direct cause of the following exception:

Traceback (most recent call last):
  File "C:\Users\oasis\Aibybit_2\.venv\Lib\site-packages\telegram\request\_httpxrequest.py", line 268, in do_request
    res = await self._client.request(
          ^^^^^^^^^^^^^^^^^^^^^^^^^^^
  File "C:\Users\oasis\Aibybit_2\.venv\Lib\site-packages\httpx\_client.py", line 1530, in request
    return await self.send(request, auth=auth, follow_redirects=follow_redirects)
           ^^^^^^^^^^^^^^^^^^^^^^^^^^^^^^^^^^^^^^^^^^^^^^^^^^^^^^^^^^^^^^^^^^^^^^
  File "C:\Users\oasis\Aibybit_2\.venv\Lib\site-packages\httpx\_client.py", line 1617, in send
    response = await self._send_handling_auth(
               ^^^^^^^^^^^^^^^^^^^^^^^^^^^^^^^
  File "C:\Users\oasis\Aibybit_2\.venv\Lib\site-packages\httpx\_client.py", line 1645, in _send_handling_auth
    response = await self._send_handling_redirects(
               ^^^^^^^^^^^^^^^^^^^^^^^^^^^^^^^^^^^^
  File "C:\Users\oasis\Aibybit_2\.venv\Lib\site-packages\httpx\_client.py", line 1682, in _send_handling_redirects
    response = await self._send_single_request(request)
               ^^^^^^^^^^^^^^^^^^^^^^^^^^^^^^^^^^^^^^^^
  File "C:\Users\oasis\Aibybit_2\.venv\Lib\site-packages\httpx\_client.py", line 1719, in _send_single_request
    response = await transport.handle_async_request(request)
               ^^^^^^^^^^^^^^^^^^^^^^^^^^^^^^^^^^^^^^^^^^^^^
  File "C:\Users\oasis\Aibybit_2\.venv\Lib\site-packages\httpx\_transports\default.py", line 365, in handle_async_request
    with map_httpcore_exceptions():
  File "C:\Program Files\Python311\Lib\contextlib.py", line 155, in __exit__
    self.gen.throw(typ, value, traceback)
  File "C:\Users\oasis\Aibybit_2\.venv\Lib\site-packages\httpx\_transports\default.py", line 83, in map_httpcore_exceptions
    raise mapped_exc(message) from exc
httpx.ConnectError: [Errno 11001] getaddrinfo failed

The above exception was the direct cause of the following exception:

Traceback (most recent call last):
  File "C:\Users\oasis\Aibybit_2\.venv\Lib\site-packages\telegram\ext\_updater.py", line 688, in _network_loop_retry
    if not await action_cb():
           ^^^^^^^^^^^^^^^^^
  File "C:\Users\oasis\Aibybit_2\.venv\Lib\site-packages\telegram\ext\_updater.py", line 384, in polling_action_cb
    raise exc
  File "C:\Users\oasis\Aibybit_2\.venv\Lib\site-packages\telegram\ext\_updater.py", line 373, in polling_action_cb
    updates = await self.bot.get_updates(
              ^^^^^^^^^^^^^^^^^^^^^^^^^^^
  File "C:\Users\oasis\Aibybit_2\.venv\Lib\site-packages\telegram\ext\_extbot.py", line 558, in get_updates
    updates = await super().get_updates(
              ^^^^^^^^^^^^^^^^^^^^^^^^^^
  File "C:\Users\oasis\Aibybit_2\.venv\Lib\site-packages\telegram\_bot.py", line 525, in decorator
    result = await func(self, *args, **kwargs)  # skipcq: PYL-E1102
             ^^^^^^^^^^^^^^^^^^^^^^^^^^^^^^^^^
  File "C:\Users\oasis\Aibybit_2\.venv\Lib\site-packages\telegram\_bot.py", line 3584, in get_updates
    await self._post(
  File "C:\Users\oasis\Aibybit_2\.venv\Lib\site-packages\telegram\_bot.py", line 613, in _post
    return await self._do_post(
           ^^^^^^^^^^^^^^^^^^^^
  File "C:\Users\oasis\Aibybit_2\.venv\Lib\site-packages\telegram\ext\_extbot.py", line 340, in _do_post
    return await super()._do_post(
           ^^^^^^^^^^^^^^^^^^^^^^^
  File "C:\Users\oasis\Aibybit_2\.venv\Lib\site-packages\telegram\_bot.py", line 641, in _do_post
    return await request.post(
           ^^^^^^^^^^^^^^^^^^^
  File "C:\Users\oasis\Aibybit_2\.venv\Lib\site-packages\telegram\request\_baserequest.py", line 200, in post
    result = await self._request_wrapper(
             ^^^^^^^^^^^^^^^^^^^^^^^^^^^^
  File "C:\Users\oasis\Aibybit_2\.venv\Lib\site-packages\telegram\request\_baserequest.py", line 340, in _request_wrapper
    raise exc
  File "C:\Users\oasis\Aibybit_2\.venv\Lib\site-packages\telegram\request\_baserequest.py", line 330, in _request_wrapper
    code, payload = await self.do_request(
                    ^^^^^^^^^^^^^^^^^^^^^^
  File "C:\Users\oasis\Aibybit_2\.venv\Lib\site-packages\telegram\request\_httpxrequest.py", line 292, in do_request
    raise NetworkError(f"httpx.{err.__class__.__name__}: {err}") from err
telegram.error.NetworkError: httpx.ConnectError: [Errno 11001] getaddrinfo failed
2025-03-12 14:56:24,588 - services.trade_history_service - ERROR - 포지션 조회 중 오류: 'BybitClient' object has no attribute 'fetch_my_trades'
2025-03-12 14:56:24,593 - services.trade_history_service - ERROR - Traceback (most recent call last):
  File "C:\Users\oasis\Aibybit_2\src\services\trade_history_service.py", line 273, in get_positions
    positions = await self.bybit_client.fetch_my_trades(
                      ^^^^^^^^^^^^^^^^^^^^^^^^^^^^^^^^^
AttributeError: 'BybitClient' object has no attribute 'fetch_my_trades'

2025-03-12 14:56:25,604 - services.trade_history_service - ERROR - 포지션 조회 중 오류: 'BybitClient' object has no attribute 'fetch_my_trades'
2025-03-12 14:56:25,605 - services.trade_history_service - ERROR - Traceback (most recent call last):
  File "C:\Users\oasis\Aibybit_2\src\services\trade_history_service.py", line 273, in get_positions
    positions = await self.bybit_client.fetch_my_trades(
                      ^^^^^^^^^^^^^^^^^^^^^^^^^^^^^^^^^
AttributeError: 'BybitClient' object has no attribute 'fetch_my_trades'

2025-03-12 14:56:26,607 - services.trade_history_service - ERROR - 포지션 조회 중 오류: 'BybitClient' object has no attribute 'fetch_my_trades'
2025-03-12 14:56:26,607 - services.trade_history_service - ERROR - Traceback (most recent call last):
  File "C:\Users\oasis\Aibybit_2\src\services\trade_history_service.py", line 273, in get_positions
    positions = await self.bybit_client.fetch_my_trades(
                      ^^^^^^^^^^^^^^^^^^^^^^^^^^^^^^^^^
AttributeError: 'BybitClient' object has no attribute 'fetch_my_trades'

2025-03-12 15:02:35,957 - services.trade_history_service - ERROR - 포지션 조회 중 오류: BybitClient.fetch_my_trades() got an unexpected keyword argument 'symbol'
2025-03-12 15:02:35,958 - services.trade_history_service - ERROR - Traceback (most recent call last):
  File "C:\Users\oasis\Aibybit_2\src\services\trade_history_service.py", line 273, in get_positions
    positions = await self.bybit_client.fetch_my_trades(
                      ^^^^^^^^^^^^^^^^^^^^^^^^^^^^^^^^^^
TypeError: BybitClient.fetch_my_trades() got an unexpected keyword argument 'symbol'

2025-03-12 15:02:36,971 - services.trade_history_service - ERROR - 포지션 조회 중 오류: BybitClient.fetch_my_trades() got an unexpected keyword argument 'symbol'
2025-03-12 15:02:36,972 - services.trade_history_service - ERROR - Traceback (most recent call last):
  File "C:\Users\oasis\Aibybit_2\src\services\trade_history_service.py", line 273, in get_positions
    positions = await self.bybit_client.fetch_my_trades(
                      ^^^^^^^^^^^^^^^^^^^^^^^^^^^^^^^^^^
TypeError: BybitClient.fetch_my_trades() got an unexpected keyword argument 'symbol'

2025-03-12 15:02:37,989 - services.trade_history_service - ERROR - 포지션 조회 중 오류: BybitClient.fetch_my_trades() got an unexpected keyword argument 'symbol'
2025-03-12 15:02:37,990 - services.trade_history_service - ERROR - Traceback (most recent call last):
  File "C:\Users\oasis\Aibybit_2\src\services\trade_history_service.py", line 273, in get_positions
    positions = await self.bybit_client.fetch_my_trades(
                      ^^^^^^^^^^^^^^^^^^^^^^^^^^^^^^^^^^
TypeError: BybitClient.fetch_my_trades() got an unexpected keyword argument 'symbol'

