2025-03-04 14:13:51,370 - telegram.ext.Updater - ERROR - Error while getting Updates: httpx.ConnectError: [Errno 11001] getaddrinfo failed
2025-03-04 14:13:51,373 - telegram.ext.Updater - ERROR - Exception happened while polling for updates.
Traceback (most recent call last):
  File "C:\Users\oasis\Aibybit_2\.venv\Lib\site-packages\httpx\_transports\default.py", line 66, in map_httpcore_exceptions
    yield
  File "C:\Users\oasis\Aibybit_2\.venv\Lib\site-packages\httpx\_transports\default.py", line 366, in handle_async_request
    resp = await self._pool.handle_async_request(req)
           ^^^^^^^^^^^^^^^^^^^^^^^^^^^^^^^^^^^^^^^^^^
  File "C:\Users\oasis\Aibybit_2\.venv\Lib\site-packages\httpcore\_async\connection_pool.py", line 256, in handle_async_request
    raise exc from None
  File "C:\Users\oasis\Aibybit_2\.venv\Lib\site-packages\httpcore\_async\connection_pool.py", line 236, in handle_async_request
    response = await connection.handle_async_request(
               ^^^^^^^^^^^^^^^^^^^^^^^^^^^^^^^^^^^^^^
  File "C:\Users\oasis\Aibybit_2\.venv\Lib\site-packages\httpcore\_async\connection.py", line 101, in handle_async_request
    raise exc
  File "C:\Users\oasis\Aibybit_2\.venv\Lib\site-packages\httpcore\_async\connection.py", line 78, in handle_async_request
    stream = await self._connect(request)
             ^^^^^^^^^^^^^^^^^^^^^^^^^^^^
  File "C:\Users\oasis\Aibybit_2\.venv\Lib\site-packages\httpcore\_async\connection.py", line 124, in _connect
    stream = await self._network_backend.connect_tcp(**kwargs)
             ^^^^^^^^^^^^^^^^^^^^^^^^^^^^^^^^^^^^^^^^^^^^^^^^^
  File "C:\Users\oasis\Aibybit_2\.venv\Lib\site-packages\httpcore\_backends\auto.py", line 31, in connect_tcp
    return await self._backend.connect_tcp(
           ^^^^^^^^^^^^^^^^^^^^^^^^^^^^^^^^
  File "C:\Users\oasis\Aibybit_2\.venv\Lib\site-packages\httpcore\_backends\anyio.py", line 113, in connect_tcp
    with map_exceptions(exc_map):
  File "C:\Program Files\Python311\Lib\contextlib.py", line 155, in __exit__
    self.gen.throw(typ, value, traceback)
  File "C:\Users\oasis\Aibybit_2\.venv\Lib\site-packages\httpcore\_exceptions.py", line 14, in map_exceptions
    raise to_exc(exc) from exc
httpcore.ConnectError: [Errno 11001] getaddrinfo failed

The above exception was the direct cause of the following exception:

Traceback (most recent call last):
  File "C:\Users\oasis\Aibybit_2\.venv\Lib\site-packages\telegram\request\_httpxrequest.py", line 268, in do_request
    res = await self._client.request(
          ^^^^^^^^^^^^^^^^^^^^^^^^^^^
  File "C:\Users\oasis\Aibybit_2\.venv\Lib\site-packages\httpx\_client.py", line 1530, in request
    return await self.send(request, auth=auth, follow_redirects=follow_redirects)
           ^^^^^^^^^^^^^^^^^^^^^^^^^^^^^^^^^^^^^^^^^^^^^^^^^^^^^^^^^^^^^^^^^^^^^^
  File "C:\Users\oasis\Aibybit_2\.venv\Lib\site-packages\httpx\_client.py", line 1617, in send
    response = await self._send_handling_auth(
               ^^^^^^^^^^^^^^^^^^^^^^^^^^^^^^^
  File "C:\Users\oasis\Aibybit_2\.venv\Lib\site-packages\httpx\_client.py", line 1645, in _send_handling_auth
    response = await self._send_handling_redirects(
               ^^^^^^^^^^^^^^^^^^^^^^^^^^^^^^^^^^^^
  File "C:\Users\oasis\Aibybit_2\.venv\Lib\site-packages\httpx\_client.py", line 1682, in _send_handling_redirects
    response = await self._send_single_request(request)
               ^^^^^^^^^^^^^^^^^^^^^^^^^^^^^^^^^^^^^^^^
  File "C:\Users\oasis\Aibybit_2\.venv\Lib\site-packages\httpx\_client.py", line 1719, in _send_single_request
    response = await transport.handle_async_request(request)
               ^^^^^^^^^^^^^^^^^^^^^^^^^^^^^^^^^^^^^^^^^^^^^
  File "C:\Users\oasis\Aibybit_2\.venv\Lib\site-packages\httpx\_transports\default.py", line 365, in handle_async_request
    with map_httpcore_exceptions():
  File "C:\Program Files\Python311\Lib\contextlib.py", line 155, in __exit__
    self.gen.throw(typ, value, traceback)
  File "C:\Users\oasis\Aibybit_2\.venv\Lib\site-packages\httpx\_transports\default.py", line 83, in map_httpcore_exceptions
    raise mapped_exc(message) from exc
httpx.ConnectError: [Errno 11001] getaddrinfo failed

The above exception was the direct cause of the following exception:

Traceback (most recent call last):
  File "C:\Users\oasis\Aibybit_2\.venv\Lib\site-packages\telegram\ext\_updater.py", line 688, in _network_loop_retry
    if not await action_cb():
           ^^^^^^^^^^^^^^^^^
  File "C:\Users\oasis\Aibybit_2\.venv\Lib\site-packages\telegram\ext\_updater.py", line 384, in polling_action_cb
    raise exc
  File "C:\Users\oasis\Aibybit_2\.venv\Lib\site-packages\telegram\ext\_updater.py", line 373, in polling_action_cb
    updates = await self.bot.get_updates(
              ^^^^^^^^^^^^^^^^^^^^^^^^^^^
  File "C:\Users\oasis\Aibybit_2\.venv\Lib\site-packages\telegram\ext\_extbot.py", line 558, in get_updates
    updates = await super().get_updates(
              ^^^^^^^^^^^^^^^^^^^^^^^^^^
  File "C:\Users\oasis\Aibybit_2\.venv\Lib\site-packages\telegram\_bot.py", line 525, in decorator
    result = await func(self, *args, **kwargs)  # skipcq: PYL-E1102
             ^^^^^^^^^^^^^^^^^^^^^^^^^^^^^^^^^
  File "C:\Users\oasis\Aibybit_2\.venv\Lib\site-packages\telegram\_bot.py", line 3584, in get_updates
    await self._post(
  File "C:\Users\oasis\Aibybit_2\.venv\Lib\site-packages\telegram\_bot.py", line 613, in _post
    return await self._do_post(
           ^^^^^^^^^^^^^^^^^^^^
  File "C:\Users\oasis\Aibybit_2\.venv\Lib\site-packages\telegram\ext\_extbot.py", line 340, in _do_post
    return await super()._do_post(
           ^^^^^^^^^^^^^^^^^^^^^^^
  File "C:\Users\oasis\Aibybit_2\.venv\Lib\site-packages\telegram\_bot.py", line 641, in _do_post
    return await request.post(
           ^^^^^^^^^^^^^^^^^^^
  File "C:\Users\oasis\Aibybit_2\.venv\Lib\site-packages\telegram\request\_baserequest.py", line 200, in post
    result = await self._request_wrapper(
             ^^^^^^^^^^^^^^^^^^^^^^^^^^^^
  File "C:\Users\oasis\Aibybit_2\.venv\Lib\site-packages\telegram\request\_baserequest.py", line 340, in _request_wrapper
    raise exc
  File "C:\Users\oasis\Aibybit_2\.venv\Lib\site-packages\telegram\request\_baserequest.py", line 330, in _request_wrapper
    code, payload = await self.do_request(
                    ^^^^^^^^^^^^^^^^^^^^^^
  File "C:\Users\oasis\Aibybit_2\.venv\Lib\site-packages\telegram\request\_httpxrequest.py", line 292, in do_request
    raise NetworkError(f"httpx.{err.__class__.__name__}: {err}") from err
telegram.error.NetworkError: httpx.ConnectError: [Errno 11001] getaddrinfo failed
2025-03-04 14:18:04,519 - telegram.ext.Updater - ERROR - Error while getting Updates: httpx.ConnectError: [Errno 11001] getaddrinfo failed
2025-03-04 14:18:04,520 - telegram.ext.Updater - ERROR - Exception happened while polling for updates.
Traceback (most recent call last):
  File "C:\Users\oasis\Aibybit_2\.venv\Lib\site-packages\httpx\_transports\default.py", line 66, in map_httpcore_exceptions
    yield
  File "C:\Users\oasis\Aibybit_2\.venv\Lib\site-packages\httpx\_transports\default.py", line 366, in handle_async_request
    resp = await self._pool.handle_async_request(req)
           ^^^^^^^^^^^^^^^^^^^^^^^^^^^^^^^^^^^^^^^^^^
  File "C:\Users\oasis\Aibybit_2\.venv\Lib\site-packages\httpcore\_async\connection_pool.py", line 256, in handle_async_request
    raise exc from None
  File "C:\Users\oasis\Aibybit_2\.venv\Lib\site-packages\httpcore\_async\connection_pool.py", line 236, in handle_async_request
    response = await connection.handle_async_request(
               ^^^^^^^^^^^^^^^^^^^^^^^^^^^^^^^^^^^^^^
  File "C:\Users\oasis\Aibybit_2\.venv\Lib\site-packages\httpcore\_async\connection.py", line 101, in handle_async_request
    raise exc
  File "C:\Users\oasis\Aibybit_2\.venv\Lib\site-packages\httpcore\_async\connection.py", line 78, in handle_async_request
    stream = await self._connect(request)
             ^^^^^^^^^^^^^^^^^^^^^^^^^^^^
  File "C:\Users\oasis\Aibybit_2\.venv\Lib\site-packages\httpcore\_async\connection.py", line 124, in _connect
    stream = await self._network_backend.connect_tcp(**kwargs)
             ^^^^^^^^^^^^^^^^^^^^^^^^^^^^^^^^^^^^^^^^^^^^^^^^^
  File "C:\Users\oasis\Aibybit_2\.venv\Lib\site-packages\httpcore\_backends\auto.py", line 31, in connect_tcp
    return await self._backend.connect_tcp(
           ^^^^^^^^^^^^^^^^^^^^^^^^^^^^^^^^
  File "C:\Users\oasis\Aibybit_2\.venv\Lib\site-packages\httpcore\_backends\anyio.py", line 113, in connect_tcp
    with map_exceptions(exc_map):
  File "C:\Program Files\Python311\Lib\contextlib.py", line 155, in __exit__
    self.gen.throw(typ, value, traceback)
  File "C:\Users\oasis\Aibybit_2\.venv\Lib\site-packages\httpcore\_exceptions.py", line 14, in map_exceptions
    raise to_exc(exc) from exc
httpcore.ConnectError: [Errno 11001] getaddrinfo failed

The above exception was the direct cause of the following exception:

Traceback (most recent call last):
  File "C:\Users\oasis\Aibybit_2\.venv\Lib\site-packages\telegram\request\_httpxrequest.py", line 268, in do_request
    res = await self._client.request(
          ^^^^^^^^^^^^^^^^^^^^^^^^^^^
  File "C:\Users\oasis\Aibybit_2\.venv\Lib\site-packages\httpx\_client.py", line 1530, in request
    return await self.send(request, auth=auth, follow_redirects=follow_redirects)
           ^^^^^^^^^^^^^^^^^^^^^^^^^^^^^^^^^^^^^^^^^^^^^^^^^^^^^^^^^^^^^^^^^^^^^^
  File "C:\Users\oasis\Aibybit_2\.venv\Lib\site-packages\httpx\_client.py", line 1617, in send
    response = await self._send_handling_auth(
               ^^^^^^^^^^^^^^^^^^^^^^^^^^^^^^^
  File "C:\Users\oasis\Aibybit_2\.venv\Lib\site-packages\httpx\_client.py", line 1645, in _send_handling_auth
    response = await self._send_handling_redirects(
               ^^^^^^^^^^^^^^^^^^^^^^^^^^^^^^^^^^^^
  File "C:\Users\oasis\Aibybit_2\.venv\Lib\site-packages\httpx\_client.py", line 1682, in _send_handling_redirects
    response = await self._send_single_request(request)
               ^^^^^^^^^^^^^^^^^^^^^^^^^^^^^^^^^^^^^^^^
  File "C:\Users\oasis\Aibybit_2\.venv\Lib\site-packages\httpx\_client.py", line 1719, in _send_single_request
    response = await transport.handle_async_request(request)
               ^^^^^^^^^^^^^^^^^^^^^^^^^^^^^^^^^^^^^^^^^^^^^
  File "C:\Users\oasis\Aibybit_2\.venv\Lib\site-packages\httpx\_transports\default.py", line 365, in handle_async_request
    with map_httpcore_exceptions():
  File "C:\Program Files\Python311\Lib\contextlib.py", line 155, in __exit__
    self.gen.throw(typ, value, traceback)
  File "C:\Users\oasis\Aibybit_2\.venv\Lib\site-packages\httpx\_transports\default.py", line 83, in map_httpcore_exceptions
    raise mapped_exc(message) from exc
httpx.ConnectError: [Errno 11001] getaddrinfo failed

The above exception was the direct cause of the following exception:

Traceback (most recent call last):
  File "C:\Users\oasis\Aibybit_2\.venv\Lib\site-packages\telegram\ext\_updater.py", line 688, in _network_loop_retry
    if not await action_cb():
           ^^^^^^^^^^^^^^^^^
  File "C:\Users\oasis\Aibybit_2\.venv\Lib\site-packages\telegram\ext\_updater.py", line 384, in polling_action_cb
    raise exc
  File "C:\Users\oasis\Aibybit_2\.venv\Lib\site-packages\telegram\ext\_updater.py", line 373, in polling_action_cb
    updates = await self.bot.get_updates(
              ^^^^^^^^^^^^^^^^^^^^^^^^^^^
  File "C:\Users\oasis\Aibybit_2\.venv\Lib\site-packages\telegram\ext\_extbot.py", line 558, in get_updates
    updates = await super().get_updates(
              ^^^^^^^^^^^^^^^^^^^^^^^^^^
  File "C:\Users\oasis\Aibybit_2\.venv\Lib\site-packages\telegram\_bot.py", line 525, in decorator
    result = await func(self, *args, **kwargs)  # skipcq: PYL-E1102
             ^^^^^^^^^^^^^^^^^^^^^^^^^^^^^^^^^
  File "C:\Users\oasis\Aibybit_2\.venv\Lib\site-packages\telegram\_bot.py", line 3584, in get_updates
    await self._post(
  File "C:\Users\oasis\Aibybit_2\.venv\Lib\site-packages\telegram\_bot.py", line 613, in _post
    return await self._do_post(
           ^^^^^^^^^^^^^^^^^^^^
  File "C:\Users\oasis\Aibybit_2\.venv\Lib\site-packages\telegram\ext\_extbot.py", line 340, in _do_post
    return await super()._do_post(
           ^^^^^^^^^^^^^^^^^^^^^^^
  File "C:\Users\oasis\Aibybit_2\.venv\Lib\site-packages\telegram\_bot.py", line 641, in _do_post
    return await request.post(
           ^^^^^^^^^^^^^^^^^^^
  File "C:\Users\oasis\Aibybit_2\.venv\Lib\site-packages\telegram\request\_baserequest.py", line 200, in post
    result = await self._request_wrapper(
             ^^^^^^^^^^^^^^^^^^^^^^^^^^^^
  File "C:\Users\oasis\Aibybit_2\.venv\Lib\site-packages\telegram\request\_baserequest.py", line 340, in _request_wrapper
    raise exc
  File "C:\Users\oasis\Aibybit_2\.venv\Lib\site-packages\telegram\request\_baserequest.py", line 330, in _request_wrapper
    code, payload = await self.do_request(
                    ^^^^^^^^^^^^^^^^^^^^^^
  File "C:\Users\oasis\Aibybit_2\.venv\Lib\site-packages\telegram\request\_httpxrequest.py", line 292, in do_request
    raise NetworkError(f"httpx.{err.__class__.__name__}: {err}") from err
telegram.error.NetworkError: httpx.ConnectError: [Errno 11001] getaddrinfo failed
2025-03-04 14:18:05,533 - telegram.ext.Updater - ERROR - Error while getting Updates: httpx.ConnectError: [Errno 11001] getaddrinfo failed
2025-03-04 14:18:05,535 - telegram.ext.Updater - ERROR - Exception happened while polling for updates.
Traceback (most recent call last):
  File "C:\Users\oasis\Aibybit_2\.venv\Lib\site-packages\httpx\_transports\default.py", line 66, in map_httpcore_exceptions
    yield
  File "C:\Users\oasis\Aibybit_2\.venv\Lib\site-packages\httpx\_transports\default.py", line 366, in handle_async_request
    resp = await self._pool.handle_async_request(req)
           ^^^^^^^^^^^^^^^^^^^^^^^^^^^^^^^^^^^^^^^^^^
  File "C:\Users\oasis\Aibybit_2\.venv\Lib\site-packages\httpcore\_async\connection_pool.py", line 256, in handle_async_request
    raise exc from None
  File "C:\Users\oasis\Aibybit_2\.venv\Lib\site-packages\httpcore\_async\connection_pool.py", line 236, in handle_async_request
    response = await connection.handle_async_request(
               ^^^^^^^^^^^^^^^^^^^^^^^^^^^^^^^^^^^^^^
  File "C:\Users\oasis\Aibybit_2\.venv\Lib\site-packages\httpcore\_async\connection.py", line 101, in handle_async_request
    raise exc
  File "C:\Users\oasis\Aibybit_2\.venv\Lib\site-packages\httpcore\_async\connection.py", line 78, in handle_async_request
    stream = await self._connect(request)
             ^^^^^^^^^^^^^^^^^^^^^^^^^^^^
  File "C:\Users\oasis\Aibybit_2\.venv\Lib\site-packages\httpcore\_async\connection.py", line 124, in _connect
    stream = await self._network_backend.connect_tcp(**kwargs)
             ^^^^^^^^^^^^^^^^^^^^^^^^^^^^^^^^^^^^^^^^^^^^^^^^^
  File "C:\Users\oasis\Aibybit_2\.venv\Lib\site-packages\httpcore\_backends\auto.py", line 31, in connect_tcp
    return await self._backend.connect_tcp(
           ^^^^^^^^^^^^^^^^^^^^^^^^^^^^^^^^
  File "C:\Users\oasis\Aibybit_2\.venv\Lib\site-packages\httpcore\_backends\anyio.py", line 113, in connect_tcp
    with map_exceptions(exc_map):
  File "C:\Program Files\Python311\Lib\contextlib.py", line 155, in __exit__
    self.gen.throw(typ, value, traceback)
  File "C:\Users\oasis\Aibybit_2\.venv\Lib\site-packages\httpcore\_exceptions.py", line 14, in map_exceptions
    raise to_exc(exc) from exc
httpcore.ConnectError: [Errno 11001] getaddrinfo failed

The above exception was the direct cause of the following exception:

Traceback (most recent call last):
  File "C:\Users\oasis\Aibybit_2\.venv\Lib\site-packages\telegram\request\_httpxrequest.py", line 268, in do_request
    res = await self._client.request(
          ^^^^^^^^^^^^^^^^^^^^^^^^^^^
  File "C:\Users\oasis\Aibybit_2\.venv\Lib\site-packages\httpx\_client.py", line 1530, in request
    return await self.send(request, auth=auth, follow_redirects=follow_redirects)
           ^^^^^^^^^^^^^^^^^^^^^^^^^^^^^^^^^^^^^^^^^^^^^^^^^^^^^^^^^^^^^^^^^^^^^^
  File "C:\Users\oasis\Aibybit_2\.venv\Lib\site-packages\httpx\_client.py", line 1617, in send
    response = await self._send_handling_auth(
               ^^^^^^^^^^^^^^^^^^^^^^^^^^^^^^^
  File "C:\Users\oasis\Aibybit_2\.venv\Lib\site-packages\httpx\_client.py", line 1645, in _send_handling_auth
    response = await self._send_handling_redirects(
               ^^^^^^^^^^^^^^^^^^^^^^^^^^^^^^^^^^^^
  File "C:\Users\oasis\Aibybit_2\.venv\Lib\site-packages\httpx\_client.py", line 1682, in _send_handling_redirects
    response = await self._send_single_request(request)
               ^^^^^^^^^^^^^^^^^^^^^^^^^^^^^^^^^^^^^^^^
  File "C:\Users\oasis\Aibybit_2\.venv\Lib\site-packages\httpx\_client.py", line 1719, in _send_single_request
    response = await transport.handle_async_request(request)
               ^^^^^^^^^^^^^^^^^^^^^^^^^^^^^^^^^^^^^^^^^^^^^
  File "C:\Users\oasis\Aibybit_2\.venv\Lib\site-packages\httpx\_transports\default.py", line 365, in handle_async_request
    with map_httpcore_exceptions():
  File "C:\Program Files\Python311\Lib\contextlib.py", line 155, in __exit__
    self.gen.throw(typ, value, traceback)
  File "C:\Users\oasis\Aibybit_2\.venv\Lib\site-packages\httpx\_transports\default.py", line 83, in map_httpcore_exceptions
    raise mapped_exc(message) from exc
httpx.ConnectError: [Errno 11001] getaddrinfo failed

The above exception was the direct cause of the following exception:

Traceback (most recent call last):
  File "C:\Users\oasis\Aibybit_2\.venv\Lib\site-packages\telegram\ext\_updater.py", line 688, in _network_loop_retry
    if not await action_cb():
           ^^^^^^^^^^^^^^^^^
  File "C:\Users\oasis\Aibybit_2\.venv\Lib\site-packages\telegram\ext\_updater.py", line 384, in polling_action_cb
    raise exc
  File "C:\Users\oasis\Aibybit_2\.venv\Lib\site-packages\telegram\ext\_updater.py", line 373, in polling_action_cb
    updates = await self.bot.get_updates(
              ^^^^^^^^^^^^^^^^^^^^^^^^^^^
  File "C:\Users\oasis\Aibybit_2\.venv\Lib\site-packages\telegram\ext\_extbot.py", line 558, in get_updates
    updates = await super().get_updates(
              ^^^^^^^^^^^^^^^^^^^^^^^^^^
  File "C:\Users\oasis\Aibybit_2\.venv\Lib\site-packages\telegram\_bot.py", line 525, in decorator
    result = await func(self, *args, **kwargs)  # skipcq: PYL-E1102
             ^^^^^^^^^^^^^^^^^^^^^^^^^^^^^^^^^
  File "C:\Users\oasis\Aibybit_2\.venv\Lib\site-packages\telegram\_bot.py", line 3584, in get_updates
    await self._post(
  File "C:\Users\oasis\Aibybit_2\.venv\Lib\site-packages\telegram\_bot.py", line 613, in _post
    return await self._do_post(
           ^^^^^^^^^^^^^^^^^^^^
  File "C:\Users\oasis\Aibybit_2\.venv\Lib\site-packages\telegram\ext\_extbot.py", line 340, in _do_post
    return await super()._do_post(
           ^^^^^^^^^^^^^^^^^^^^^^^
  File "C:\Users\oasis\Aibybit_2\.venv\Lib\site-packages\telegram\_bot.py", line 641, in _do_post
    return await request.post(
           ^^^^^^^^^^^^^^^^^^^
  File "C:\Users\oasis\Aibybit_2\.venv\Lib\site-packages\telegram\request\_baserequest.py", line 200, in post
    result = await self._request_wrapper(
             ^^^^^^^^^^^^^^^^^^^^^^^^^^^^
  File "C:\Users\oasis\Aibybit_2\.venv\Lib\site-packages\telegram\request\_baserequest.py", line 340, in _request_wrapper
    raise exc
  File "C:\Users\oasis\Aibybit_2\.venv\Lib\site-packages\telegram\request\_baserequest.py", line 330, in _request_wrapper
    code, payload = await self.do_request(
                    ^^^^^^^^^^^^^^^^^^^^^^
  File "C:\Users\oasis\Aibybit_2\.venv\Lib\site-packages\telegram\request\_httpxrequest.py", line 292, in do_request
    raise NetworkError(f"httpx.{err.__class__.__name__}: {err}") from err
telegram.error.NetworkError: httpx.ConnectError: [Errno 11001] getaddrinfo failed
2025-03-04 14:18:07,054 - telegram.ext.Updater - ERROR - Error while getting Updates: httpx.ConnectError: [Errno 11001] getaddrinfo failed
2025-03-04 14:18:07,055 - telegram.ext.Updater - ERROR - Exception happened while polling for updates.
Traceback (most recent call last):
  File "C:\Users\oasis\Aibybit_2\.venv\Lib\site-packages\httpx\_transports\default.py", line 66, in map_httpcore_exceptions
    yield
  File "C:\Users\oasis\Aibybit_2\.venv\Lib\site-packages\httpx\_transports\default.py", line 366, in handle_async_request
    resp = await self._pool.handle_async_request(req)
           ^^^^^^^^^^^^^^^^^^^^^^^^^^^^^^^^^^^^^^^^^^
  File "C:\Users\oasis\Aibybit_2\.venv\Lib\site-packages\httpcore\_async\connection_pool.py", line 256, in handle_async_request
    raise exc from None
  File "C:\Users\oasis\Aibybit_2\.venv\Lib\site-packages\httpcore\_async\connection_pool.py", line 236, in handle_async_request
    response = await connection.handle_async_request(
               ^^^^^^^^^^^^^^^^^^^^^^^^^^^^^^^^^^^^^^
  File "C:\Users\oasis\Aibybit_2\.venv\Lib\site-packages\httpcore\_async\connection.py", line 101, in handle_async_request
    raise exc
  File "C:\Users\oasis\Aibybit_2\.venv\Lib\site-packages\httpcore\_async\connection.py", line 78, in handle_async_request
    stream = await self._connect(request)
             ^^^^^^^^^^^^^^^^^^^^^^^^^^^^
  File "C:\Users\oasis\Aibybit_2\.venv\Lib\site-packages\httpcore\_async\connection.py", line 124, in _connect
    stream = await self._network_backend.connect_tcp(**kwargs)
             ^^^^^^^^^^^^^^^^^^^^^^^^^^^^^^^^^^^^^^^^^^^^^^^^^
  File "C:\Users\oasis\Aibybit_2\.venv\Lib\site-packages\httpcore\_backends\auto.py", line 31, in connect_tcp
    return await self._backend.connect_tcp(
           ^^^^^^^^^^^^^^^^^^^^^^^^^^^^^^^^
  File "C:\Users\oasis\Aibybit_2\.venv\Lib\site-packages\httpcore\_backends\anyio.py", line 113, in connect_tcp
    with map_exceptions(exc_map):
  File "C:\Program Files\Python311\Lib\contextlib.py", line 155, in __exit__
    self.gen.throw(typ, value, traceback)
  File "C:\Users\oasis\Aibybit_2\.venv\Lib\site-packages\httpcore\_exceptions.py", line 14, in map_exceptions
    raise to_exc(exc) from exc
httpcore.ConnectError: [Errno 11001] getaddrinfo failed

The above exception was the direct cause of the following exception:

Traceback (most recent call last):
  File "C:\Users\oasis\Aibybit_2\.venv\Lib\site-packages\telegram\request\_httpxrequest.py", line 268, in do_request
    res = await self._client.request(
          ^^^^^^^^^^^^^^^^^^^^^^^^^^^
  File "C:\Users\oasis\Aibybit_2\.venv\Lib\site-packages\httpx\_client.py", line 1530, in request
    return await self.send(request, auth=auth, follow_redirects=follow_redirects)
           ^^^^^^^^^^^^^^^^^^^^^^^^^^^^^^^^^^^^^^^^^^^^^^^^^^^^^^^^^^^^^^^^^^^^^^
  File "C:\Users\oasis\Aibybit_2\.venv\Lib\site-packages\httpx\_client.py", line 1617, in send
    response = await self._send_handling_auth(
               ^^^^^^^^^^^^^^^^^^^^^^^^^^^^^^^
  File "C:\Users\oasis\Aibybit_2\.venv\Lib\site-packages\httpx\_client.py", line 1645, in _send_handling_auth
    response = await self._send_handling_redirects(
               ^^^^^^^^^^^^^^^^^^^^^^^^^^^^^^^^^^^^
  File "C:\Users\oasis\Aibybit_2\.venv\Lib\site-packages\httpx\_client.py", line 1682, in _send_handling_redirects
    response = await self._send_single_request(request)
               ^^^^^^^^^^^^^^^^^^^^^^^^^^^^^^^^^^^^^^^^
  File "C:\Users\oasis\Aibybit_2\.venv\Lib\site-packages\httpx\_client.py", line 1719, in _send_single_request
    response = await transport.handle_async_request(request)
               ^^^^^^^^^^^^^^^^^^^^^^^^^^^^^^^^^^^^^^^^^^^^^
  File "C:\Users\oasis\Aibybit_2\.venv\Lib\site-packages\httpx\_transports\default.py", line 365, in handle_async_request
    with map_httpcore_exceptions():
  File "C:\Program Files\Python311\Lib\contextlib.py", line 155, in __exit__
    self.gen.throw(typ, value, traceback)
  File "C:\Users\oasis\Aibybit_2\.venv\Lib\site-packages\httpx\_transports\default.py", line 83, in map_httpcore_exceptions
    raise mapped_exc(message) from exc
httpx.ConnectError: [Errno 11001] getaddrinfo failed

The above exception was the direct cause of the following exception:

Traceback (most recent call last):
  File "C:\Users\oasis\Aibybit_2\.venv\Lib\site-packages\telegram\ext\_updater.py", line 688, in _network_loop_retry
    if not await action_cb():
           ^^^^^^^^^^^^^^^^^
  File "C:\Users\oasis\Aibybit_2\.venv\Lib\site-packages\telegram\ext\_updater.py", line 384, in polling_action_cb
    raise exc
  File "C:\Users\oasis\Aibybit_2\.venv\Lib\site-packages\telegram\ext\_updater.py", line 373, in polling_action_cb
    updates = await self.bot.get_updates(
              ^^^^^^^^^^^^^^^^^^^^^^^^^^^
  File "C:\Users\oasis\Aibybit_2\.venv\Lib\site-packages\telegram\ext\_extbot.py", line 558, in get_updates
    updates = await super().get_updates(
              ^^^^^^^^^^^^^^^^^^^^^^^^^^
  File "C:\Users\oasis\Aibybit_2\.venv\Lib\site-packages\telegram\_bot.py", line 525, in decorator
    result = await func(self, *args, **kwargs)  # skipcq: PYL-E1102
             ^^^^^^^^^^^^^^^^^^^^^^^^^^^^^^^^^
  File "C:\Users\oasis\Aibybit_2\.venv\Lib\site-packages\telegram\_bot.py", line 3584, in get_updates
    await self._post(
  File "C:\Users\oasis\Aibybit_2\.venv\Lib\site-packages\telegram\_bot.py", line 613, in _post
    return await self._do_post(
           ^^^^^^^^^^^^^^^^^^^^
  File "C:\Users\oasis\Aibybit_2\.venv\Lib\site-packages\telegram\ext\_extbot.py", line 340, in _do_post
    return await super()._do_post(
           ^^^^^^^^^^^^^^^^^^^^^^^
  File "C:\Users\oasis\Aibybit_2\.venv\Lib\site-packages\telegram\_bot.py", line 641, in _do_post
    return await request.post(
           ^^^^^^^^^^^^^^^^^^^
  File "C:\Users\oasis\Aibybit_2\.venv\Lib\site-packages\telegram\request\_baserequest.py", line 200, in post
    result = await self._request_wrapper(
             ^^^^^^^^^^^^^^^^^^^^^^^^^^^^
  File "C:\Users\oasis\Aibybit_2\.venv\Lib\site-packages\telegram\request\_baserequest.py", line 340, in _request_wrapper
    raise exc
  File "C:\Users\oasis\Aibybit_2\.venv\Lib\site-packages\telegram\request\_baserequest.py", line 330, in _request_wrapper
    code, payload = await self.do_request(
                    ^^^^^^^^^^^^^^^^^^^^^^
  File "C:\Users\oasis\Aibybit_2\.venv\Lib\site-packages\telegram\request\_httpxrequest.py", line 292, in do_request
    raise NetworkError(f"httpx.{err.__class__.__name__}: {err}") from err
telegram.error.NetworkError: httpx.ConnectError: [Errno 11001] getaddrinfo failed
2025-03-04 14:18:09,318 - telegram.ext.Updater - ERROR - Error while getting Updates: httpx.ConnectError: [Errno 11001] getaddrinfo failed
2025-03-04 14:18:09,319 - telegram.ext.Updater - ERROR - Exception happened while polling for updates.
Traceback (most recent call last):
  File "C:\Users\oasis\Aibybit_2\.venv\Lib\site-packages\httpx\_transports\default.py", line 66, in map_httpcore_exceptions
    yield
  File "C:\Users\oasis\Aibybit_2\.venv\Lib\site-packages\httpx\_transports\default.py", line 366, in handle_async_request
    resp = await self._pool.handle_async_request(req)
           ^^^^^^^^^^^^^^^^^^^^^^^^^^^^^^^^^^^^^^^^^^
  File "C:\Users\oasis\Aibybit_2\.venv\Lib\site-packages\httpcore\_async\connection_pool.py", line 256, in handle_async_request
    raise exc from None
  File "C:\Users\oasis\Aibybit_2\.venv\Lib\site-packages\httpcore\_async\connection_pool.py", line 236, in handle_async_request
    response = await connection.handle_async_request(
               ^^^^^^^^^^^^^^^^^^^^^^^^^^^^^^^^^^^^^^
  File "C:\Users\oasis\Aibybit_2\.venv\Lib\site-packages\httpcore\_async\connection.py", line 101, in handle_async_request
    raise exc
  File "C:\Users\oasis\Aibybit_2\.venv\Lib\site-packages\httpcore\_async\connection.py", line 78, in handle_async_request
    stream = await self._connect(request)
             ^^^^^^^^^^^^^^^^^^^^^^^^^^^^
  File "C:\Users\oasis\Aibybit_2\.venv\Lib\site-packages\httpcore\_async\connection.py", line 124, in _connect
    stream = await self._network_backend.connect_tcp(**kwargs)
             ^^^^^^^^^^^^^^^^^^^^^^^^^^^^^^^^^^^^^^^^^^^^^^^^^
  File "C:\Users\oasis\Aibybit_2\.venv\Lib\site-packages\httpcore\_backends\auto.py", line 31, in connect_tcp
    return await self._backend.connect_tcp(
           ^^^^^^^^^^^^^^^^^^^^^^^^^^^^^^^^
  File "C:\Users\oasis\Aibybit_2\.venv\Lib\site-packages\httpcore\_backends\anyio.py", line 113, in connect_tcp
    with map_exceptions(exc_map):
  File "C:\Program Files\Python311\Lib\contextlib.py", line 155, in __exit__
    self.gen.throw(typ, value, traceback)
  File "C:\Users\oasis\Aibybit_2\.venv\Lib\site-packages\httpcore\_exceptions.py", line 14, in map_exceptions
    raise to_exc(exc) from exc
httpcore.ConnectError: [Errno 11001] getaddrinfo failed

The above exception was the direct cause of the following exception:

Traceback (most recent call last):
  File "C:\Users\oasis\Aibybit_2\.venv\Lib\site-packages\telegram\request\_httpxrequest.py", line 268, in do_request
    res = await self._client.request(
          ^^^^^^^^^^^^^^^^^^^^^^^^^^^
  File "C:\Users\oasis\Aibybit_2\.venv\Lib\site-packages\httpx\_client.py", line 1530, in request
    return await self.send(request, auth=auth, follow_redirects=follow_redirects)
           ^^^^^^^^^^^^^^^^^^^^^^^^^^^^^^^^^^^^^^^^^^^^^^^^^^^^^^^^^^^^^^^^^^^^^^
  File "C:\Users\oasis\Aibybit_2\.venv\Lib\site-packages\httpx\_client.py", line 1617, in send
    response = await self._send_handling_auth(
               ^^^^^^^^^^^^^^^^^^^^^^^^^^^^^^^
  File "C:\Users\oasis\Aibybit_2\.venv\Lib\site-packages\httpx\_client.py", line 1645, in _send_handling_auth
    response = await self._send_handling_redirects(
               ^^^^^^^^^^^^^^^^^^^^^^^^^^^^^^^^^^^^
  File "C:\Users\oasis\Aibybit_2\.venv\Lib\site-packages\httpx\_client.py", line 1682, in _send_handling_redirects
    response = await self._send_single_request(request)
               ^^^^^^^^^^^^^^^^^^^^^^^^^^^^^^^^^^^^^^^^
  File "C:\Users\oasis\Aibybit_2\.venv\Lib\site-packages\httpx\_client.py", line 1719, in _send_single_request
    response = await transport.handle_async_request(request)
               ^^^^^^^^^^^^^^^^^^^^^^^^^^^^^^^^^^^^^^^^^^^^^
  File "C:\Users\oasis\Aibybit_2\.venv\Lib\site-packages\httpx\_transports\default.py", line 365, in handle_async_request
    with map_httpcore_exceptions():
  File "C:\Program Files\Python311\Lib\contextlib.py", line 155, in __exit__
    self.gen.throw(typ, value, traceback)
  File "C:\Users\oasis\Aibybit_2\.venv\Lib\site-packages\httpx\_transports\default.py", line 83, in map_httpcore_exceptions
    raise mapped_exc(message) from exc
httpx.ConnectError: [Errno 11001] getaddrinfo failed

The above exception was the direct cause of the following exception:

Traceback (most recent call last):
  File "C:\Users\oasis\Aibybit_2\.venv\Lib\site-packages\telegram\ext\_updater.py", line 688, in _network_loop_retry
    if not await action_cb():
           ^^^^^^^^^^^^^^^^^
  File "C:\Users\oasis\Aibybit_2\.venv\Lib\site-packages\telegram\ext\_updater.py", line 384, in polling_action_cb
    raise exc
  File "C:\Users\oasis\Aibybit_2\.venv\Lib\site-packages\telegram\ext\_updater.py", line 373, in polling_action_cb
    updates = await self.bot.get_updates(
              ^^^^^^^^^^^^^^^^^^^^^^^^^^^
  File "C:\Users\oasis\Aibybit_2\.venv\Lib\site-packages\telegram\ext\_extbot.py", line 558, in get_updates
    updates = await super().get_updates(
              ^^^^^^^^^^^^^^^^^^^^^^^^^^
  File "C:\Users\oasis\Aibybit_2\.venv\Lib\site-packages\telegram\_bot.py", line 525, in decorator
    result = await func(self, *args, **kwargs)  # skipcq: PYL-E1102
             ^^^^^^^^^^^^^^^^^^^^^^^^^^^^^^^^^
  File "C:\Users\oasis\Aibybit_2\.venv\Lib\site-packages\telegram\_bot.py", line 3584, in get_updates
    await self._post(
  File "C:\Users\oasis\Aibybit_2\.venv\Lib\site-packages\telegram\_bot.py", line 613, in _post
    return await self._do_post(
           ^^^^^^^^^^^^^^^^^^^^
  File "C:\Users\oasis\Aibybit_2\.venv\Lib\site-packages\telegram\ext\_extbot.py", line 340, in _do_post
    return await super()._do_post(
           ^^^^^^^^^^^^^^^^^^^^^^^
  File "C:\Users\oasis\Aibybit_2\.venv\Lib\site-packages\telegram\_bot.py", line 641, in _do_post
    return await request.post(
           ^^^^^^^^^^^^^^^^^^^
  File "C:\Users\oasis\Aibybit_2\.venv\Lib\site-packages\telegram\request\_baserequest.py", line 200, in post
    result = await self._request_wrapper(
             ^^^^^^^^^^^^^^^^^^^^^^^^^^^^
  File "C:\Users\oasis\Aibybit_2\.venv\Lib\site-packages\telegram\request\_baserequest.py", line 340, in _request_wrapper
    raise exc
  File "C:\Users\oasis\Aibybit_2\.venv\Lib\site-packages\telegram\request\_baserequest.py", line 330, in _request_wrapper
    code, payload = await self.do_request(
                    ^^^^^^^^^^^^^^^^^^^^^^
  File "C:\Users\oasis\Aibybit_2\.venv\Lib\site-packages\telegram\request\_httpxrequest.py", line 292, in do_request
    raise NetworkError(f"httpx.{err.__class__.__name__}: {err}") from err
telegram.error.NetworkError: httpx.ConnectError: [Errno 11001] getaddrinfo failed
2025-03-04 14:18:12,703 - telegram.ext.Updater - ERROR - Error while getting Updates: httpx.ConnectError: [Errno 11001] getaddrinfo failed
2025-03-04 14:18:12,704 - telegram.ext.Updater - ERROR - Exception happened while polling for updates.
Traceback (most recent call last):
  File "C:\Users\oasis\Aibybit_2\.venv\Lib\site-packages\httpx\_transports\default.py", line 66, in map_httpcore_exceptions
    yield
  File "C:\Users\oasis\Aibybit_2\.venv\Lib\site-packages\httpx\_transports\default.py", line 366, in handle_async_request
    resp = await self._pool.handle_async_request(req)
           ^^^^^^^^^^^^^^^^^^^^^^^^^^^^^^^^^^^^^^^^^^
  File "C:\Users\oasis\Aibybit_2\.venv\Lib\site-packages\httpcore\_async\connection_pool.py", line 256, in handle_async_request
    raise exc from None
  File "C:\Users\oasis\Aibybit_2\.venv\Lib\site-packages\httpcore\_async\connection_pool.py", line 236, in handle_async_request
    response = await connection.handle_async_request(
               ^^^^^^^^^^^^^^^^^^^^^^^^^^^^^^^^^^^^^^
  File "C:\Users\oasis\Aibybit_2\.venv\Lib\site-packages\httpcore\_async\connection.py", line 101, in handle_async_request
    raise exc
  File "C:\Users\oasis\Aibybit_2\.venv\Lib\site-packages\httpcore\_async\connection.py", line 78, in handle_async_request
    stream = await self._connect(request)
             ^^^^^^^^^^^^^^^^^^^^^^^^^^^^
  File "C:\Users\oasis\Aibybit_2\.venv\Lib\site-packages\httpcore\_async\connection.py", line 124, in _connect
    stream = await self._network_backend.connect_tcp(**kwargs)
             ^^^^^^^^^^^^^^^^^^^^^^^^^^^^^^^^^^^^^^^^^^^^^^^^^
  File "C:\Users\oasis\Aibybit_2\.venv\Lib\site-packages\httpcore\_backends\auto.py", line 31, in connect_tcp
    return await self._backend.connect_tcp(
           ^^^^^^^^^^^^^^^^^^^^^^^^^^^^^^^^
  File "C:\Users\oasis\Aibybit_2\.venv\Lib\site-packages\httpcore\_backends\anyio.py", line 113, in connect_tcp
    with map_exceptions(exc_map):
  File "C:\Program Files\Python311\Lib\contextlib.py", line 155, in __exit__
    self.gen.throw(typ, value, traceback)
  File "C:\Users\oasis\Aibybit_2\.venv\Lib\site-packages\httpcore\_exceptions.py", line 14, in map_exceptions
    raise to_exc(exc) from exc
httpcore.ConnectError: [Errno 11001] getaddrinfo failed

The above exception was the direct cause of the following exception:

Traceback (most recent call last):
  File "C:\Users\oasis\Aibybit_2\.venv\Lib\site-packages\telegram\request\_httpxrequest.py", line 268, in do_request
    res = await self._client.request(
          ^^^^^^^^^^^^^^^^^^^^^^^^^^^
  File "C:\Users\oasis\Aibybit_2\.venv\Lib\site-packages\httpx\_client.py", line 1530, in request
    return await self.send(request, auth=auth, follow_redirects=follow_redirects)
           ^^^^^^^^^^^^^^^^^^^^^^^^^^^^^^^^^^^^^^^^^^^^^^^^^^^^^^^^^^^^^^^^^^^^^^
  File "C:\Users\oasis\Aibybit_2\.venv\Lib\site-packages\httpx\_client.py", line 1617, in send
    response = await self._send_handling_auth(
               ^^^^^^^^^^^^^^^^^^^^^^^^^^^^^^^
  File "C:\Users\oasis\Aibybit_2\.venv\Lib\site-packages\httpx\_client.py", line 1645, in _send_handling_auth
    response = await self._send_handling_redirects(
               ^^^^^^^^^^^^^^^^^^^^^^^^^^^^^^^^^^^^
  File "C:\Users\oasis\Aibybit_2\.venv\Lib\site-packages\httpx\_client.py", line 1682, in _send_handling_redirects
    response = await self._send_single_request(request)
               ^^^^^^^^^^^^^^^^^^^^^^^^^^^^^^^^^^^^^^^^
  File "C:\Users\oasis\Aibybit_2\.venv\Lib\site-packages\httpx\_client.py", line 1719, in _send_single_request
    response = await transport.handle_async_request(request)
               ^^^^^^^^^^^^^^^^^^^^^^^^^^^^^^^^^^^^^^^^^^^^^
  File "C:\Users\oasis\Aibybit_2\.venv\Lib\site-packages\httpx\_transports\default.py", line 365, in handle_async_request
    with map_httpcore_exceptions():
  File "C:\Program Files\Python311\Lib\contextlib.py", line 155, in __exit__
    self.gen.throw(typ, value, traceback)
  File "C:\Users\oasis\Aibybit_2\.venv\Lib\site-packages\httpx\_transports\default.py", line 83, in map_httpcore_exceptions
    raise mapped_exc(message) from exc
httpx.ConnectError: [Errno 11001] getaddrinfo failed

The above exception was the direct cause of the following exception:

Traceback (most recent call last):
  File "C:\Users\oasis\Aibybit_2\.venv\Lib\site-packages\telegram\ext\_updater.py", line 688, in _network_loop_retry
    if not await action_cb():
           ^^^^^^^^^^^^^^^^^
  File "C:\Users\oasis\Aibybit_2\.venv\Lib\site-packages\telegram\ext\_updater.py", line 384, in polling_action_cb
    raise exc
  File "C:\Users\oasis\Aibybit_2\.venv\Lib\site-packages\telegram\ext\_updater.py", line 373, in polling_action_cb
    updates = await self.bot.get_updates(
              ^^^^^^^^^^^^^^^^^^^^^^^^^^^
  File "C:\Users\oasis\Aibybit_2\.venv\Lib\site-packages\telegram\ext\_extbot.py", line 558, in get_updates
    updates = await super().get_updates(
              ^^^^^^^^^^^^^^^^^^^^^^^^^^
  File "C:\Users\oasis\Aibybit_2\.venv\Lib\site-packages\telegram\_bot.py", line 525, in decorator
    result = await func(self, *args, **kwargs)  # skipcq: PYL-E1102
             ^^^^^^^^^^^^^^^^^^^^^^^^^^^^^^^^^
  File "C:\Users\oasis\Aibybit_2\.venv\Lib\site-packages\telegram\_bot.py", line 3584, in get_updates
    await self._post(
  File "C:\Users\oasis\Aibybit_2\.venv\Lib\site-packages\telegram\_bot.py", line 613, in _post
    return await self._do_post(
           ^^^^^^^^^^^^^^^^^^^^
  File "C:\Users\oasis\Aibybit_2\.venv\Lib\site-packages\telegram\ext\_extbot.py", line 340, in _do_post
    return await super()._do_post(
           ^^^^^^^^^^^^^^^^^^^^^^^
  File "C:\Users\oasis\Aibybit_2\.venv\Lib\site-packages\telegram\_bot.py", line 641, in _do_post
    return await request.post(
           ^^^^^^^^^^^^^^^^^^^
  File "C:\Users\oasis\Aibybit_2\.venv\Lib\site-packages\telegram\request\_baserequest.py", line 200, in post
    result = await self._request_wrapper(
             ^^^^^^^^^^^^^^^^^^^^^^^^^^^^
  File "C:\Users\oasis\Aibybit_2\.venv\Lib\site-packages\telegram\request\_baserequest.py", line 340, in _request_wrapper
    raise exc
  File "C:\Users\oasis\Aibybit_2\.venv\Lib\site-packages\telegram\request\_baserequest.py", line 330, in _request_wrapper
    code, payload = await self.do_request(
                    ^^^^^^^^^^^^^^^^^^^^^^
  File "C:\Users\oasis\Aibybit_2\.venv\Lib\site-packages\telegram\request\_httpxrequest.py", line 292, in do_request
    raise NetworkError(f"httpx.{err.__class__.__name__}: {err}") from err
telegram.error.NetworkError: httpx.ConnectError: [Errno 11001] getaddrinfo failed
2025-03-04 14:18:17,787 - telegram.ext.Updater - ERROR - Error while getting Updates: httpx.ConnectError: [Errno 11001] getaddrinfo failed
2025-03-04 14:18:17,788 - telegram.ext.Updater - ERROR - Exception happened while polling for updates.
Traceback (most recent call last):
  File "C:\Users\oasis\Aibybit_2\.venv\Lib\site-packages\httpx\_transports\default.py", line 66, in map_httpcore_exceptions
    yield
  File "C:\Users\oasis\Aibybit_2\.venv\Lib\site-packages\httpx\_transports\default.py", line 366, in handle_async_request
    resp = await self._pool.handle_async_request(req)
           ^^^^^^^^^^^^^^^^^^^^^^^^^^^^^^^^^^^^^^^^^^
  File "C:\Users\oasis\Aibybit_2\.venv\Lib\site-packages\httpcore\_async\connection_pool.py", line 256, in handle_async_request
    raise exc from None
  File "C:\Users\oasis\Aibybit_2\.venv\Lib\site-packages\httpcore\_async\connection_pool.py", line 236, in handle_async_request
    response = await connection.handle_async_request(
               ^^^^^^^^^^^^^^^^^^^^^^^^^^^^^^^^^^^^^^
  File "C:\Users\oasis\Aibybit_2\.venv\Lib\site-packages\httpcore\_async\connection.py", line 101, in handle_async_request
    raise exc
  File "C:\Users\oasis\Aibybit_2\.venv\Lib\site-packages\httpcore\_async\connection.py", line 78, in handle_async_request
    stream = await self._connect(request)
             ^^^^^^^^^^^^^^^^^^^^^^^^^^^^
  File "C:\Users\oasis\Aibybit_2\.venv\Lib\site-packages\httpcore\_async\connection.py", line 124, in _connect
    stream = await self._network_backend.connect_tcp(**kwargs)
             ^^^^^^^^^^^^^^^^^^^^^^^^^^^^^^^^^^^^^^^^^^^^^^^^^
  File "C:\Users\oasis\Aibybit_2\.venv\Lib\site-packages\httpcore\_backends\auto.py", line 31, in connect_tcp
    return await self._backend.connect_tcp(
           ^^^^^^^^^^^^^^^^^^^^^^^^^^^^^^^^
  File "C:\Users\oasis\Aibybit_2\.venv\Lib\site-packages\httpcore\_backends\anyio.py", line 113, in connect_tcp
    with map_exceptions(exc_map):
  File "C:\Program Files\Python311\Lib\contextlib.py", line 155, in __exit__
    self.gen.throw(typ, value, traceback)
  File "C:\Users\oasis\Aibybit_2\.venv\Lib\site-packages\httpcore\_exceptions.py", line 14, in map_exceptions
    raise to_exc(exc) from exc
httpcore.ConnectError: [Errno 11001] getaddrinfo failed

The above exception was the direct cause of the following exception:

Traceback (most recent call last):
  File "C:\Users\oasis\Aibybit_2\.venv\Lib\site-packages\telegram\request\_httpxrequest.py", line 268, in do_request
    res = await self._client.request(
          ^^^^^^^^^^^^^^^^^^^^^^^^^^^
  File "C:\Users\oasis\Aibybit_2\.venv\Lib\site-packages\httpx\_client.py", line 1530, in request
    return await self.send(request, auth=auth, follow_redirects=follow_redirects)
           ^^^^^^^^^^^^^^^^^^^^^^^^^^^^^^^^^^^^^^^^^^^^^^^^^^^^^^^^^^^^^^^^^^^^^^
  File "C:\Users\oasis\Aibybit_2\.venv\Lib\site-packages\httpx\_client.py", line 1617, in send
    response = await self._send_handling_auth(
               ^^^^^^^^^^^^^^^^^^^^^^^^^^^^^^^
  File "C:\Users\oasis\Aibybit_2\.venv\Lib\site-packages\httpx\_client.py", line 1645, in _send_handling_auth
    response = await self._send_handling_redirects(
               ^^^^^^^^^^^^^^^^^^^^^^^^^^^^^^^^^^^^
  File "C:\Users\oasis\Aibybit_2\.venv\Lib\site-packages\httpx\_client.py", line 1682, in _send_handling_redirects
    response = await self._send_single_request(request)
               ^^^^^^^^^^^^^^^^^^^^^^^^^^^^^^^^^^^^^^^^
  File "C:\Users\oasis\Aibybit_2\.venv\Lib\site-packages\httpx\_client.py", line 1719, in _send_single_request
    response = await transport.handle_async_request(request)
               ^^^^^^^^^^^^^^^^^^^^^^^^^^^^^^^^^^^^^^^^^^^^^
  File "C:\Users\oasis\Aibybit_2\.venv\Lib\site-packages\httpx\_transports\default.py", line 365, in handle_async_request
    with map_httpcore_exceptions():
  File "C:\Program Files\Python311\Lib\contextlib.py", line 155, in __exit__
    self.gen.throw(typ, value, traceback)
  File "C:\Users\oasis\Aibybit_2\.venv\Lib\site-packages\httpx\_transports\default.py", line 83, in map_httpcore_exceptions
    raise mapped_exc(message) from exc
httpx.ConnectError: [Errno 11001] getaddrinfo failed

The above exception was the direct cause of the following exception:

Traceback (most recent call last):
  File "C:\Users\oasis\Aibybit_2\.venv\Lib\site-packages\telegram\ext\_updater.py", line 688, in _network_loop_retry
    if not await action_cb():
           ^^^^^^^^^^^^^^^^^
  File "C:\Users\oasis\Aibybit_2\.venv\Lib\site-packages\telegram\ext\_updater.py", line 384, in polling_action_cb
    raise exc
  File "C:\Users\oasis\Aibybit_2\.venv\Lib\site-packages\telegram\ext\_updater.py", line 373, in polling_action_cb
    updates = await self.bot.get_updates(
              ^^^^^^^^^^^^^^^^^^^^^^^^^^^
  File "C:\Users\oasis\Aibybit_2\.venv\Lib\site-packages\telegram\ext\_extbot.py", line 558, in get_updates
    updates = await super().get_updates(
              ^^^^^^^^^^^^^^^^^^^^^^^^^^
  File "C:\Users\oasis\Aibybit_2\.venv\Lib\site-packages\telegram\_bot.py", line 525, in decorator
    result = await func(self, *args, **kwargs)  # skipcq: PYL-E1102
             ^^^^^^^^^^^^^^^^^^^^^^^^^^^^^^^^^
  File "C:\Users\oasis\Aibybit_2\.venv\Lib\site-packages\telegram\_bot.py", line 3584, in get_updates
    await self._post(
  File "C:\Users\oasis\Aibybit_2\.venv\Lib\site-packages\telegram\_bot.py", line 613, in _post
    return await self._do_post(
           ^^^^^^^^^^^^^^^^^^^^
  File "C:\Users\oasis\Aibybit_2\.venv\Lib\site-packages\telegram\ext\_extbot.py", line 340, in _do_post
    return await super()._do_post(
           ^^^^^^^^^^^^^^^^^^^^^^^
  File "C:\Users\oasis\Aibybit_2\.venv\Lib\site-packages\telegram\_bot.py", line 641, in _do_post
    return await request.post(
           ^^^^^^^^^^^^^^^^^^^
  File "C:\Users\oasis\Aibybit_2\.venv\Lib\site-packages\telegram\request\_baserequest.py", line 200, in post
    result = await self._request_wrapper(
             ^^^^^^^^^^^^^^^^^^^^^^^^^^^^
  File "C:\Users\oasis\Aibybit_2\.venv\Lib\site-packages\telegram\request\_baserequest.py", line 340, in _request_wrapper
    raise exc
  File "C:\Users\oasis\Aibybit_2\.venv\Lib\site-packages\telegram\request\_baserequest.py", line 330, in _request_wrapper
    code, payload = await self.do_request(
                    ^^^^^^^^^^^^^^^^^^^^^^
  File "C:\Users\oasis\Aibybit_2\.venv\Lib\site-packages\telegram\request\_httpxrequest.py", line 292, in do_request
    raise NetworkError(f"httpx.{err.__class__.__name__}: {err}") from err
telegram.error.NetworkError: httpx.ConnectError: [Errno 11001] getaddrinfo failed
2025-03-04 14:18:25,394 - telegram.ext.Updater - ERROR - Error while getting Updates: httpx.ConnectError: [Errno 11001] getaddrinfo failed
2025-03-04 14:18:25,395 - telegram.ext.Updater - ERROR - Exception happened while polling for updates.
Traceback (most recent call last):
  File "C:\Users\oasis\Aibybit_2\.venv\Lib\site-packages\httpx\_transports\default.py", line 66, in map_httpcore_exceptions
    yield
  File "C:\Users\oasis\Aibybit_2\.venv\Lib\site-packages\httpx\_transports\default.py", line 366, in handle_async_request
    resp = await self._pool.handle_async_request(req)
           ^^^^^^^^^^^^^^^^^^^^^^^^^^^^^^^^^^^^^^^^^^
  File "C:\Users\oasis\Aibybit_2\.venv\Lib\site-packages\httpcore\_async\connection_pool.py", line 256, in handle_async_request
    raise exc from None
  File "C:\Users\oasis\Aibybit_2\.venv\Lib\site-packages\httpcore\_async\connection_pool.py", line 236, in handle_async_request
    response = await connection.handle_async_request(
               ^^^^^^^^^^^^^^^^^^^^^^^^^^^^^^^^^^^^^^
  File "C:\Users\oasis\Aibybit_2\.venv\Lib\site-packages\httpcore\_async\connection.py", line 101, in handle_async_request
    raise exc
  File "C:\Users\oasis\Aibybit_2\.venv\Lib\site-packages\httpcore\_async\connection.py", line 78, in handle_async_request
    stream = await self._connect(request)
             ^^^^^^^^^^^^^^^^^^^^^^^^^^^^
  File "C:\Users\oasis\Aibybit_2\.venv\Lib\site-packages\httpcore\_async\connection.py", line 124, in _connect
    stream = await self._network_backend.connect_tcp(**kwargs)
             ^^^^^^^^^^^^^^^^^^^^^^^^^^^^^^^^^^^^^^^^^^^^^^^^^
  File "C:\Users\oasis\Aibybit_2\.venv\Lib\site-packages\httpcore\_backends\auto.py", line 31, in connect_tcp
    return await self._backend.connect_tcp(
           ^^^^^^^^^^^^^^^^^^^^^^^^^^^^^^^^
  File "C:\Users\oasis\Aibybit_2\.venv\Lib\site-packages\httpcore\_backends\anyio.py", line 113, in connect_tcp
    with map_exceptions(exc_map):
  File "C:\Program Files\Python311\Lib\contextlib.py", line 155, in __exit__
    self.gen.throw(typ, value, traceback)
  File "C:\Users\oasis\Aibybit_2\.venv\Lib\site-packages\httpcore\_exceptions.py", line 14, in map_exceptions
    raise to_exc(exc) from exc
httpcore.ConnectError: [Errno 11001] getaddrinfo failed

The above exception was the direct cause of the following exception:

Traceback (most recent call last):
  File "C:\Users\oasis\Aibybit_2\.venv\Lib\site-packages\telegram\request\_httpxrequest.py", line 268, in do_request
    res = await self._client.request(
          ^^^^^^^^^^^^^^^^^^^^^^^^^^^
  File "C:\Users\oasis\Aibybit_2\.venv\Lib\site-packages\httpx\_client.py", line 1530, in request
    return await self.send(request, auth=auth, follow_redirects=follow_redirects)
           ^^^^^^^^^^^^^^^^^^^^^^^^^^^^^^^^^^^^^^^^^^^^^^^^^^^^^^^^^^^^^^^^^^^^^^
  File "C:\Users\oasis\Aibybit_2\.venv\Lib\site-packages\httpx\_client.py", line 1617, in send
    response = await self._send_handling_auth(
               ^^^^^^^^^^^^^^^^^^^^^^^^^^^^^^^
  File "C:\Users\oasis\Aibybit_2\.venv\Lib\site-packages\httpx\_client.py", line 1645, in _send_handling_auth
    response = await self._send_handling_redirects(
               ^^^^^^^^^^^^^^^^^^^^^^^^^^^^^^^^^^^^
  File "C:\Users\oasis\Aibybit_2\.venv\Lib\site-packages\httpx\_client.py", line 1682, in _send_handling_redirects
    response = await self._send_single_request(request)
               ^^^^^^^^^^^^^^^^^^^^^^^^^^^^^^^^^^^^^^^^
  File "C:\Users\oasis\Aibybit_2\.venv\Lib\site-packages\httpx\_client.py", line 1719, in _send_single_request
    response = await transport.handle_async_request(request)
               ^^^^^^^^^^^^^^^^^^^^^^^^^^^^^^^^^^^^^^^^^^^^^
  File "C:\Users\oasis\Aibybit_2\.venv\Lib\site-packages\httpx\_transports\default.py", line 365, in handle_async_request
    with map_httpcore_exceptions():
  File "C:\Program Files\Python311\Lib\contextlib.py", line 155, in __exit__
    self.gen.throw(typ, value, traceback)
  File "C:\Users\oasis\Aibybit_2\.venv\Lib\site-packages\httpx\_transports\default.py", line 83, in map_httpcore_exceptions
    raise mapped_exc(message) from exc
httpx.ConnectError: [Errno 11001] getaddrinfo failed

The above exception was the direct cause of the following exception:

Traceback (most recent call last):
  File "C:\Users\oasis\Aibybit_2\.venv\Lib\site-packages\telegram\ext\_updater.py", line 688, in _network_loop_retry
    if not await action_cb():
           ^^^^^^^^^^^^^^^^^
  File "C:\Users\oasis\Aibybit_2\.venv\Lib\site-packages\telegram\ext\_updater.py", line 384, in polling_action_cb
    raise exc
  File "C:\Users\oasis\Aibybit_2\.venv\Lib\site-packages\telegram\ext\_updater.py", line 373, in polling_action_cb
    updates = await self.bot.get_updates(
              ^^^^^^^^^^^^^^^^^^^^^^^^^^^
  File "C:\Users\oasis\Aibybit_2\.venv\Lib\site-packages\telegram\ext\_extbot.py", line 558, in get_updates
    updates = await super().get_updates(
              ^^^^^^^^^^^^^^^^^^^^^^^^^^
  File "C:\Users\oasis\Aibybit_2\.venv\Lib\site-packages\telegram\_bot.py", line 525, in decorator
    result = await func(self, *args, **kwargs)  # skipcq: PYL-E1102
             ^^^^^^^^^^^^^^^^^^^^^^^^^^^^^^^^^
  File "C:\Users\oasis\Aibybit_2\.venv\Lib\site-packages\telegram\_bot.py", line 3584, in get_updates
    await self._post(
  File "C:\Users\oasis\Aibybit_2\.venv\Lib\site-packages\telegram\_bot.py", line 613, in _post
    return await self._do_post(
           ^^^^^^^^^^^^^^^^^^^^
  File "C:\Users\oasis\Aibybit_2\.venv\Lib\site-packages\telegram\ext\_extbot.py", line 340, in _do_post
    return await super()._do_post(
           ^^^^^^^^^^^^^^^^^^^^^^^
  File "C:\Users\oasis\Aibybit_2\.venv\Lib\site-packages\telegram\_bot.py", line 641, in _do_post
    return await request.post(
           ^^^^^^^^^^^^^^^^^^^
  File "C:\Users\oasis\Aibybit_2\.venv\Lib\site-packages\telegram\request\_baserequest.py", line 200, in post
    result = await self._request_wrapper(
             ^^^^^^^^^^^^^^^^^^^^^^^^^^^^
  File "C:\Users\oasis\Aibybit_2\.venv\Lib\site-packages\telegram\request\_baserequest.py", line 340, in _request_wrapper
    raise exc
  File "C:\Users\oasis\Aibybit_2\.venv\Lib\site-packages\telegram\request\_baserequest.py", line 330, in _request_wrapper
    code, payload = await self.do_request(
                    ^^^^^^^^^^^^^^^^^^^^^^
  File "C:\Users\oasis\Aibybit_2\.venv\Lib\site-packages\telegram\request\_httpxrequest.py", line 292, in do_request
    raise NetworkError(f"httpx.{err.__class__.__name__}: {err}") from err
telegram.error.NetworkError: httpx.ConnectError: [Errno 11001] getaddrinfo failed
2025-03-04 14:18:36,813 - telegram.ext.Updater - ERROR - Error while getting Updates: httpx.ConnectError: [Errno 11001] getaddrinfo failed
2025-03-04 14:18:36,814 - telegram.ext.Updater - ERROR - Exception happened while polling for updates.
Traceback (most recent call last):
  File "C:\Users\oasis\Aibybit_2\.venv\Lib\site-packages\httpx\_transports\default.py", line 66, in map_httpcore_exceptions
    yield
  File "C:\Users\oasis\Aibybit_2\.venv\Lib\site-packages\httpx\_transports\default.py", line 366, in handle_async_request
    resp = await self._pool.handle_async_request(req)
           ^^^^^^^^^^^^^^^^^^^^^^^^^^^^^^^^^^^^^^^^^^
  File "C:\Users\oasis\Aibybit_2\.venv\Lib\site-packages\httpcore\_async\connection_pool.py", line 256, in handle_async_request
    raise exc from None
  File "C:\Users\oasis\Aibybit_2\.venv\Lib\site-packages\httpcore\_async\connection_pool.py", line 236, in handle_async_request
    response = await connection.handle_async_request(
               ^^^^^^^^^^^^^^^^^^^^^^^^^^^^^^^^^^^^^^
  File "C:\Users\oasis\Aibybit_2\.venv\Lib\site-packages\httpcore\_async\connection.py", line 101, in handle_async_request
    raise exc
  File "C:\Users\oasis\Aibybit_2\.venv\Lib\site-packages\httpcore\_async\connection.py", line 78, in handle_async_request
    stream = await self._connect(request)
             ^^^^^^^^^^^^^^^^^^^^^^^^^^^^
  File "C:\Users\oasis\Aibybit_2\.venv\Lib\site-packages\httpcore\_async\connection.py", line 124, in _connect
    stream = await self._network_backend.connect_tcp(**kwargs)
             ^^^^^^^^^^^^^^^^^^^^^^^^^^^^^^^^^^^^^^^^^^^^^^^^^
  File "C:\Users\oasis\Aibybit_2\.venv\Lib\site-packages\httpcore\_backends\auto.py", line 31, in connect_tcp
    return await self._backend.connect_tcp(
           ^^^^^^^^^^^^^^^^^^^^^^^^^^^^^^^^
  File "C:\Users\oasis\Aibybit_2\.venv\Lib\site-packages\httpcore\_backends\anyio.py", line 113, in connect_tcp
    with map_exceptions(exc_map):
  File "C:\Program Files\Python311\Lib\contextlib.py", line 155, in __exit__
    self.gen.throw(typ, value, traceback)
  File "C:\Users\oasis\Aibybit_2\.venv\Lib\site-packages\httpcore\_exceptions.py", line 14, in map_exceptions
    raise to_exc(exc) from exc
httpcore.ConnectError: [Errno 11001] getaddrinfo failed

The above exception was the direct cause of the following exception:

Traceback (most recent call last):
  File "C:\Users\oasis\Aibybit_2\.venv\Lib\site-packages\telegram\request\_httpxrequest.py", line 268, in do_request
    res = await self._client.request(
          ^^^^^^^^^^^^^^^^^^^^^^^^^^^
  File "C:\Users\oasis\Aibybit_2\.venv\Lib\site-packages\httpx\_client.py", line 1530, in request
    return await self.send(request, auth=auth, follow_redirects=follow_redirects)
           ^^^^^^^^^^^^^^^^^^^^^^^^^^^^^^^^^^^^^^^^^^^^^^^^^^^^^^^^^^^^^^^^^^^^^^
  File "C:\Users\oasis\Aibybit_2\.venv\Lib\site-packages\httpx\_client.py", line 1617, in send
    response = await self._send_handling_auth(
               ^^^^^^^^^^^^^^^^^^^^^^^^^^^^^^^
  File "C:\Users\oasis\Aibybit_2\.venv\Lib\site-packages\httpx\_client.py", line 1645, in _send_handling_auth
    response = await self._send_handling_redirects(
               ^^^^^^^^^^^^^^^^^^^^^^^^^^^^^^^^^^^^
  File "C:\Users\oasis\Aibybit_2\.venv\Lib\site-packages\httpx\_client.py", line 1682, in _send_handling_redirects
    response = await self._send_single_request(request)
               ^^^^^^^^^^^^^^^^^^^^^^^^^^^^^^^^^^^^^^^^
  File "C:\Users\oasis\Aibybit_2\.venv\Lib\site-packages\httpx\_client.py", line 1719, in _send_single_request
    response = await transport.handle_async_request(request)
               ^^^^^^^^^^^^^^^^^^^^^^^^^^^^^^^^^^^^^^^^^^^^^
  File "C:\Users\oasis\Aibybit_2\.venv\Lib\site-packages\httpx\_transports\default.py", line 365, in handle_async_request
    with map_httpcore_exceptions():
  File "C:\Program Files\Python311\Lib\contextlib.py", line 155, in __exit__
    self.gen.throw(typ, value, traceback)
  File "C:\Users\oasis\Aibybit_2\.venv\Lib\site-packages\httpx\_transports\default.py", line 83, in map_httpcore_exceptions
    raise mapped_exc(message) from exc
httpx.ConnectError: [Errno 11001] getaddrinfo failed

The above exception was the direct cause of the following exception:

Traceback (most recent call last):
  File "C:\Users\oasis\Aibybit_2\.venv\Lib\site-packages\telegram\ext\_updater.py", line 688, in _network_loop_retry
    if not await action_cb():
           ^^^^^^^^^^^^^^^^^
  File "C:\Users\oasis\Aibybit_2\.venv\Lib\site-packages\telegram\ext\_updater.py", line 384, in polling_action_cb
    raise exc
  File "C:\Users\oasis\Aibybit_2\.venv\Lib\site-packages\telegram\ext\_updater.py", line 373, in polling_action_cb
    updates = await self.bot.get_updates(
              ^^^^^^^^^^^^^^^^^^^^^^^^^^^
  File "C:\Users\oasis\Aibybit_2\.venv\Lib\site-packages\telegram\ext\_extbot.py", line 558, in get_updates
    updates = await super().get_updates(
              ^^^^^^^^^^^^^^^^^^^^^^^^^^
  File "C:\Users\oasis\Aibybit_2\.venv\Lib\site-packages\telegram\_bot.py", line 525, in decorator
    result = await func(self, *args, **kwargs)  # skipcq: PYL-E1102
             ^^^^^^^^^^^^^^^^^^^^^^^^^^^^^^^^^
  File "C:\Users\oasis\Aibybit_2\.venv\Lib\site-packages\telegram\_bot.py", line 3584, in get_updates
    await self._post(
  File "C:\Users\oasis\Aibybit_2\.venv\Lib\site-packages\telegram\_bot.py", line 613, in _post
    return await self._do_post(
           ^^^^^^^^^^^^^^^^^^^^
  File "C:\Users\oasis\Aibybit_2\.venv\Lib\site-packages\telegram\ext\_extbot.py", line 340, in _do_post
    return await super()._do_post(
           ^^^^^^^^^^^^^^^^^^^^^^^
  File "C:\Users\oasis\Aibybit_2\.venv\Lib\site-packages\telegram\_bot.py", line 641, in _do_post
    return await request.post(
           ^^^^^^^^^^^^^^^^^^^
  File "C:\Users\oasis\Aibybit_2\.venv\Lib\site-packages\telegram\request\_baserequest.py", line 200, in post
    result = await self._request_wrapper(
             ^^^^^^^^^^^^^^^^^^^^^^^^^^^^
  File "C:\Users\oasis\Aibybit_2\.venv\Lib\site-packages\telegram\request\_baserequest.py", line 340, in _request_wrapper
    raise exc
  File "C:\Users\oasis\Aibybit_2\.venv\Lib\site-packages\telegram\request\_baserequest.py", line 330, in _request_wrapper
    code, payload = await self.do_request(
                    ^^^^^^^^^^^^^^^^^^^^^^
  File "C:\Users\oasis\Aibybit_2\.venv\Lib\site-packages\telegram\request\_httpxrequest.py", line 292, in do_request
    raise NetworkError(f"httpx.{err.__class__.__name__}: {err}") from err
telegram.error.NetworkError: httpx.ConnectError: [Errno 11001] getaddrinfo failed
2025-03-04 14:18:53,917 - telegram.ext.Updater - ERROR - Error while getting Updates: httpx.ConnectError: [Errno 11001] getaddrinfo failed
2025-03-04 14:18:53,919 - telegram.ext.Updater - ERROR - Exception happened while polling for updates.
Traceback (most recent call last):
  File "C:\Users\oasis\Aibybit_2\.venv\Lib\site-packages\httpx\_transports\default.py", line 66, in map_httpcore_exceptions
    yield
  File "C:\Users\oasis\Aibybit_2\.venv\Lib\site-packages\httpx\_transports\default.py", line 366, in handle_async_request
    resp = await self._pool.handle_async_request(req)
           ^^^^^^^^^^^^^^^^^^^^^^^^^^^^^^^^^^^^^^^^^^
  File "C:\Users\oasis\Aibybit_2\.venv\Lib\site-packages\httpcore\_async\connection_pool.py", line 256, in handle_async_request
    raise exc from None
  File "C:\Users\oasis\Aibybit_2\.venv\Lib\site-packages\httpcore\_async\connection_pool.py", line 236, in handle_async_request
    response = await connection.handle_async_request(
               ^^^^^^^^^^^^^^^^^^^^^^^^^^^^^^^^^^^^^^
  File "C:\Users\oasis\Aibybit_2\.venv\Lib\site-packages\httpcore\_async\connection.py", line 101, in handle_async_request
    raise exc
  File "C:\Users\oasis\Aibybit_2\.venv\Lib\site-packages\httpcore\_async\connection.py", line 78, in handle_async_request
    stream = await self._connect(request)
             ^^^^^^^^^^^^^^^^^^^^^^^^^^^^
  File "C:\Users\oasis\Aibybit_2\.venv\Lib\site-packages\httpcore\_async\connection.py", line 124, in _connect
    stream = await self._network_backend.connect_tcp(**kwargs)
             ^^^^^^^^^^^^^^^^^^^^^^^^^^^^^^^^^^^^^^^^^^^^^^^^^
  File "C:\Users\oasis\Aibybit_2\.venv\Lib\site-packages\httpcore\_backends\auto.py", line 31, in connect_tcp
    return await self._backend.connect_tcp(
           ^^^^^^^^^^^^^^^^^^^^^^^^^^^^^^^^
  File "C:\Users\oasis\Aibybit_2\.venv\Lib\site-packages\httpcore\_backends\anyio.py", line 113, in connect_tcp
    with map_exceptions(exc_map):
  File "C:\Program Files\Python311\Lib\contextlib.py", line 155, in __exit__
    self.gen.throw(typ, value, traceback)
  File "C:\Users\oasis\Aibybit_2\.venv\Lib\site-packages\httpcore\_exceptions.py", line 14, in map_exceptions
    raise to_exc(exc) from exc
httpcore.ConnectError: [Errno 11001] getaddrinfo failed

The above exception was the direct cause of the following exception:

Traceback (most recent call last):
  File "C:\Users\oasis\Aibybit_2\.venv\Lib\site-packages\telegram\request\_httpxrequest.py", line 268, in do_request
    res = await self._client.request(
          ^^^^^^^^^^^^^^^^^^^^^^^^^^^
  File "C:\Users\oasis\Aibybit_2\.venv\Lib\site-packages\httpx\_client.py", line 1530, in request
    return await self.send(request, auth=auth, follow_redirects=follow_redirects)
           ^^^^^^^^^^^^^^^^^^^^^^^^^^^^^^^^^^^^^^^^^^^^^^^^^^^^^^^^^^^^^^^^^^^^^^
  File "C:\Users\oasis\Aibybit_2\.venv\Lib\site-packages\httpx\_client.py", line 1617, in send
    response = await self._send_handling_auth(
               ^^^^^^^^^^^^^^^^^^^^^^^^^^^^^^^
  File "C:\Users\oasis\Aibybit_2\.venv\Lib\site-packages\httpx\_client.py", line 1645, in _send_handling_auth
    response = await self._send_handling_redirects(
               ^^^^^^^^^^^^^^^^^^^^^^^^^^^^^^^^^^^^
  File "C:\Users\oasis\Aibybit_2\.venv\Lib\site-packages\httpx\_client.py", line 1682, in _send_handling_redirects
    response = await self._send_single_request(request)
               ^^^^^^^^^^^^^^^^^^^^^^^^^^^^^^^^^^^^^^^^
  File "C:\Users\oasis\Aibybit_2\.venv\Lib\site-packages\httpx\_client.py", line 1719, in _send_single_request
    response = await transport.handle_async_request(request)
               ^^^^^^^^^^^^^^^^^^^^^^^^^^^^^^^^^^^^^^^^^^^^^
  File "C:\Users\oasis\Aibybit_2\.venv\Lib\site-packages\httpx\_transports\default.py", line 365, in handle_async_request
    with map_httpcore_exceptions():
  File "C:\Program Files\Python311\Lib\contextlib.py", line 155, in __exit__
    self.gen.throw(typ, value, traceback)
  File "C:\Users\oasis\Aibybit_2\.venv\Lib\site-packages\httpx\_transports\default.py", line 83, in map_httpcore_exceptions
    raise mapped_exc(message) from exc
httpx.ConnectError: [Errno 11001] getaddrinfo failed

The above exception was the direct cause of the following exception:

Traceback (most recent call last):
  File "C:\Users\oasis\Aibybit_2\.venv\Lib\site-packages\telegram\ext\_updater.py", line 688, in _network_loop_retry
    if not await action_cb():
           ^^^^^^^^^^^^^^^^^
  File "C:\Users\oasis\Aibybit_2\.venv\Lib\site-packages\telegram\ext\_updater.py", line 384, in polling_action_cb
    raise exc
  File "C:\Users\oasis\Aibybit_2\.venv\Lib\site-packages\telegram\ext\_updater.py", line 373, in polling_action_cb
    updates = await self.bot.get_updates(
              ^^^^^^^^^^^^^^^^^^^^^^^^^^^
  File "C:\Users\oasis\Aibybit_2\.venv\Lib\site-packages\telegram\ext\_extbot.py", line 558, in get_updates
    updates = await super().get_updates(
              ^^^^^^^^^^^^^^^^^^^^^^^^^^
  File "C:\Users\oasis\Aibybit_2\.venv\Lib\site-packages\telegram\_bot.py", line 525, in decorator
    result = await func(self, *args, **kwargs)  # skipcq: PYL-E1102
             ^^^^^^^^^^^^^^^^^^^^^^^^^^^^^^^^^
  File "C:\Users\oasis\Aibybit_2\.venv\Lib\site-packages\telegram\_bot.py", line 3584, in get_updates
    await self._post(
  File "C:\Users\oasis\Aibybit_2\.venv\Lib\site-packages\telegram\_bot.py", line 613, in _post
    return await self._do_post(
           ^^^^^^^^^^^^^^^^^^^^
  File "C:\Users\oasis\Aibybit_2\.venv\Lib\site-packages\telegram\ext\_extbot.py", line 340, in _do_post
    return await super()._do_post(
           ^^^^^^^^^^^^^^^^^^^^^^^
  File "C:\Users\oasis\Aibybit_2\.venv\Lib\site-packages\telegram\_bot.py", line 641, in _do_post
    return await request.post(
           ^^^^^^^^^^^^^^^^^^^
  File "C:\Users\oasis\Aibybit_2\.venv\Lib\site-packages\telegram\request\_baserequest.py", line 200, in post
    result = await self._request_wrapper(
             ^^^^^^^^^^^^^^^^^^^^^^^^^^^^
  File "C:\Users\oasis\Aibybit_2\.venv\Lib\site-packages\telegram\request\_baserequest.py", line 340, in _request_wrapper
    raise exc
  File "C:\Users\oasis\Aibybit_2\.venv\Lib\site-packages\telegram\request\_baserequest.py", line 330, in _request_wrapper
    code, payload = await self.do_request(
                    ^^^^^^^^^^^^^^^^^^^^^^
  File "C:\Users\oasis\Aibybit_2\.venv\Lib\site-packages\telegram\request\_httpxrequest.py", line 292, in do_request
    raise NetworkError(f"httpx.{err.__class__.__name__}: {err}") from err
telegram.error.NetworkError: httpx.ConnectError: [Errno 11001] getaddrinfo failed
2025-03-04 14:19:19,576 - telegram.ext.Updater - ERROR - Error while getting Updates: httpx.ConnectError: [Errno 11001] getaddrinfo failed
2025-03-04 14:19:19,576 - telegram.ext.Updater - ERROR - Exception happened while polling for updates.
Traceback (most recent call last):
  File "C:\Users\oasis\Aibybit_2\.venv\Lib\site-packages\httpx\_transports\default.py", line 66, in map_httpcore_exceptions
    yield
  File "C:\Users\oasis\Aibybit_2\.venv\Lib\site-packages\httpx\_transports\default.py", line 366, in handle_async_request
    resp = await self._pool.handle_async_request(req)
           ^^^^^^^^^^^^^^^^^^^^^^^^^^^^^^^^^^^^^^^^^^
  File "C:\Users\oasis\Aibybit_2\.venv\Lib\site-packages\httpcore\_async\connection_pool.py", line 256, in handle_async_request
    raise exc from None
  File "C:\Users\oasis\Aibybit_2\.venv\Lib\site-packages\httpcore\_async\connection_pool.py", line 236, in handle_async_request
    response = await connection.handle_async_request(
               ^^^^^^^^^^^^^^^^^^^^^^^^^^^^^^^^^^^^^^
  File "C:\Users\oasis\Aibybit_2\.venv\Lib\site-packages\httpcore\_async\connection.py", line 101, in handle_async_request
    raise exc
  File "C:\Users\oasis\Aibybit_2\.venv\Lib\site-packages\httpcore\_async\connection.py", line 78, in handle_async_request
    stream = await self._connect(request)
             ^^^^^^^^^^^^^^^^^^^^^^^^^^^^
  File "C:\Users\oasis\Aibybit_2\.venv\Lib\site-packages\httpcore\_async\connection.py", line 124, in _connect
    stream = await self._network_backend.connect_tcp(**kwargs)
             ^^^^^^^^^^^^^^^^^^^^^^^^^^^^^^^^^^^^^^^^^^^^^^^^^
  File "C:\Users\oasis\Aibybit_2\.venv\Lib\site-packages\httpcore\_backends\auto.py", line 31, in connect_tcp
    return await self._backend.connect_tcp(
           ^^^^^^^^^^^^^^^^^^^^^^^^^^^^^^^^
  File "C:\Users\oasis\Aibybit_2\.venv\Lib\site-packages\httpcore\_backends\anyio.py", line 113, in connect_tcp
    with map_exceptions(exc_map):
  File "C:\Program Files\Python311\Lib\contextlib.py", line 155, in __exit__
    self.gen.throw(typ, value, traceback)
  File "C:\Users\oasis\Aibybit_2\.venv\Lib\site-packages\httpcore\_exceptions.py", line 14, in map_exceptions
    raise to_exc(exc) from exc
httpcore.ConnectError: [Errno 11001] getaddrinfo failed

The above exception was the direct cause of the following exception:

Traceback (most recent call last):
  File "C:\Users\oasis\Aibybit_2\.venv\Lib\site-packages\telegram\request\_httpxrequest.py", line 268, in do_request
    res = await self._client.request(
          ^^^^^^^^^^^^^^^^^^^^^^^^^^^
  File "C:\Users\oasis\Aibybit_2\.venv\Lib\site-packages\httpx\_client.py", line 1530, in request
    return await self.send(request, auth=auth, follow_redirects=follow_redirects)
           ^^^^^^^^^^^^^^^^^^^^^^^^^^^^^^^^^^^^^^^^^^^^^^^^^^^^^^^^^^^^^^^^^^^^^^
  File "C:\Users\oasis\Aibybit_2\.venv\Lib\site-packages\httpx\_client.py", line 1617, in send
    response = await self._send_handling_auth(
               ^^^^^^^^^^^^^^^^^^^^^^^^^^^^^^^
  File "C:\Users\oasis\Aibybit_2\.venv\Lib\site-packages\httpx\_client.py", line 1645, in _send_handling_auth
    response = await self._send_handling_redirects(
               ^^^^^^^^^^^^^^^^^^^^^^^^^^^^^^^^^^^^
  File "C:\Users\oasis\Aibybit_2\.venv\Lib\site-packages\httpx\_client.py", line 1682, in _send_handling_redirects
    response = await self._send_single_request(request)
               ^^^^^^^^^^^^^^^^^^^^^^^^^^^^^^^^^^^^^^^^
  File "C:\Users\oasis\Aibybit_2\.venv\Lib\site-packages\httpx\_client.py", line 1719, in _send_single_request
    response = await transport.handle_async_request(request)
               ^^^^^^^^^^^^^^^^^^^^^^^^^^^^^^^^^^^^^^^^^^^^^
  File "C:\Users\oasis\Aibybit_2\.venv\Lib\site-packages\httpx\_transports\default.py", line 365, in handle_async_request
    with map_httpcore_exceptions():
  File "C:\Program Files\Python311\Lib\contextlib.py", line 155, in __exit__
    self.gen.throw(typ, value, traceback)
  File "C:\Users\oasis\Aibybit_2\.venv\Lib\site-packages\httpx\_transports\default.py", line 83, in map_httpcore_exceptions
    raise mapped_exc(message) from exc
httpx.ConnectError: [Errno 11001] getaddrinfo failed

The above exception was the direct cause of the following exception:

Traceback (most recent call last):
  File "C:\Users\oasis\Aibybit_2\.venv\Lib\site-packages\telegram\ext\_updater.py", line 688, in _network_loop_retry
    if not await action_cb():
           ^^^^^^^^^^^^^^^^^
  File "C:\Users\oasis\Aibybit_2\.venv\Lib\site-packages\telegram\ext\_updater.py", line 384, in polling_action_cb
    raise exc
  File "C:\Users\oasis\Aibybit_2\.venv\Lib\site-packages\telegram\ext\_updater.py", line 373, in polling_action_cb
    updates = await self.bot.get_updates(
              ^^^^^^^^^^^^^^^^^^^^^^^^^^^
  File "C:\Users\oasis\Aibybit_2\.venv\Lib\site-packages\telegram\ext\_extbot.py", line 558, in get_updates
    updates = await super().get_updates(
              ^^^^^^^^^^^^^^^^^^^^^^^^^^
  File "C:\Users\oasis\Aibybit_2\.venv\Lib\site-packages\telegram\_bot.py", line 525, in decorator
    result = await func(self, *args, **kwargs)  # skipcq: PYL-E1102
             ^^^^^^^^^^^^^^^^^^^^^^^^^^^^^^^^^
  File "C:\Users\oasis\Aibybit_2\.venv\Lib\site-packages\telegram\_bot.py", line 3584, in get_updates
    await self._post(
  File "C:\Users\oasis\Aibybit_2\.venv\Lib\site-packages\telegram\_bot.py", line 613, in _post
    return await self._do_post(
           ^^^^^^^^^^^^^^^^^^^^
  File "C:\Users\oasis\Aibybit_2\.venv\Lib\site-packages\telegram\ext\_extbot.py", line 340, in _do_post
    return await super()._do_post(
           ^^^^^^^^^^^^^^^^^^^^^^^
  File "C:\Users\oasis\Aibybit_2\.venv\Lib\site-packages\telegram\_bot.py", line 641, in _do_post
    return await request.post(
           ^^^^^^^^^^^^^^^^^^^
  File "C:\Users\oasis\Aibybit_2\.venv\Lib\site-packages\telegram\request\_baserequest.py", line 200, in post
    result = await self._request_wrapper(
             ^^^^^^^^^^^^^^^^^^^^^^^^^^^^
  File "C:\Users\oasis\Aibybit_2\.venv\Lib\site-packages\telegram\request\_baserequest.py", line 340, in _request_wrapper
    raise exc
  File "C:\Users\oasis\Aibybit_2\.venv\Lib\site-packages\telegram\request\_baserequest.py", line 330, in _request_wrapper
    code, payload = await self.do_request(
                    ^^^^^^^^^^^^^^^^^^^^^^
  File "C:\Users\oasis\Aibybit_2\.venv\Lib\site-packages\telegram\request\_httpxrequest.py", line 292, in do_request
    raise NetworkError(f"httpx.{err.__class__.__name__}: {err}") from err
telegram.error.NetworkError: httpx.ConnectError: [Errno 11001] getaddrinfo failed
2025-03-04 14:42:07,583 - telegram.ext.Updater - ERROR - Error while getting Updates: httpx.ConnectError: [Errno 11001] getaddrinfo failed
2025-03-04 14:42:07,593 - telegram.ext.Updater - ERROR - Exception happened while polling for updates.
Traceback (most recent call last):
  File "C:\Users\oasis\Aibybit_2\.venv\Lib\site-packages\httpx\_transports\default.py", line 66, in map_httpcore_exceptions
    yield
  File "C:\Users\oasis\Aibybit_2\.venv\Lib\site-packages\httpx\_transports\default.py", line 366, in handle_async_request
    resp = await self._pool.handle_async_request(req)
           ^^^^^^^^^^^^^^^^^^^^^^^^^^^^^^^^^^^^^^^^^^
  File "C:\Users\oasis\Aibybit_2\.venv\Lib\site-packages\httpcore\_async\connection_pool.py", line 256, in handle_async_request
    raise exc from None
  File "C:\Users\oasis\Aibybit_2\.venv\Lib\site-packages\httpcore\_async\connection_pool.py", line 236, in handle_async_request
    response = await connection.handle_async_request(
               ^^^^^^^^^^^^^^^^^^^^^^^^^^^^^^^^^^^^^^
  File "C:\Users\oasis\Aibybit_2\.venv\Lib\site-packages\httpcore\_async\connection.py", line 101, in handle_async_request
    raise exc
  File "C:\Users\oasis\Aibybit_2\.venv\Lib\site-packages\httpcore\_async\connection.py", line 78, in handle_async_request
    stream = await self._connect(request)
             ^^^^^^^^^^^^^^^^^^^^^^^^^^^^
  File "C:\Users\oasis\Aibybit_2\.venv\Lib\site-packages\httpcore\_async\connection.py", line 124, in _connect
    stream = await self._network_backend.connect_tcp(**kwargs)
             ^^^^^^^^^^^^^^^^^^^^^^^^^^^^^^^^^^^^^^^^^^^^^^^^^
  File "C:\Users\oasis\Aibybit_2\.venv\Lib\site-packages\httpcore\_backends\auto.py", line 31, in connect_tcp
    return await self._backend.connect_tcp(
           ^^^^^^^^^^^^^^^^^^^^^^^^^^^^^^^^
  File "C:\Users\oasis\Aibybit_2\.venv\Lib\site-packages\httpcore\_backends\anyio.py", line 113, in connect_tcp
    with map_exceptions(exc_map):
  File "C:\Program Files\Python311\Lib\contextlib.py", line 155, in __exit__
    self.gen.throw(typ, value, traceback)
  File "C:\Users\oasis\Aibybit_2\.venv\Lib\site-packages\httpcore\_exceptions.py", line 14, in map_exceptions
    raise to_exc(exc) from exc
httpcore.ConnectError: [Errno 11001] getaddrinfo failed

The above exception was the direct cause of the following exception:

Traceback (most recent call last):
  File "C:\Users\oasis\Aibybit_2\.venv\Lib\site-packages\telegram\request\_httpxrequest.py", line 268, in do_request
    res = await self._client.request(
          ^^^^^^^^^^^^^^^^^^^^^^^^^^^
  File "C:\Users\oasis\Aibybit_2\.venv\Lib\site-packages\httpx\_client.py", line 1530, in request
    return await self.send(request, auth=auth, follow_redirects=follow_redirects)
           ^^^^^^^^^^^^^^^^^^^^^^^^^^^^^^^^^^^^^^^^^^^^^^^^^^^^^^^^^^^^^^^^^^^^^^
  File "C:\Users\oasis\Aibybit_2\.venv\Lib\site-packages\httpx\_client.py", line 1617, in send
    response = await self._send_handling_auth(
               ^^^^^^^^^^^^^^^^^^^^^^^^^^^^^^^
  File "C:\Users\oasis\Aibybit_2\.venv\Lib\site-packages\httpx\_client.py", line 1645, in _send_handling_auth
    response = await self._send_handling_redirects(
               ^^^^^^^^^^^^^^^^^^^^^^^^^^^^^^^^^^^^
  File "C:\Users\oasis\Aibybit_2\.venv\Lib\site-packages\httpx\_client.py", line 1682, in _send_handling_redirects
    response = await self._send_single_request(request)
               ^^^^^^^^^^^^^^^^^^^^^^^^^^^^^^^^^^^^^^^^
  File "C:\Users\oasis\Aibybit_2\.venv\Lib\site-packages\httpx\_client.py", line 1719, in _send_single_request
    response = await transport.handle_async_request(request)
               ^^^^^^^^^^^^^^^^^^^^^^^^^^^^^^^^^^^^^^^^^^^^^
  File "C:\Users\oasis\Aibybit_2\.venv\Lib\site-packages\httpx\_transports\default.py", line 365, in handle_async_request
    with map_httpcore_exceptions():
  File "C:\Program Files\Python311\Lib\contextlib.py", line 155, in __exit__
    self.gen.throw(typ, value, traceback)
  File "C:\Users\oasis\Aibybit_2\.venv\Lib\site-packages\httpx\_transports\default.py", line 83, in map_httpcore_exceptions
    raise mapped_exc(message) from exc
httpx.ConnectError: [Errno 11001] getaddrinfo failed

The above exception was the direct cause of the following exception:

Traceback (most recent call last):
  File "C:\Users\oasis\Aibybit_2\.venv\Lib\site-packages\telegram\ext\_updater.py", line 688, in _network_loop_retry
    if not await action_cb():
           ^^^^^^^^^^^^^^^^^
  File "C:\Users\oasis\Aibybit_2\.venv\Lib\site-packages\telegram\ext\_updater.py", line 384, in polling_action_cb
    raise exc
  File "C:\Users\oasis\Aibybit_2\.venv\Lib\site-packages\telegram\ext\_updater.py", line 373, in polling_action_cb
    updates = await self.bot.get_updates(
              ^^^^^^^^^^^^^^^^^^^^^^^^^^^
  File "C:\Users\oasis\Aibybit_2\.venv\Lib\site-packages\telegram\ext\_extbot.py", line 558, in get_updates
    updates = await super().get_updates(
              ^^^^^^^^^^^^^^^^^^^^^^^^^^
  File "C:\Users\oasis\Aibybit_2\.venv\Lib\site-packages\telegram\_bot.py", line 525, in decorator
    result = await func(self, *args, **kwargs)  # skipcq: PYL-E1102
             ^^^^^^^^^^^^^^^^^^^^^^^^^^^^^^^^^
  File "C:\Users\oasis\Aibybit_2\.venv\Lib\site-packages\telegram\_bot.py", line 3584, in get_updates
    await self._post(
  File "C:\Users\oasis\Aibybit_2\.venv\Lib\site-packages\telegram\_bot.py", line 613, in _post
    return await self._do_post(
           ^^^^^^^^^^^^^^^^^^^^
  File "C:\Users\oasis\Aibybit_2\.venv\Lib\site-packages\telegram\ext\_extbot.py", line 340, in _do_post
    return await super()._do_post(
           ^^^^^^^^^^^^^^^^^^^^^^^
  File "C:\Users\oasis\Aibybit_2\.venv\Lib\site-packages\telegram\_bot.py", line 641, in _do_post
    return await request.post(
           ^^^^^^^^^^^^^^^^^^^
  File "C:\Users\oasis\Aibybit_2\.venv\Lib\site-packages\telegram\request\_baserequest.py", line 200, in post
    result = await self._request_wrapper(
             ^^^^^^^^^^^^^^^^^^^^^^^^^^^^
  File "C:\Users\oasis\Aibybit_2\.venv\Lib\site-packages\telegram\request\_baserequest.py", line 340, in _request_wrapper
    raise exc
  File "C:\Users\oasis\Aibybit_2\.venv\Lib\site-packages\telegram\request\_baserequest.py", line 330, in _request_wrapper
    code, payload = await self.do_request(
                    ^^^^^^^^^^^^^^^^^^^^^^
  File "C:\Users\oasis\Aibybit_2\.venv\Lib\site-packages\telegram\request\_httpxrequest.py", line 292, in do_request
    raise NetworkError(f"httpx.{err.__class__.__name__}: {err}") from err
telegram.error.NetworkError: httpx.ConnectError: [Errno 11001] getaddrinfo failed
2025-03-04 15:11:28,549 - telegram.ext.Updater - ERROR - Error while getting Updates: httpx.ConnectError: [Errno 11001] getaddrinfo failed
2025-03-04 15:11:28,551 - telegram.ext.Updater - ERROR - Exception happened while polling for updates.
Traceback (most recent call last):
  File "C:\Users\oasis\Aibybit_2\.venv\Lib\site-packages\httpx\_transports\default.py", line 66, in map_httpcore_exceptions
    yield
  File "C:\Users\oasis\Aibybit_2\.venv\Lib\site-packages\httpx\_transports\default.py", line 366, in handle_async_request
    resp = await self._pool.handle_async_request(req)
           ^^^^^^^^^^^^^^^^^^^^^^^^^^^^^^^^^^^^^^^^^^
  File "C:\Users\oasis\Aibybit_2\.venv\Lib\site-packages\httpcore\_async\connection_pool.py", line 256, in handle_async_request
    raise exc from None
  File "C:\Users\oasis\Aibybit_2\.venv\Lib\site-packages\httpcore\_async\connection_pool.py", line 236, in handle_async_request
    response = await connection.handle_async_request(
               ^^^^^^^^^^^^^^^^^^^^^^^^^^^^^^^^^^^^^^
  File "C:\Users\oasis\Aibybit_2\.venv\Lib\site-packages\httpcore\_async\connection.py", line 101, in handle_async_request
    raise exc
  File "C:\Users\oasis\Aibybit_2\.venv\Lib\site-packages\httpcore\_async\connection.py", line 78, in handle_async_request
    stream = await self._connect(request)
             ^^^^^^^^^^^^^^^^^^^^^^^^^^^^
  File "C:\Users\oasis\Aibybit_2\.venv\Lib\site-packages\httpcore\_async\connection.py", line 124, in _connect
    stream = await self._network_backend.connect_tcp(**kwargs)
             ^^^^^^^^^^^^^^^^^^^^^^^^^^^^^^^^^^^^^^^^^^^^^^^^^
  File "C:\Users\oasis\Aibybit_2\.venv\Lib\site-packages\httpcore\_backends\auto.py", line 31, in connect_tcp
    return await self._backend.connect_tcp(
           ^^^^^^^^^^^^^^^^^^^^^^^^^^^^^^^^
  File "C:\Users\oasis\Aibybit_2\.venv\Lib\site-packages\httpcore\_backends\anyio.py", line 113, in connect_tcp
    with map_exceptions(exc_map):
  File "C:\Program Files\Python311\Lib\contextlib.py", line 155, in __exit__
    self.gen.throw(typ, value, traceback)
  File "C:\Users\oasis\Aibybit_2\.venv\Lib\site-packages\httpcore\_exceptions.py", line 14, in map_exceptions
    raise to_exc(exc) from exc
httpcore.ConnectError: [Errno 11001] getaddrinfo failed

The above exception was the direct cause of the following exception:

Traceback (most recent call last):
  File "C:\Users\oasis\Aibybit_2\.venv\Lib\site-packages\telegram\request\_httpxrequest.py", line 268, in do_request
    res = await self._client.request(
          ^^^^^^^^^^^^^^^^^^^^^^^^^^^
  File "C:\Users\oasis\Aibybit_2\.venv\Lib\site-packages\httpx\_client.py", line 1530, in request
    return await self.send(request, auth=auth, follow_redirects=follow_redirects)
           ^^^^^^^^^^^^^^^^^^^^^^^^^^^^^^^^^^^^^^^^^^^^^^^^^^^^^^^^^^^^^^^^^^^^^^
  File "C:\Users\oasis\Aibybit_2\.venv\Lib\site-packages\httpx\_client.py", line 1617, in send
    response = await self._send_handling_auth(
               ^^^^^^^^^^^^^^^^^^^^^^^^^^^^^^^
  File "C:\Users\oasis\Aibybit_2\.venv\Lib\site-packages\httpx\_client.py", line 1645, in _send_handling_auth
    response = await self._send_handling_redirects(
               ^^^^^^^^^^^^^^^^^^^^^^^^^^^^^^^^^^^^
  File "C:\Users\oasis\Aibybit_2\.venv\Lib\site-packages\httpx\_client.py", line 1682, in _send_handling_redirects
    response = await self._send_single_request(request)
               ^^^^^^^^^^^^^^^^^^^^^^^^^^^^^^^^^^^^^^^^
  File "C:\Users\oasis\Aibybit_2\.venv\Lib\site-packages\httpx\_client.py", line 1719, in _send_single_request
    response = await transport.handle_async_request(request)
               ^^^^^^^^^^^^^^^^^^^^^^^^^^^^^^^^^^^^^^^^^^^^^
  File "C:\Users\oasis\Aibybit_2\.venv\Lib\site-packages\httpx\_transports\default.py", line 365, in handle_async_request
    with map_httpcore_exceptions():
  File "C:\Program Files\Python311\Lib\contextlib.py", line 155, in __exit__
    self.gen.throw(typ, value, traceback)
  File "C:\Users\oasis\Aibybit_2\.venv\Lib\site-packages\httpx\_transports\default.py", line 83, in map_httpcore_exceptions
    raise mapped_exc(message) from exc
httpx.ConnectError: [Errno 11001] getaddrinfo failed

The above exception was the direct cause of the following exception:

Traceback (most recent call last):
  File "C:\Users\oasis\Aibybit_2\.venv\Lib\site-packages\telegram\ext\_updater.py", line 688, in _network_loop_retry
    if not await action_cb():
           ^^^^^^^^^^^^^^^^^
  File "C:\Users\oasis\Aibybit_2\.venv\Lib\site-packages\telegram\ext\_updater.py", line 384, in polling_action_cb
    raise exc
  File "C:\Users\oasis\Aibybit_2\.venv\Lib\site-packages\telegram\ext\_updater.py", line 373, in polling_action_cb
    updates = await self.bot.get_updates(
              ^^^^^^^^^^^^^^^^^^^^^^^^^^^
  File "C:\Users\oasis\Aibybit_2\.venv\Lib\site-packages\telegram\ext\_extbot.py", line 558, in get_updates
    updates = await super().get_updates(
              ^^^^^^^^^^^^^^^^^^^^^^^^^^
  File "C:\Users\oasis\Aibybit_2\.venv\Lib\site-packages\telegram\_bot.py", line 525, in decorator
    result = await func(self, *args, **kwargs)  # skipcq: PYL-E1102
             ^^^^^^^^^^^^^^^^^^^^^^^^^^^^^^^^^
  File "C:\Users\oasis\Aibybit_2\.venv\Lib\site-packages\telegram\_bot.py", line 3584, in get_updates
    await self._post(
  File "C:\Users\oasis\Aibybit_2\.venv\Lib\site-packages\telegram\_bot.py", line 613, in _post
    return await self._do_post(
           ^^^^^^^^^^^^^^^^^^^^
  File "C:\Users\oasis\Aibybit_2\.venv\Lib\site-packages\telegram\ext\_extbot.py", line 340, in _do_post
    return await super()._do_post(
           ^^^^^^^^^^^^^^^^^^^^^^^
  File "C:\Users\oasis\Aibybit_2\.venv\Lib\site-packages\telegram\_bot.py", line 641, in _do_post
    return await request.post(
           ^^^^^^^^^^^^^^^^^^^
  File "C:\Users\oasis\Aibybit_2\.venv\Lib\site-packages\telegram\request\_baserequest.py", line 200, in post
    result = await self._request_wrapper(
             ^^^^^^^^^^^^^^^^^^^^^^^^^^^^
  File "C:\Users\oasis\Aibybit_2\.venv\Lib\site-packages\telegram\request\_baserequest.py", line 340, in _request_wrapper
    raise exc
  File "C:\Users\oasis\Aibybit_2\.venv\Lib\site-packages\telegram\request\_baserequest.py", line 330, in _request_wrapper
    code, payload = await self.do_request(
                    ^^^^^^^^^^^^^^^^^^^^^^
  File "C:\Users\oasis\Aibybit_2\.venv\Lib\site-packages\telegram\request\_httpxrequest.py", line 292, in do_request
    raise NetworkError(f"httpx.{err.__class__.__name__}: {err}") from err
telegram.error.NetworkError: httpx.ConnectError: [Errno 11001] getaddrinfo failed
2025-03-04 15:37:22,501 - exchange.bybit_client - ERROR - API 요청 실패: Cannot connect to host api-testnet.bybit.com:443 ssl:True [SSLCertVerificationError: (1, '[SSL: CERTIFICATE_VERIFY_FAILED] certificate verify failed: unable to get local issuer certificate (_ssl.c:1006)')]
2025-03-04 15:37:23,632 - exchange.bybit_client - ERROR - API 요청 실패: Cannot connect to host api-testnet.bybit.com:443 ssl:True [SSLCertVerificationError: (1, '[SSL: CERTIFICATE_VERIFY_FAILED] certificate verify failed: unable to get local issuer certificate (_ssl.c:1006)')]
2025-03-04 15:37:24,759 - exchange.bybit_client - ERROR - API 요청 실패: Cannot connect to host api-testnet.bybit.com:443 ssl:True [SSLCertVerificationError: (1, '[SSL: CERTIFICATE_VERIFY_FAILED] certificate verify failed: unable to get local issuer certificate (_ssl.c:1006)')]
2025-03-04 15:37:26,100 - exchange.bybit_client - ERROR - API 요청 실패: Cannot connect to host api-testnet.bybit.com:443 ssl:True [SSLCertVerificationError: (1, '[SSL: CERTIFICATE_VERIFY_FAILED] certificate verify failed: unable to get local issuer certificate (_ssl.c:1006)')]
2025-03-04 15:37:27,174 - exchange.bybit_client - ERROR - API 요청 실패: Cannot connect to host api-testnet.bybit.com:443 ssl:True [SSLCertVerificationError: (1, '[SSL: CERTIFICATE_VERIFY_FAILED] certificate verify failed: unable to get local issuer certificate (_ssl.c:1006)')]
2025-03-04 15:37:28,298 - exchange.bybit_client - ERROR - API 요청 실패: Cannot connect to host api-testnet.bybit.com:443 ssl:True [SSLCertVerificationError: (1, '[SSL: CERTIFICATE_VERIFY_FAILED] certificate verify failed: unable to get local issuer certificate (_ssl.c:1006)')]
2025-03-04 15:37:29,371 - exchange.bybit_client - ERROR - API 요청 실패: Cannot connect to host api-testnet.bybit.com:443 ssl:True [SSLCertVerificationError: (1, '[SSL: CERTIFICATE_VERIFY_FAILED] certificate verify failed: unable to get local issuer certificate (_ssl.c:1006)')]
2025-03-04 15:37:30,450 - exchange.bybit_client - ERROR - API 요청 실패: Cannot connect to host api-testnet.bybit.com:443 ssl:True [SSLCertVerificationError: (1, '[SSL: CERTIFICATE_VERIFY_FAILED] certificate verify failed: unable to get local issuer certificate (_ssl.c:1006)')]
2025-03-04 15:37:31,538 - exchange.bybit_client - ERROR - API 요청 실패: Cannot connect to host api-testnet.bybit.com:443 ssl:True [SSLCertVerificationError: (1, '[SSL: CERTIFICATE_VERIFY_FAILED] certificate verify failed: unable to get local issuer certificate (_ssl.c:1006)')]
2025-03-04 15:37:32,635 - exchange.bybit_client - ERROR - API 요청 실패: Cannot connect to host api-testnet.bybit.com:443 ssl:True [SSLCertVerificationError: (1, '[SSL: CERTIFICATE_VERIFY_FAILED] certificate verify failed: unable to get local issuer certificate (_ssl.c:1006)')]
2025-03-04 15:37:33,746 - exchange.bybit_client - ERROR - API 요청 실패: Cannot connect to host api-testnet.bybit.com:443 ssl:True [SSLCertVerificationError: (1, '[SSL: CERTIFICATE_VERIFY_FAILED] certificate verify failed: unable to get local issuer certificate (_ssl.c:1006)')]
2025-03-04 15:37:34,835 - exchange.bybit_client - ERROR - API 요청 실패: Cannot connect to host api-testnet.bybit.com:443 ssl:True [SSLCertVerificationError: (1, '[SSL: CERTIFICATE_VERIFY_FAILED] certificate verify failed: unable to get local issuer certificate (_ssl.c:1006)')]
2025-03-04 15:37:35,965 - exchange.bybit_client - ERROR - API 요청 실패: Cannot connect to host api-testnet.bybit.com:443 ssl:True [SSLCertVerificationError: (1, '[SSL: CERTIFICATE_VERIFY_FAILED] certificate verify failed: unable to get local issuer certificate (_ssl.c:1006)')]
2025-03-04 15:49:16,604 - main - ERROR - 실행 중 에러 발생: 'dict' object has no attribute 'verify'
2025-03-04 15:49:16,614 - main - ERROR - Traceback (most recent call last):
  File "C:\Users\oasis\Aibybit_2\src\main.py", line 60, in main
    bybit_client = BybitClient(config=bybit_config)
                   ^^^^^^^^^^^^^^^^^^^^^^^^^^^^^^^^
  File "C:\Users\oasis\Aibybit_2\src\exchange\bybit_client.py", line 52, in __init__
    self.exchange.session.verify = certifi.where()
    ^^^^^^^^^^^^^^^^^^^^^^^^^^^^
AttributeError: 'dict' object has no attribute 'verify'

