2025-02-24 12:59:29,404 - services.market_data_service - ERROR - 마켓 데이터 로드 실패: bybit {"retCode":33004,"retMsg":"Your api key has expired.","result":{},"retExtInfo":{},"time":1740369570270}
2025-02-24 12:59:29,420 - main - ERROR - 실행 중 에러 발생: bybit {"retCode":33004,"retMsg":"Your api key has expired.","result":{},"retExtInfo":{},"time":1740369570270}
2025-02-24 12:59:29,465 - main - ERROR - Traceback (most recent call last):
  File "C:\Users\oasis\Aibybit_2\src\main.py", line 76, in main
    await market_data_service.initialize()
  File "C:\Users\oasis\Aibybit_2\src\services\market_data_service.py", line 57, in initialize
    await self.bybit_client.exchange.load_markets()
  File "C:\Users\oasis\Aibybit_2\.venv\Lib\site-packages\ccxt\async_support\base\exchange.py", line 254, in load_markets
    raise e
  File "C:\Users\oasis\Aibybit_2\.venv\Lib\site-packages\ccxt\async_support\base\exchange.py", line 250, in load_markets
    result = await self.markets_loading
             ^^^^^^^^^^^^^^^^^^^^^^^^^^
  File "C:\Users\oasis\Aibybit_2\.venv\Lib\site-packages\ccxt\async_support\base\exchange.py", line 239, in load_markets_helper
    currencies = await self.fetch_currencies()
                 ^^^^^^^^^^^^^^^^^^^^^^^^^^^^^
  File "C:\Users\oasis\Aibybit_2\.venv\Lib\site-packages\ccxt\async_support\bybit.py", line 1486, in fetch_currencies
    response = await self.privateGetV5AssetCoinQueryInfo(params)
               ^^^^^^^^^^^^^^^^^^^^^^^^^^^^^^^^^^^^^^^^^^^^^^^^^
  File "C:\Users\oasis\Aibybit_2\.venv\Lib\site-packages\ccxt\async_support\base\exchange.py", line 1889, in request
    return await self.fetch2(path, api, method, params, headers, body, config)
           ^^^^^^^^^^^^^^^^^^^^^^^^^^^^^^^^^^^^^^^^^^^^^^^^^^^^^^^^^^^^^^^^^^^
  File "C:\Users\oasis\Aibybit_2\.venv\Lib\site-packages\ccxt\async_support\base\exchange.py", line 1886, in fetch2
    return await self.fetch(request['url'], request['method'], request['headers'], request['body'])
           ^^^^^^^^^^^^^^^^^^^^^^^^^^^^^^^^^^^^^^^^^^^^^^^^^^^^^^^^^^^^^^^^^^^^^^^^^^^^^^^^^^^^^^^^
  File "C:\Users\oasis\Aibybit_2\.venv\Lib\site-packages\ccxt\async_support\base\exchange.py", line 221, in fetch
    self.handle_errors(http_status_code, http_status_text, url, method, headers, http_response, json_response, request_headers, request_body)
  File "C:\Users\oasis\Aibybit_2\.venv\Lib\site-packages\ccxt\async_support\bybit.py", line 7046, in handle_errors
    self.throw_exactly_matched_exception(self.exceptions['exact'], errorCode, feedback)
  File "C:\Users\oasis\Aibybit_2\.venv\Lib\site-packages\ccxt\async_support\base\exchange.py", line 2252, in throw_exactly_matched_exception
    raise exact[string](message)
ccxt.base.errors.AuthenticationError: bybit {"retCode":33004,"retMsg":"Your api key has expired.","result":{},"retExtInfo":{},"time":1740369570270}

2025-02-24 13:04:04,350 - services.market_data_service - ERROR - 마켓 데이터 로드 실패: bybit {"retCode":33004,"retMsg":"Your api key has expired.","result":{},"retExtInfo":{},"time":1740369845210}
2025-02-24 13:04:04,350 - main - ERROR - 실행 중 에러 발생: bybit {"retCode":33004,"retMsg":"Your api key has expired.","result":{},"retExtInfo":{},"time":1740369845210}
2025-02-24 13:04:04,389 - main - ERROR - Traceback (most recent call last):
  File "C:\Users\oasis\Aibybit_2\src\main.py", line 76, in main
    await market_data_service.initialize()
  File "C:\Users\oasis\Aibybit_2\src\services\market_data_service.py", line 57, in initialize
    await self.bybit_client.exchange.load_markets()
  File "C:\Users\oasis\Aibybit_2\.venv\Lib\site-packages\ccxt\async_support\base\exchange.py", line 254, in load_markets
    raise e
  File "C:\Users\oasis\Aibybit_2\.venv\Lib\site-packages\ccxt\async_support\base\exchange.py", line 250, in load_markets
    result = await self.markets_loading
             ^^^^^^^^^^^^^^^^^^^^^^^^^^
  File "C:\Users\oasis\Aibybit_2\.venv\Lib\site-packages\ccxt\async_support\base\exchange.py", line 239, in load_markets_helper
    currencies = await self.fetch_currencies()
                 ^^^^^^^^^^^^^^^^^^^^^^^^^^^^^
  File "C:\Users\oasis\Aibybit_2\.venv\Lib\site-packages\ccxt\async_support\bybit.py", line 1486, in fetch_currencies
    response = await self.privateGetV5AssetCoinQueryInfo(params)
               ^^^^^^^^^^^^^^^^^^^^^^^^^^^^^^^^^^^^^^^^^^^^^^^^^
  File "C:\Users\oasis\Aibybit_2\.venv\Lib\site-packages\ccxt\async_support\base\exchange.py", line 1889, in request
    return await self.fetch2(path, api, method, params, headers, body, config)
           ^^^^^^^^^^^^^^^^^^^^^^^^^^^^^^^^^^^^^^^^^^^^^^^^^^^^^^^^^^^^^^^^^^^
  File "C:\Users\oasis\Aibybit_2\.venv\Lib\site-packages\ccxt\async_support\base\exchange.py", line 1886, in fetch2
    return await self.fetch(request['url'], request['method'], request['headers'], request['body'])
           ^^^^^^^^^^^^^^^^^^^^^^^^^^^^^^^^^^^^^^^^^^^^^^^^^^^^^^^^^^^^^^^^^^^^^^^^^^^^^^^^^^^^^^^^
  File "C:\Users\oasis\Aibybit_2\.venv\Lib\site-packages\ccxt\async_support\base\exchange.py", line 221, in fetch
    self.handle_errors(http_status_code, http_status_text, url, method, headers, http_response, json_response, request_headers, request_body)
  File "C:\Users\oasis\Aibybit_2\.venv\Lib\site-packages\ccxt\async_support\bybit.py", line 7046, in handle_errors
    self.throw_exactly_matched_exception(self.exceptions['exact'], errorCode, feedback)
  File "C:\Users\oasis\Aibybit_2\.venv\Lib\site-packages\ccxt\async_support\base\exchange.py", line 2252, in throw_exactly_matched_exception
    raise exact[string](message)
ccxt.base.errors.AuthenticationError: bybit {"retCode":33004,"retMsg":"Your api key has expired.","result":{},"retExtInfo":{},"time":1740369845210}

2025-02-24 14:00:17,577 - main - ERROR - 실행 중 에러 발생: TradeHistoryService.__init__() takes 2 positional arguments but 3 were given
2025-02-24 14:00:17,580 - main - ERROR - Traceback (most recent call last):
  File "C:\Users\oasis\Aibybit_2\src\main.py", line 82, in main
    telegram_bot = TelegramBot(
                   ^^^^^^^^^^^^
  File "C:\Users\oasis\Aibybit_2\src\telegram_bot\bot.py", line 77, in __init__
    self.trade_history_service = TradeHistoryService(self.trade_store, bybit_client)
                                 ^^^^^^^^^^^^^^^^^^^^^^^^^^^^^^^^^^^^^^^^^^^^^^^^^^^
TypeError: TradeHistoryService.__init__() takes 2 positional arguments but 3 were given

2025-02-24 14:35:26,151 - position_service - ERROR - 포지션 조회 중 오류: 'BybitClient' object has no attribute 'get_positions'
2025-02-24 14:58:18,043 - main - ERROR - 실행 중 에러 발생: AutoAnalyzer.__init__() got an unexpected keyword argument 'bot'
2025-02-24 14:58:18,045 - main - ERROR - Traceback (most recent call last):
  File "C:\Users\oasis\Aibybit_2\src\main.py", line 82, in main
    telegram_bot = TelegramBot(
                   ^^^^^^^^^^^^
  File "C:\Users\oasis\Aibybit_2\src\telegram_bot\bot.py", line 109, in __init__
    self.auto_analyzer = AutoAnalyzer(
                         ^^^^^^^^^^^^^
TypeError: AutoAnalyzer.__init__() got an unexpected keyword argument 'bot'

2025-02-24 15:00:10,782 - main - ERROR - 실행 중 에러 발생: TradingHandler.__init__() missing 1 required positional argument: 'trade_history_service'
2025-02-24 15:00:10,783 - main - ERROR - Traceback (most recent call last):
  File "C:\Users\oasis\Aibybit_2\src\main.py", line 82, in main
    telegram_bot = TelegramBot(
                   ^^^^^^^^^^^^
  File "C:\Users\oasis\Aibybit_2\src\telegram_bot\bot.py", line 123, in __init__
    self.trading_handler = TradingHandler(
                           ^^^^^^^^^^^^^^^
TypeError: TradingHandler.__init__() missing 1 required positional argument: 'trade_history_service'

2025-02-24 15:15:25,138 - services.trade_history_service - ERROR - 포지션 정보 초기화 실패: TradeHistoryService.fetch_and_update_positions() got an unexpected keyword argument 'start_timestamp'
2025-02-24 15:15:25,140 - services.trade_history_service - ERROR - Traceback (most recent call last):
  File "C:\Users\oasis\Aibybit_2\src\services\trade_history_service.py", line 41, in initialize
    await self.fetch_and_update_positions(
          ^^^^^^^^^^^^^^^^^^^^^^^^^^^^^^^^
TypeError: TradeHistoryService.fetch_and_update_positions() got an unexpected keyword argument 'start_timestamp'

2025-02-24 15:29:31,333 - telegram.ext.Updater - ERROR - Error while getting Updates: Conflict: terminated by other getUpdates request; make sure that only one bot instance is running
2025-02-24 15:29:31,450 - telegram.ext.Updater - ERROR - Exception happened while polling for updates.
Traceback (most recent call last):
  File "C:\Users\oasis\Aibybit_2\.venv\Lib\site-packages\telegram\ext\_updater.py", line 688, in _network_loop_retry
    if not await action_cb():
           ^^^^^^^^^^^^^^^^^
  File "C:\Users\oasis\Aibybit_2\.venv\Lib\site-packages\telegram\ext\_updater.py", line 384, in polling_action_cb
    raise exc
  File "C:\Users\oasis\Aibybit_2\.venv\Lib\site-packages\telegram\ext\_updater.py", line 373, in polling_action_cb
    updates = await self.bot.get_updates(
              ^^^^^^^^^^^^^^^^^^^^^^^^^^^
  File "C:\Users\oasis\Aibybit_2\.venv\Lib\site-packages\telegram\ext\_extbot.py", line 558, in get_updates
    updates = await super().get_updates(
              ^^^^^^^^^^^^^^^^^^^^^^^^^^
  File "C:\Users\oasis\Aibybit_2\.venv\Lib\site-packages\telegram\_bot.py", line 525, in decorator
    result = await func(self, *args, **kwargs)  # skipcq: PYL-E1102
             ^^^^^^^^^^^^^^^^^^^^^^^^^^^^^^^^^
  File "C:\Users\oasis\Aibybit_2\.venv\Lib\site-packages\telegram\_bot.py", line 3584, in get_updates
    await self._post(
  File "C:\Users\oasis\Aibybit_2\.venv\Lib\site-packages\telegram\_bot.py", line 613, in _post
    return await self._do_post(
           ^^^^^^^^^^^^^^^^^^^^
  File "C:\Users\oasis\Aibybit_2\.venv\Lib\site-packages\telegram\ext\_extbot.py", line 340, in _do_post
    return await super()._do_post(
           ^^^^^^^^^^^^^^^^^^^^^^^
  File "C:\Users\oasis\Aibybit_2\.venv\Lib\site-packages\telegram\_bot.py", line 641, in _do_post
    return await request.post(
           ^^^^^^^^^^^^^^^^^^^
  File "C:\Users\oasis\Aibybit_2\.venv\Lib\site-packages\telegram\request\_baserequest.py", line 200, in post
    result = await self._request_wrapper(
             ^^^^^^^^^^^^^^^^^^^^^^^^^^^^
  File "C:\Users\oasis\Aibybit_2\.venv\Lib\site-packages\telegram\request\_baserequest.py", line 381, in _request_wrapper
    raise Conflict(message)
telegram.error.Conflict: Conflict: terminated by other getUpdates request; make sure that only one bot instance is running
2025-02-24 15:29:37,535 - telegram.ext.Updater - ERROR - Error while getting Updates: Conflict: terminated by other getUpdates request; make sure that only one bot instance is running
2025-02-24 15:29:37,539 - telegram.ext.Updater - ERROR - Exception happened while polling for updates.
Traceback (most recent call last):
  File "C:\Users\oasis\Aibybit_2\.venv\Lib\site-packages\telegram\ext\_updater.py", line 688, in _network_loop_retry
    if not await action_cb():
           ^^^^^^^^^^^^^^^^^
  File "C:\Users\oasis\Aibybit_2\.venv\Lib\site-packages\telegram\ext\_updater.py", line 384, in polling_action_cb
    raise exc
  File "C:\Users\oasis\Aibybit_2\.venv\Lib\site-packages\telegram\ext\_updater.py", line 373, in polling_action_cb
    updates = await self.bot.get_updates(
              ^^^^^^^^^^^^^^^^^^^^^^^^^^^
  File "C:\Users\oasis\Aibybit_2\.venv\Lib\site-packages\telegram\ext\_extbot.py", line 558, in get_updates
    updates = await super().get_updates(
              ^^^^^^^^^^^^^^^^^^^^^^^^^^
  File "C:\Users\oasis\Aibybit_2\.venv\Lib\site-packages\telegram\_bot.py", line 525, in decorator
    result = await func(self, *args, **kwargs)  # skipcq: PYL-E1102
             ^^^^^^^^^^^^^^^^^^^^^^^^^^^^^^^^^
  File "C:\Users\oasis\Aibybit_2\.venv\Lib\site-packages\telegram\_bot.py", line 3584, in get_updates
    await self._post(
  File "C:\Users\oasis\Aibybit_2\.venv\Lib\site-packages\telegram\_bot.py", line 613, in _post
    return await self._do_post(
           ^^^^^^^^^^^^^^^^^^^^
  File "C:\Users\oasis\Aibybit_2\.venv\Lib\site-packages\telegram\ext\_extbot.py", line 340, in _do_post
    return await super()._do_post(
           ^^^^^^^^^^^^^^^^^^^^^^^
  File "C:\Users\oasis\Aibybit_2\.venv\Lib\site-packages\telegram\_bot.py", line 641, in _do_post
    return await request.post(
           ^^^^^^^^^^^^^^^^^^^
  File "C:\Users\oasis\Aibybit_2\.venv\Lib\site-packages\telegram\request\_baserequest.py", line 200, in post
    result = await self._request_wrapper(
             ^^^^^^^^^^^^^^^^^^^^^^^^^^^^
  File "C:\Users\oasis\Aibybit_2\.venv\Lib\site-packages\telegram\request\_baserequest.py", line 381, in _request_wrapper
    raise Conflict(message)
telegram.error.Conflict: Conflict: terminated by other getUpdates request; make sure that only one bot instance is running
2025-02-24 15:29:44,825 - telegram.ext.Updater - ERROR - Error while getting Updates: Conflict: terminated by other getUpdates request; make sure that only one bot instance is running
2025-02-24 15:29:44,827 - telegram.ext.Updater - ERROR - Exception happened while polling for updates.
Traceback (most recent call last):
  File "C:\Users\oasis\Aibybit_2\.venv\Lib\site-packages\telegram\ext\_updater.py", line 688, in _network_loop_retry
    if not await action_cb():
           ^^^^^^^^^^^^^^^^^
  File "C:\Users\oasis\Aibybit_2\.venv\Lib\site-packages\telegram\ext\_updater.py", line 384, in polling_action_cb
    raise exc
  File "C:\Users\oasis\Aibybit_2\.venv\Lib\site-packages\telegram\ext\_updater.py", line 373, in polling_action_cb
    updates = await self.bot.get_updates(
              ^^^^^^^^^^^^^^^^^^^^^^^^^^^
  File "C:\Users\oasis\Aibybit_2\.venv\Lib\site-packages\telegram\ext\_extbot.py", line 558, in get_updates
    updates = await super().get_updates(
              ^^^^^^^^^^^^^^^^^^^^^^^^^^
  File "C:\Users\oasis\Aibybit_2\.venv\Lib\site-packages\telegram\_bot.py", line 525, in decorator
    result = await func(self, *args, **kwargs)  # skipcq: PYL-E1102
             ^^^^^^^^^^^^^^^^^^^^^^^^^^^^^^^^^
  File "C:\Users\oasis\Aibybit_2\.venv\Lib\site-packages\telegram\_bot.py", line 3584, in get_updates
    await self._post(
  File "C:\Users\oasis\Aibybit_2\.venv\Lib\site-packages\telegram\_bot.py", line 613, in _post
    return await self._do_post(
           ^^^^^^^^^^^^^^^^^^^^
  File "C:\Users\oasis\Aibybit_2\.venv\Lib\site-packages\telegram\ext\_extbot.py", line 340, in _do_post
    return await super()._do_post(
           ^^^^^^^^^^^^^^^^^^^^^^^
  File "C:\Users\oasis\Aibybit_2\.venv\Lib\site-packages\telegram\_bot.py", line 641, in _do_post
    return await request.post(
           ^^^^^^^^^^^^^^^^^^^
  File "C:\Users\oasis\Aibybit_2\.venv\Lib\site-packages\telegram\request\_baserequest.py", line 200, in post
    result = await self._request_wrapper(
             ^^^^^^^^^^^^^^^^^^^^^^^^^^^^
  File "C:\Users\oasis\Aibybit_2\.venv\Lib\site-packages\telegram\request\_baserequest.py", line 381, in _request_wrapper
    raise Conflict(message)
telegram.error.Conflict: Conflict: terminated by other getUpdates request; make sure that only one bot instance is running
2025-02-24 15:29:50,981 - telegram.ext.Updater - ERROR - Error while getting Updates: Conflict: terminated by other getUpdates request; make sure that only one bot instance is running
2025-02-24 15:29:50,982 - telegram.ext.Updater - ERROR - Exception happened while polling for updates.
Traceback (most recent call last):
  File "C:\Users\oasis\Aibybit_2\.venv\Lib\site-packages\telegram\ext\_updater.py", line 688, in _network_loop_retry
    if not await action_cb():
           ^^^^^^^^^^^^^^^^^
  File "C:\Users\oasis\Aibybit_2\.venv\Lib\site-packages\telegram\ext\_updater.py", line 384, in polling_action_cb
    raise exc
  File "C:\Users\oasis\Aibybit_2\.venv\Lib\site-packages\telegram\ext\_updater.py", line 373, in polling_action_cb
    updates = await self.bot.get_updates(
              ^^^^^^^^^^^^^^^^^^^^^^^^^^^
  File "C:\Users\oasis\Aibybit_2\.venv\Lib\site-packages\telegram\ext\_extbot.py", line 558, in get_updates
    updates = await super().get_updates(
              ^^^^^^^^^^^^^^^^^^^^^^^^^^
  File "C:\Users\oasis\Aibybit_2\.venv\Lib\site-packages\telegram\_bot.py", line 525, in decorator
    result = await func(self, *args, **kwargs)  # skipcq: PYL-E1102
             ^^^^^^^^^^^^^^^^^^^^^^^^^^^^^^^^^
  File "C:\Users\oasis\Aibybit_2\.venv\Lib\site-packages\telegram\_bot.py", line 3584, in get_updates
    await self._post(
  File "C:\Users\oasis\Aibybit_2\.venv\Lib\site-packages\telegram\_bot.py", line 613, in _post
    return await self._do_post(
           ^^^^^^^^^^^^^^^^^^^^
  File "C:\Users\oasis\Aibybit_2\.venv\Lib\site-packages\telegram\ext\_extbot.py", line 340, in _do_post
    return await super()._do_post(
           ^^^^^^^^^^^^^^^^^^^^^^^
  File "C:\Users\oasis\Aibybit_2\.venv\Lib\site-packages\telegram\_bot.py", line 641, in _do_post
    return await request.post(
           ^^^^^^^^^^^^^^^^^^^
  File "C:\Users\oasis\Aibybit_2\.venv\Lib\site-packages\telegram\request\_baserequest.py", line 200, in post
    result = await self._request_wrapper(
             ^^^^^^^^^^^^^^^^^^^^^^^^^^^^
  File "C:\Users\oasis\Aibybit_2\.venv\Lib\site-packages\telegram\request\_baserequest.py", line 381, in _request_wrapper
    raise Conflict(message)
telegram.error.Conflict: Conflict: terminated by other getUpdates request; make sure that only one bot instance is running
