2025-02-27 15:35:57,946 - exchange.bybit_client - ERROR - API 요청 실패: Cannot connect to host api-testnet.bybit.com:443 ssl:True [SSLCertVerificationError: (1, '[SSL: CERTIFICATE_VERIFY_FAILED] certificate verify failed: unable to get local issuer certificate (_ssl.c:1006)')]
2025-02-27 15:35:57,951 - exchange.bybit_client - ERROR - Traceback (most recent call last):
  File "C:\Users\oasis\Aibybit_2\.venv\Lib\site-packages\aiohttp\connector.py", line 1123, in _wrap_create_connection
    connection = await self._loop.create_connection(
                 ^^^^^^^^^^^^^^^^^^^^^^^^^^^^^^^^^^^
  File "C:\Program Files\Python311\Lib\asyncio\base_events.py", line 1112, in create_connection
    transport, protocol = await self._create_connection_transport(
                          ^^^^^^^^^^^^^^^^^^^^^^^^^^^^^^^^^^^^^^^^
  File "C:\Program Files\Python311\Lib\asyncio\base_events.py", line 1145, in _create_connection_transport
    await waiter
  File "C:\Program Files\Python311\Lib\asyncio\sslproto.py", line 575, in _on_handshake_complete
    raise handshake_exc
  File "C:\Program Files\Python311\Lib\asyncio\sslproto.py", line 557, in _do_handshake
    self._sslobj.do_handshake()
  File "C:\Program Files\Python311\Lib\ssl.py", line 979, in do_handshake
    self._sslobj.do_handshake()
ssl.SSLCertVerificationError: [SSL: CERTIFICATE_VERIFY_FAILED] certificate verify failed: unable to get local issuer certificate (_ssl.c:1006)

The above exception was the direct cause of the following exception:

Traceback (most recent call last):
  File "C:\Users\oasis\Aibybit_2\src\exchange\bybit_client.py", line 108, in _request
    async with session.get(url, params=request_params, headers=headers) as response:
  File "C:\Users\oasis\Aibybit_2\.venv\Lib\site-packages\aiohttp\client.py", line 1425, in __aenter__
    self._resp: _RetType = await self._coro
                           ^^^^^^^^^^^^^^^^
  File "C:\Users\oasis\Aibybit_2\.venv\Lib\site-packages\aiohttp\client.py", line 703, in _request
    conn = await self._connector.connect(
           ^^^^^^^^^^^^^^^^^^^^^^^^^^^^^^
  File "C:\Users\oasis\Aibybit_2\.venv\Lib\site-packages\aiohttp\connector.py", line 548, in connect
    proto = await self._create_connection(req, traces, timeout)
            ^^^^^^^^^^^^^^^^^^^^^^^^^^^^^^^^^^^^^^^^^^^^^^^^^^^
  File "C:\Users\oasis\Aibybit_2\.venv\Lib\site-packages\aiohttp\connector.py", line 1056, in _create_connection
    _, proto = await self._create_direct_connection(req, traces, timeout)
               ^^^^^^^^^^^^^^^^^^^^^^^^^^^^^^^^^^^^^^^^^^^^^^^^^^^^^^^^^^
  File "C:\Users\oasis\Aibybit_2\.venv\Lib\site-packages\aiohttp\connector.py", line 1411, in _create_direct_connection
    raise last_exc
  File "C:\Users\oasis\Aibybit_2\.venv\Lib\site-packages\aiohttp\connector.py", line 1380, in _create_direct_connection
    transp, proto = await self._wrap_create_connection(
                    ^^^^^^^^^^^^^^^^^^^^^^^^^^^^^^^^^^^
  File "C:\Users\oasis\Aibybit_2\.venv\Lib\site-packages\aiohttp\connector.py", line 1129, in _wrap_create_connection
    raise ClientConnectorCertificateError(req.connection_key, exc) from exc
aiohttp.client_exceptions.ClientConnectorCertificateError: Cannot connect to host api-testnet.bybit.com:443 ssl:True [SSLCertVerificationError: (1, '[SSL: CERTIFICATE_VERIFY_FAILED] certificate verify failed: unable to get local issuer certificate (_ssl.c:1006)')]

2025-02-27 15:35:59,049 - exchange.bybit_client - ERROR - API 요청 실패: Cannot connect to host api-testnet.bybit.com:443 ssl:True [SSLCertVerificationError: (1, '[SSL: CERTIFICATE_VERIFY_FAILED] certificate verify failed: unable to get local issuer certificate (_ssl.c:1006)')]
2025-02-27 15:35:59,050 - exchange.bybit_client - ERROR - Traceback (most recent call last):
  File "C:\Users\oasis\Aibybit_2\.venv\Lib\site-packages\aiohttp\connector.py", line 1123, in _wrap_create_connection
    connection = await self._loop.create_connection(
                 ^^^^^^^^^^^^^^^^^^^^^^^^^^^^^^^^^^^
  File "C:\Program Files\Python311\Lib\asyncio\base_events.py", line 1112, in create_connection
    transport, protocol = await self._create_connection_transport(
                          ^^^^^^^^^^^^^^^^^^^^^^^^^^^^^^^^^^^^^^^^
  File "C:\Program Files\Python311\Lib\asyncio\base_events.py", line 1145, in _create_connection_transport
    await waiter
  File "C:\Program Files\Python311\Lib\asyncio\sslproto.py", line 575, in _on_handshake_complete
    raise handshake_exc
  File "C:\Program Files\Python311\Lib\asyncio\sslproto.py", line 557, in _do_handshake
    self._sslobj.do_handshake()
  File "C:\Program Files\Python311\Lib\ssl.py", line 979, in do_handshake
    self._sslobj.do_handshake()
ssl.SSLCertVerificationError: [SSL: CERTIFICATE_VERIFY_FAILED] certificate verify failed: unable to get local issuer certificate (_ssl.c:1006)

The above exception was the direct cause of the following exception:

Traceback (most recent call last):
  File "C:\Users\oasis\Aibybit_2\src\exchange\bybit_client.py", line 108, in _request
    async with session.get(url, params=request_params, headers=headers) as response:
  File "C:\Users\oasis\Aibybit_2\.venv\Lib\site-packages\aiohttp\client.py", line 1425, in __aenter__
    self._resp: _RetType = await self._coro
                           ^^^^^^^^^^^^^^^^
  File "C:\Users\oasis\Aibybit_2\.venv\Lib\site-packages\aiohttp\client.py", line 703, in _request
    conn = await self._connector.connect(
           ^^^^^^^^^^^^^^^^^^^^^^^^^^^^^^
  File "C:\Users\oasis\Aibybit_2\.venv\Lib\site-packages\aiohttp\connector.py", line 548, in connect
    proto = await self._create_connection(req, traces, timeout)
            ^^^^^^^^^^^^^^^^^^^^^^^^^^^^^^^^^^^^^^^^^^^^^^^^^^^
  File "C:\Users\oasis\Aibybit_2\.venv\Lib\site-packages\aiohttp\connector.py", line 1056, in _create_connection
    _, proto = await self._create_direct_connection(req, traces, timeout)
               ^^^^^^^^^^^^^^^^^^^^^^^^^^^^^^^^^^^^^^^^^^^^^^^^^^^^^^^^^^
  File "C:\Users\oasis\Aibybit_2\.venv\Lib\site-packages\aiohttp\connector.py", line 1411, in _create_direct_connection
    raise last_exc
  File "C:\Users\oasis\Aibybit_2\.venv\Lib\site-packages\aiohttp\connector.py", line 1380, in _create_direct_connection
    transp, proto = await self._wrap_create_connection(
                    ^^^^^^^^^^^^^^^^^^^^^^^^^^^^^^^^^^^
  File "C:\Users\oasis\Aibybit_2\.venv\Lib\site-packages\aiohttp\connector.py", line 1129, in _wrap_create_connection
    raise ClientConnectorCertificateError(req.connection_key, exc) from exc
aiohttp.client_exceptions.ClientConnectorCertificateError: Cannot connect to host api-testnet.bybit.com:443 ssl:True [SSLCertVerificationError: (1, '[SSL: CERTIFICATE_VERIFY_FAILED] certificate verify failed: unable to get local issuer certificate (_ssl.c:1006)')]

2025-02-27 15:36:00,179 - exchange.bybit_client - ERROR - API 요청 실패: Cannot connect to host api-testnet.bybit.com:443 ssl:True [SSLCertVerificationError: (1, '[SSL: CERTIFICATE_VERIFY_FAILED] certificate verify failed: unable to get local issuer certificate (_ssl.c:1006)')]
2025-02-27 15:36:00,182 - exchange.bybit_client - ERROR - Traceback (most recent call last):
  File "C:\Users\oasis\Aibybit_2\.venv\Lib\site-packages\aiohttp\connector.py", line 1123, in _wrap_create_connection
    connection = await self._loop.create_connection(
                 ^^^^^^^^^^^^^^^^^^^^^^^^^^^^^^^^^^^
  File "C:\Program Files\Python311\Lib\asyncio\base_events.py", line 1112, in create_connection
    transport, protocol = await self._create_connection_transport(
                          ^^^^^^^^^^^^^^^^^^^^^^^^^^^^^^^^^^^^^^^^
  File "C:\Program Files\Python311\Lib\asyncio\base_events.py", line 1145, in _create_connection_transport
    await waiter
  File "C:\Program Files\Python311\Lib\asyncio\sslproto.py", line 575, in _on_handshake_complete
    raise handshake_exc
  File "C:\Program Files\Python311\Lib\asyncio\sslproto.py", line 557, in _do_handshake
    self._sslobj.do_handshake()
  File "C:\Program Files\Python311\Lib\ssl.py", line 979, in do_handshake
    self._sslobj.do_handshake()
ssl.SSLCertVerificationError: [SSL: CERTIFICATE_VERIFY_FAILED] certificate verify failed: unable to get local issuer certificate (_ssl.c:1006)

The above exception was the direct cause of the following exception:

Traceback (most recent call last):
  File "C:\Users\oasis\Aibybit_2\src\exchange\bybit_client.py", line 108, in _request
    async with session.get(url, params=request_params, headers=headers) as response:
  File "C:\Users\oasis\Aibybit_2\.venv\Lib\site-packages\aiohttp\client.py", line 1425, in __aenter__
    self._resp: _RetType = await self._coro
                           ^^^^^^^^^^^^^^^^
  File "C:\Users\oasis\Aibybit_2\.venv\Lib\site-packages\aiohttp\client.py", line 703, in _request
    conn = await self._connector.connect(
           ^^^^^^^^^^^^^^^^^^^^^^^^^^^^^^
  File "C:\Users\oasis\Aibybit_2\.venv\Lib\site-packages\aiohttp\connector.py", line 548, in connect
    proto = await self._create_connection(req, traces, timeout)
            ^^^^^^^^^^^^^^^^^^^^^^^^^^^^^^^^^^^^^^^^^^^^^^^^^^^
  File "C:\Users\oasis\Aibybit_2\.venv\Lib\site-packages\aiohttp\connector.py", line 1056, in _create_connection
    _, proto = await self._create_direct_connection(req, traces, timeout)
               ^^^^^^^^^^^^^^^^^^^^^^^^^^^^^^^^^^^^^^^^^^^^^^^^^^^^^^^^^^
  File "C:\Users\oasis\Aibybit_2\.venv\Lib\site-packages\aiohttp\connector.py", line 1411, in _create_direct_connection
    raise last_exc
  File "C:\Users\oasis\Aibybit_2\.venv\Lib\site-packages\aiohttp\connector.py", line 1380, in _create_direct_connection
    transp, proto = await self._wrap_create_connection(
                    ^^^^^^^^^^^^^^^^^^^^^^^^^^^^^^^^^^^
  File "C:\Users\oasis\Aibybit_2\.venv\Lib\site-packages\aiohttp\connector.py", line 1129, in _wrap_create_connection
    raise ClientConnectorCertificateError(req.connection_key, exc) from exc
aiohttp.client_exceptions.ClientConnectorCertificateError: Cannot connect to host api-testnet.bybit.com:443 ssl:True [SSLCertVerificationError: (1, '[SSL: CERTIFICATE_VERIFY_FAILED] certificate verify failed: unable to get local issuer certificate (_ssl.c:1006)')]

2025-02-27 15:36:01,333 - exchange.bybit_client - ERROR - API 요청 실패: Cannot connect to host api-testnet.bybit.com:443 ssl:True [SSLCertVerificationError: (1, '[SSL: CERTIFICATE_VERIFY_FAILED] certificate verify failed: unable to get local issuer certificate (_ssl.c:1006)')]
2025-02-27 15:36:01,337 - exchange.bybit_client - ERROR - Traceback (most recent call last):
  File "C:\Users\oasis\Aibybit_2\.venv\Lib\site-packages\aiohttp\connector.py", line 1123, in _wrap_create_connection
    connection = await self._loop.create_connection(
                 ^^^^^^^^^^^^^^^^^^^^^^^^^^^^^^^^^^^
  File "C:\Program Files\Python311\Lib\asyncio\base_events.py", line 1112, in create_connection
    transport, protocol = await self._create_connection_transport(
                          ^^^^^^^^^^^^^^^^^^^^^^^^^^^^^^^^^^^^^^^^
  File "C:\Program Files\Python311\Lib\asyncio\base_events.py", line 1145, in _create_connection_transport
    await waiter
  File "C:\Program Files\Python311\Lib\asyncio\sslproto.py", line 575, in _on_handshake_complete
    raise handshake_exc
  File "C:\Program Files\Python311\Lib\asyncio\sslproto.py", line 557, in _do_handshake
    self._sslobj.do_handshake()
  File "C:\Program Files\Python311\Lib\ssl.py", line 979, in do_handshake
    self._sslobj.do_handshake()
ssl.SSLCertVerificationError: [SSL: CERTIFICATE_VERIFY_FAILED] certificate verify failed: unable to get local issuer certificate (_ssl.c:1006)

The above exception was the direct cause of the following exception:

Traceback (most recent call last):
  File "C:\Users\oasis\Aibybit_2\src\exchange\bybit_client.py", line 108, in _request
    async with session.get(url, params=request_params, headers=headers) as response:
  File "C:\Users\oasis\Aibybit_2\.venv\Lib\site-packages\aiohttp\client.py", line 1425, in __aenter__
    self._resp: _RetType = await self._coro
                           ^^^^^^^^^^^^^^^^
  File "C:\Users\oasis\Aibybit_2\.venv\Lib\site-packages\aiohttp\client.py", line 703, in _request
    conn = await self._connector.connect(
           ^^^^^^^^^^^^^^^^^^^^^^^^^^^^^^
  File "C:\Users\oasis\Aibybit_2\.venv\Lib\site-packages\aiohttp\connector.py", line 548, in connect
    proto = await self._create_connection(req, traces, timeout)
            ^^^^^^^^^^^^^^^^^^^^^^^^^^^^^^^^^^^^^^^^^^^^^^^^^^^
  File "C:\Users\oasis\Aibybit_2\.venv\Lib\site-packages\aiohttp\connector.py", line 1056, in _create_connection
    _, proto = await self._create_direct_connection(req, traces, timeout)
               ^^^^^^^^^^^^^^^^^^^^^^^^^^^^^^^^^^^^^^^^^^^^^^^^^^^^^^^^^^
  File "C:\Users\oasis\Aibybit_2\.venv\Lib\site-packages\aiohttp\connector.py", line 1411, in _create_direct_connection
    raise last_exc
  File "C:\Users\oasis\Aibybit_2\.venv\Lib\site-packages\aiohttp\connector.py", line 1380, in _create_direct_connection
    transp, proto = await self._wrap_create_connection(
                    ^^^^^^^^^^^^^^^^^^^^^^^^^^^^^^^^^^^
  File "C:\Users\oasis\Aibybit_2\.venv\Lib\site-packages\aiohttp\connector.py", line 1129, in _wrap_create_connection
    raise ClientConnectorCertificateError(req.connection_key, exc) from exc
aiohttp.client_exceptions.ClientConnectorCertificateError: Cannot connect to host api-testnet.bybit.com:443 ssl:True [SSLCertVerificationError: (1, '[SSL: CERTIFICATE_VERIFY_FAILED] certificate verify failed: unable to get local issuer certificate (_ssl.c:1006)')]

2025-02-27 15:36:02,445 - exchange.bybit_client - ERROR - API 요청 실패: Cannot connect to host api-testnet.bybit.com:443 ssl:True [SSLCertVerificationError: (1, '[SSL: CERTIFICATE_VERIFY_FAILED] certificate verify failed: unable to get local issuer certificate (_ssl.c:1006)')]
2025-02-27 15:36:02,448 - exchange.bybit_client - ERROR - Traceback (most recent call last):
  File "C:\Users\oasis\Aibybit_2\.venv\Lib\site-packages\aiohttp\connector.py", line 1123, in _wrap_create_connection
    connection = await self._loop.create_connection(
                 ^^^^^^^^^^^^^^^^^^^^^^^^^^^^^^^^^^^
  File "C:\Program Files\Python311\Lib\asyncio\base_events.py", line 1112, in create_connection
    transport, protocol = await self._create_connection_transport(
                          ^^^^^^^^^^^^^^^^^^^^^^^^^^^^^^^^^^^^^^^^
  File "C:\Program Files\Python311\Lib\asyncio\base_events.py", line 1145, in _create_connection_transport
    await waiter
  File "C:\Program Files\Python311\Lib\asyncio\sslproto.py", line 575, in _on_handshake_complete
    raise handshake_exc
  File "C:\Program Files\Python311\Lib\asyncio\sslproto.py", line 557, in _do_handshake
    self._sslobj.do_handshake()
  File "C:\Program Files\Python311\Lib\ssl.py", line 979, in do_handshake
    self._sslobj.do_handshake()
ssl.SSLCertVerificationError: [SSL: CERTIFICATE_VERIFY_FAILED] certificate verify failed: unable to get local issuer certificate (_ssl.c:1006)

The above exception was the direct cause of the following exception:

Traceback (most recent call last):
  File "C:\Users\oasis\Aibybit_2\src\exchange\bybit_client.py", line 108, in _request
    async with session.get(url, params=request_params, headers=headers) as response:
  File "C:\Users\oasis\Aibybit_2\.venv\Lib\site-packages\aiohttp\client.py", line 1425, in __aenter__
    self._resp: _RetType = await self._coro
                           ^^^^^^^^^^^^^^^^
  File "C:\Users\oasis\Aibybit_2\.venv\Lib\site-packages\aiohttp\client.py", line 703, in _request
    conn = await self._connector.connect(
           ^^^^^^^^^^^^^^^^^^^^^^^^^^^^^^
  File "C:\Users\oasis\Aibybit_2\.venv\Lib\site-packages\aiohttp\connector.py", line 548, in connect
    proto = await self._create_connection(req, traces, timeout)
            ^^^^^^^^^^^^^^^^^^^^^^^^^^^^^^^^^^^^^^^^^^^^^^^^^^^
  File "C:\Users\oasis\Aibybit_2\.venv\Lib\site-packages\aiohttp\connector.py", line 1056, in _create_connection
    _, proto = await self._create_direct_connection(req, traces, timeout)
               ^^^^^^^^^^^^^^^^^^^^^^^^^^^^^^^^^^^^^^^^^^^^^^^^^^^^^^^^^^
  File "C:\Users\oasis\Aibybit_2\.venv\Lib\site-packages\aiohttp\connector.py", line 1411, in _create_direct_connection
    raise last_exc
  File "C:\Users\oasis\Aibybit_2\.venv\Lib\site-packages\aiohttp\connector.py", line 1380, in _create_direct_connection
    transp, proto = await self._wrap_create_connection(
                    ^^^^^^^^^^^^^^^^^^^^^^^^^^^^^^^^^^^
  File "C:\Users\oasis\Aibybit_2\.venv\Lib\site-packages\aiohttp\connector.py", line 1129, in _wrap_create_connection
    raise ClientConnectorCertificateError(req.connection_key, exc) from exc
aiohttp.client_exceptions.ClientConnectorCertificateError: Cannot connect to host api-testnet.bybit.com:443 ssl:True [SSLCertVerificationError: (1, '[SSL: CERTIFICATE_VERIFY_FAILED] certificate verify failed: unable to get local issuer certificate (_ssl.c:1006)')]

2025-02-27 15:36:03,545 - exchange.bybit_client - ERROR - API 요청 실패: Cannot connect to host api-testnet.bybit.com:443 ssl:True [SSLCertVerificationError: (1, '[SSL: CERTIFICATE_VERIFY_FAILED] certificate verify failed: unable to get local issuer certificate (_ssl.c:1006)')]
2025-02-27 15:36:03,546 - exchange.bybit_client - ERROR - Traceback (most recent call last):
  File "C:\Users\oasis\Aibybit_2\.venv\Lib\site-packages\aiohttp\connector.py", line 1123, in _wrap_create_connection
    connection = await self._loop.create_connection(
                 ^^^^^^^^^^^^^^^^^^^^^^^^^^^^^^^^^^^
  File "C:\Program Files\Python311\Lib\asyncio\base_events.py", line 1112, in create_connection
    transport, protocol = await self._create_connection_transport(
                          ^^^^^^^^^^^^^^^^^^^^^^^^^^^^^^^^^^^^^^^^
  File "C:\Program Files\Python311\Lib\asyncio\base_events.py", line 1145, in _create_connection_transport
    await waiter
  File "C:\Program Files\Python311\Lib\asyncio\sslproto.py", line 575, in _on_handshake_complete
    raise handshake_exc
  File "C:\Program Files\Python311\Lib\asyncio\sslproto.py", line 557, in _do_handshake
    self._sslobj.do_handshake()
  File "C:\Program Files\Python311\Lib\ssl.py", line 979, in do_handshake
    self._sslobj.do_handshake()
ssl.SSLCertVerificationError: [SSL: CERTIFICATE_VERIFY_FAILED] certificate verify failed: unable to get local issuer certificate (_ssl.c:1006)

The above exception was the direct cause of the following exception:

Traceback (most recent call last):
  File "C:\Users\oasis\Aibybit_2\src\exchange\bybit_client.py", line 108, in _request
    async with session.get(url, params=request_params, headers=headers) as response:
  File "C:\Users\oasis\Aibybit_2\.venv\Lib\site-packages\aiohttp\client.py", line 1425, in __aenter__
    self._resp: _RetType = await self._coro
                           ^^^^^^^^^^^^^^^^
  File "C:\Users\oasis\Aibybit_2\.venv\Lib\site-packages\aiohttp\client.py", line 703, in _request
    conn = await self._connector.connect(
           ^^^^^^^^^^^^^^^^^^^^^^^^^^^^^^
  File "C:\Users\oasis\Aibybit_2\.venv\Lib\site-packages\aiohttp\connector.py", line 548, in connect
    proto = await self._create_connection(req, traces, timeout)
            ^^^^^^^^^^^^^^^^^^^^^^^^^^^^^^^^^^^^^^^^^^^^^^^^^^^
  File "C:\Users\oasis\Aibybit_2\.venv\Lib\site-packages\aiohttp\connector.py", line 1056, in _create_connection
    _, proto = await self._create_direct_connection(req, traces, timeout)
               ^^^^^^^^^^^^^^^^^^^^^^^^^^^^^^^^^^^^^^^^^^^^^^^^^^^^^^^^^^
  File "C:\Users\oasis\Aibybit_2\.venv\Lib\site-packages\aiohttp\connector.py", line 1411, in _create_direct_connection
    raise last_exc
  File "C:\Users\oasis\Aibybit_2\.venv\Lib\site-packages\aiohttp\connector.py", line 1380, in _create_direct_connection
    transp, proto = await self._wrap_create_connection(
                    ^^^^^^^^^^^^^^^^^^^^^^^^^^^^^^^^^^^
  File "C:\Users\oasis\Aibybit_2\.venv\Lib\site-packages\aiohttp\connector.py", line 1129, in _wrap_create_connection
    raise ClientConnectorCertificateError(req.connection_key, exc) from exc
aiohttp.client_exceptions.ClientConnectorCertificateError: Cannot connect to host api-testnet.bybit.com:443 ssl:True [SSLCertVerificationError: (1, '[SSL: CERTIFICATE_VERIFY_FAILED] certificate verify failed: unable to get local issuer certificate (_ssl.c:1006)')]

2025-02-27 15:36:04,649 - exchange.bybit_client - ERROR - API 요청 실패: Cannot connect to host api-testnet.bybit.com:443 ssl:True [SSLCertVerificationError: (1, '[SSL: CERTIFICATE_VERIFY_FAILED] certificate verify failed: unable to get local issuer certificate (_ssl.c:1006)')]
2025-02-27 15:36:04,653 - exchange.bybit_client - ERROR - Traceback (most recent call last):
  File "C:\Users\oasis\Aibybit_2\.venv\Lib\site-packages\aiohttp\connector.py", line 1123, in _wrap_create_connection
    connection = await self._loop.create_connection(
                 ^^^^^^^^^^^^^^^^^^^^^^^^^^^^^^^^^^^
  File "C:\Program Files\Python311\Lib\asyncio\base_events.py", line 1112, in create_connection
    transport, protocol = await self._create_connection_transport(
                          ^^^^^^^^^^^^^^^^^^^^^^^^^^^^^^^^^^^^^^^^
  File "C:\Program Files\Python311\Lib\asyncio\base_events.py", line 1145, in _create_connection_transport
    await waiter
  File "C:\Program Files\Python311\Lib\asyncio\sslproto.py", line 575, in _on_handshake_complete
    raise handshake_exc
  File "C:\Program Files\Python311\Lib\asyncio\sslproto.py", line 557, in _do_handshake
    self._sslobj.do_handshake()
  File "C:\Program Files\Python311\Lib\ssl.py", line 979, in do_handshake
    self._sslobj.do_handshake()
ssl.SSLCertVerificationError: [SSL: CERTIFICATE_VERIFY_FAILED] certificate verify failed: unable to get local issuer certificate (_ssl.c:1006)

The above exception was the direct cause of the following exception:

Traceback (most recent call last):
  File "C:\Users\oasis\Aibybit_2\src\exchange\bybit_client.py", line 108, in _request
    async with session.get(url, params=request_params, headers=headers) as response:
  File "C:\Users\oasis\Aibybit_2\.venv\Lib\site-packages\aiohttp\client.py", line 1425, in __aenter__
    self._resp: _RetType = await self._coro
                           ^^^^^^^^^^^^^^^^
  File "C:\Users\oasis\Aibybit_2\.venv\Lib\site-packages\aiohttp\client.py", line 703, in _request
    conn = await self._connector.connect(
           ^^^^^^^^^^^^^^^^^^^^^^^^^^^^^^
  File "C:\Users\oasis\Aibybit_2\.venv\Lib\site-packages\aiohttp\connector.py", line 548, in connect
    proto = await self._create_connection(req, traces, timeout)
            ^^^^^^^^^^^^^^^^^^^^^^^^^^^^^^^^^^^^^^^^^^^^^^^^^^^
  File "C:\Users\oasis\Aibybit_2\.venv\Lib\site-packages\aiohttp\connector.py", line 1056, in _create_connection
    _, proto = await self._create_direct_connection(req, traces, timeout)
               ^^^^^^^^^^^^^^^^^^^^^^^^^^^^^^^^^^^^^^^^^^^^^^^^^^^^^^^^^^
  File "C:\Users\oasis\Aibybit_2\.venv\Lib\site-packages\aiohttp\connector.py", line 1411, in _create_direct_connection
    raise last_exc
  File "C:\Users\oasis\Aibybit_2\.venv\Lib\site-packages\aiohttp\connector.py", line 1380, in _create_direct_connection
    transp, proto = await self._wrap_create_connection(
                    ^^^^^^^^^^^^^^^^^^^^^^^^^^^^^^^^^^^
  File "C:\Users\oasis\Aibybit_2\.venv\Lib\site-packages\aiohttp\connector.py", line 1129, in _wrap_create_connection
    raise ClientConnectorCertificateError(req.connection_key, exc) from exc
aiohttp.client_exceptions.ClientConnectorCertificateError: Cannot connect to host api-testnet.bybit.com:443 ssl:True [SSLCertVerificationError: (1, '[SSL: CERTIFICATE_VERIFY_FAILED] certificate verify failed: unable to get local issuer certificate (_ssl.c:1006)')]

2025-02-27 15:36:05,774 - exchange.bybit_client - ERROR - API 요청 실패: Cannot connect to host api-testnet.bybit.com:443 ssl:True [SSLCertVerificationError: (1, '[SSL: CERTIFICATE_VERIFY_FAILED] certificate verify failed: unable to get local issuer certificate (_ssl.c:1006)')]
2025-02-27 15:36:05,777 - exchange.bybit_client - ERROR - Traceback (most recent call last):
  File "C:\Users\oasis\Aibybit_2\.venv\Lib\site-packages\aiohttp\connector.py", line 1123, in _wrap_create_connection
    connection = await self._loop.create_connection(
                 ^^^^^^^^^^^^^^^^^^^^^^^^^^^^^^^^^^^
  File "C:\Program Files\Python311\Lib\asyncio\base_events.py", line 1112, in create_connection
    transport, protocol = await self._create_connection_transport(
                          ^^^^^^^^^^^^^^^^^^^^^^^^^^^^^^^^^^^^^^^^
  File "C:\Program Files\Python311\Lib\asyncio\base_events.py", line 1145, in _create_connection_transport
    await waiter
  File "C:\Program Files\Python311\Lib\asyncio\sslproto.py", line 575, in _on_handshake_complete
    raise handshake_exc
  File "C:\Program Files\Python311\Lib\asyncio\sslproto.py", line 557, in _do_handshake
    self._sslobj.do_handshake()
  File "C:\Program Files\Python311\Lib\ssl.py", line 979, in do_handshake
    self._sslobj.do_handshake()
ssl.SSLCertVerificationError: [SSL: CERTIFICATE_VERIFY_FAILED] certificate verify failed: unable to get local issuer certificate (_ssl.c:1006)

The above exception was the direct cause of the following exception:

Traceback (most recent call last):
  File "C:\Users\oasis\Aibybit_2\src\exchange\bybit_client.py", line 108, in _request
    async with session.get(url, params=request_params, headers=headers) as response:
  File "C:\Users\oasis\Aibybit_2\.venv\Lib\site-packages\aiohttp\client.py", line 1425, in __aenter__
    self._resp: _RetType = await self._coro
                           ^^^^^^^^^^^^^^^^
  File "C:\Users\oasis\Aibybit_2\.venv\Lib\site-packages\aiohttp\client.py", line 703, in _request
    conn = await self._connector.connect(
           ^^^^^^^^^^^^^^^^^^^^^^^^^^^^^^
  File "C:\Users\oasis\Aibybit_2\.venv\Lib\site-packages\aiohttp\connector.py", line 548, in connect
    proto = await self._create_connection(req, traces, timeout)
            ^^^^^^^^^^^^^^^^^^^^^^^^^^^^^^^^^^^^^^^^^^^^^^^^^^^
  File "C:\Users\oasis\Aibybit_2\.venv\Lib\site-packages\aiohttp\connector.py", line 1056, in _create_connection
    _, proto = await self._create_direct_connection(req, traces, timeout)
               ^^^^^^^^^^^^^^^^^^^^^^^^^^^^^^^^^^^^^^^^^^^^^^^^^^^^^^^^^^
  File "C:\Users\oasis\Aibybit_2\.venv\Lib\site-packages\aiohttp\connector.py", line 1411, in _create_direct_connection
    raise last_exc
  File "C:\Users\oasis\Aibybit_2\.venv\Lib\site-packages\aiohttp\connector.py", line 1380, in _create_direct_connection
    transp, proto = await self._wrap_create_connection(
                    ^^^^^^^^^^^^^^^^^^^^^^^^^^^^^^^^^^^
  File "C:\Users\oasis\Aibybit_2\.venv\Lib\site-packages\aiohttp\connector.py", line 1129, in _wrap_create_connection
    raise ClientConnectorCertificateError(req.connection_key, exc) from exc
aiohttp.client_exceptions.ClientConnectorCertificateError: Cannot connect to host api-testnet.bybit.com:443 ssl:True [SSLCertVerificationError: (1, '[SSL: CERTIFICATE_VERIFY_FAILED] certificate verify failed: unable to get local issuer certificate (_ssl.c:1006)')]

2025-02-27 15:36:06,896 - exchange.bybit_client - ERROR - API 요청 실패: Cannot connect to host api-testnet.bybit.com:443 ssl:True [SSLCertVerificationError: (1, '[SSL: CERTIFICATE_VERIFY_FAILED] certificate verify failed: unable to get local issuer certificate (_ssl.c:1006)')]
2025-02-27 15:36:06,900 - exchange.bybit_client - ERROR - Traceback (most recent call last):
  File "C:\Users\oasis\Aibybit_2\.venv\Lib\site-packages\aiohttp\connector.py", line 1123, in _wrap_create_connection
    connection = await self._loop.create_connection(
                 ^^^^^^^^^^^^^^^^^^^^^^^^^^^^^^^^^^^
  File "C:\Program Files\Python311\Lib\asyncio\base_events.py", line 1112, in create_connection
    transport, protocol = await self._create_connection_transport(
                          ^^^^^^^^^^^^^^^^^^^^^^^^^^^^^^^^^^^^^^^^
  File "C:\Program Files\Python311\Lib\asyncio\base_events.py", line 1145, in _create_connection_transport
    await waiter
  File "C:\Program Files\Python311\Lib\asyncio\sslproto.py", line 575, in _on_handshake_complete
    raise handshake_exc
  File "C:\Program Files\Python311\Lib\asyncio\sslproto.py", line 557, in _do_handshake
    self._sslobj.do_handshake()
  File "C:\Program Files\Python311\Lib\ssl.py", line 979, in do_handshake
    self._sslobj.do_handshake()
ssl.SSLCertVerificationError: [SSL: CERTIFICATE_VERIFY_FAILED] certificate verify failed: unable to get local issuer certificate (_ssl.c:1006)

The above exception was the direct cause of the following exception:

Traceback (most recent call last):
  File "C:\Users\oasis\Aibybit_2\src\exchange\bybit_client.py", line 108, in _request
    async with session.get(url, params=request_params, headers=headers) as response:
  File "C:\Users\oasis\Aibybit_2\.venv\Lib\site-packages\aiohttp\client.py", line 1425, in __aenter__
    self._resp: _RetType = await self._coro
                           ^^^^^^^^^^^^^^^^
  File "C:\Users\oasis\Aibybit_2\.venv\Lib\site-packages\aiohttp\client.py", line 703, in _request
    conn = await self._connector.connect(
           ^^^^^^^^^^^^^^^^^^^^^^^^^^^^^^
  File "C:\Users\oasis\Aibybit_2\.venv\Lib\site-packages\aiohttp\connector.py", line 548, in connect
    proto = await self._create_connection(req, traces, timeout)
            ^^^^^^^^^^^^^^^^^^^^^^^^^^^^^^^^^^^^^^^^^^^^^^^^^^^
  File "C:\Users\oasis\Aibybit_2\.venv\Lib\site-packages\aiohttp\connector.py", line 1056, in _create_connection
    _, proto = await self._create_direct_connection(req, traces, timeout)
               ^^^^^^^^^^^^^^^^^^^^^^^^^^^^^^^^^^^^^^^^^^^^^^^^^^^^^^^^^^
  File "C:\Users\oasis\Aibybit_2\.venv\Lib\site-packages\aiohttp\connector.py", line 1411, in _create_direct_connection
    raise last_exc
  File "C:\Users\oasis\Aibybit_2\.venv\Lib\site-packages\aiohttp\connector.py", line 1380, in _create_direct_connection
    transp, proto = await self._wrap_create_connection(
                    ^^^^^^^^^^^^^^^^^^^^^^^^^^^^^^^^^^^
  File "C:\Users\oasis\Aibybit_2\.venv\Lib\site-packages\aiohttp\connector.py", line 1129, in _wrap_create_connection
    raise ClientConnectorCertificateError(req.connection_key, exc) from exc
aiohttp.client_exceptions.ClientConnectorCertificateError: Cannot connect to host api-testnet.bybit.com:443 ssl:True [SSLCertVerificationError: (1, '[SSL: CERTIFICATE_VERIFY_FAILED] certificate verify failed: unable to get local issuer certificate (_ssl.c:1006)')]

2025-02-27 15:36:08,033 - exchange.bybit_client - ERROR - API 요청 실패: Cannot connect to host api-testnet.bybit.com:443 ssl:True [SSLCertVerificationError: (1, '[SSL: CERTIFICATE_VERIFY_FAILED] certificate verify failed: unable to get local issuer certificate (_ssl.c:1006)')]
2025-02-27 15:36:08,038 - exchange.bybit_client - ERROR - Traceback (most recent call last):
  File "C:\Users\oasis\Aibybit_2\.venv\Lib\site-packages\aiohttp\connector.py", line 1123, in _wrap_create_connection
    connection = await self._loop.create_connection(
                 ^^^^^^^^^^^^^^^^^^^^^^^^^^^^^^^^^^^
  File "C:\Program Files\Python311\Lib\asyncio\base_events.py", line 1112, in create_connection
    transport, protocol = await self._create_connection_transport(
                          ^^^^^^^^^^^^^^^^^^^^^^^^^^^^^^^^^^^^^^^^
  File "C:\Program Files\Python311\Lib\asyncio\base_events.py", line 1145, in _create_connection_transport
    await waiter
  File "C:\Program Files\Python311\Lib\asyncio\sslproto.py", line 575, in _on_handshake_complete
    raise handshake_exc
  File "C:\Program Files\Python311\Lib\asyncio\sslproto.py", line 557, in _do_handshake
    self._sslobj.do_handshake()
  File "C:\Program Files\Python311\Lib\ssl.py", line 979, in do_handshake
    self._sslobj.do_handshake()
ssl.SSLCertVerificationError: [SSL: CERTIFICATE_VERIFY_FAILED] certificate verify failed: unable to get local issuer certificate (_ssl.c:1006)

The above exception was the direct cause of the following exception:

Traceback (most recent call last):
  File "C:\Users\oasis\Aibybit_2\src\exchange\bybit_client.py", line 108, in _request
    async with session.get(url, params=request_params, headers=headers) as response:
  File "C:\Users\oasis\Aibybit_2\.venv\Lib\site-packages\aiohttp\client.py", line 1425, in __aenter__
    self._resp: _RetType = await self._coro
                           ^^^^^^^^^^^^^^^^
  File "C:\Users\oasis\Aibybit_2\.venv\Lib\site-packages\aiohttp\client.py", line 703, in _request
    conn = await self._connector.connect(
           ^^^^^^^^^^^^^^^^^^^^^^^^^^^^^^
  File "C:\Users\oasis\Aibybit_2\.venv\Lib\site-packages\aiohttp\connector.py", line 548, in connect
    proto = await self._create_connection(req, traces, timeout)
            ^^^^^^^^^^^^^^^^^^^^^^^^^^^^^^^^^^^^^^^^^^^^^^^^^^^
  File "C:\Users\oasis\Aibybit_2\.venv\Lib\site-packages\aiohttp\connector.py", line 1056, in _create_connection
    _, proto = await self._create_direct_connection(req, traces, timeout)
               ^^^^^^^^^^^^^^^^^^^^^^^^^^^^^^^^^^^^^^^^^^^^^^^^^^^^^^^^^^
  File "C:\Users\oasis\Aibybit_2\.venv\Lib\site-packages\aiohttp\connector.py", line 1411, in _create_direct_connection
    raise last_exc
  File "C:\Users\oasis\Aibybit_2\.venv\Lib\site-packages\aiohttp\connector.py", line 1380, in _create_direct_connection
    transp, proto = await self._wrap_create_connection(
                    ^^^^^^^^^^^^^^^^^^^^^^^^^^^^^^^^^^^
  File "C:\Users\oasis\Aibybit_2\.venv\Lib\site-packages\aiohttp\connector.py", line 1129, in _wrap_create_connection
    raise ClientConnectorCertificateError(req.connection_key, exc) from exc
aiohttp.client_exceptions.ClientConnectorCertificateError: Cannot connect to host api-testnet.bybit.com:443 ssl:True [SSLCertVerificationError: (1, '[SSL: CERTIFICATE_VERIFY_FAILED] certificate verify failed: unable to get local issuer certificate (_ssl.c:1006)')]

2025-02-27 15:36:09,162 - exchange.bybit_client - ERROR - API 요청 실패: Cannot connect to host api-testnet.bybit.com:443 ssl:True [SSLCertVerificationError: (1, '[SSL: CERTIFICATE_VERIFY_FAILED] certificate verify failed: unable to get local issuer certificate (_ssl.c:1006)')]
2025-02-27 15:36:09,165 - exchange.bybit_client - ERROR - Traceback (most recent call last):
  File "C:\Users\oasis\Aibybit_2\.venv\Lib\site-packages\aiohttp\connector.py", line 1123, in _wrap_create_connection
    connection = await self._loop.create_connection(
                 ^^^^^^^^^^^^^^^^^^^^^^^^^^^^^^^^^^^
  File "C:\Program Files\Python311\Lib\asyncio\base_events.py", line 1112, in create_connection
    transport, protocol = await self._create_connection_transport(
                          ^^^^^^^^^^^^^^^^^^^^^^^^^^^^^^^^^^^^^^^^
  File "C:\Program Files\Python311\Lib\asyncio\base_events.py", line 1145, in _create_connection_transport
    await waiter
  File "C:\Program Files\Python311\Lib\asyncio\sslproto.py", line 575, in _on_handshake_complete
    raise handshake_exc
  File "C:\Program Files\Python311\Lib\asyncio\sslproto.py", line 557, in _do_handshake
    self._sslobj.do_handshake()
  File "C:\Program Files\Python311\Lib\ssl.py", line 979, in do_handshake
    self._sslobj.do_handshake()
ssl.SSLCertVerificationError: [SSL: CERTIFICATE_VERIFY_FAILED] certificate verify failed: unable to get local issuer certificate (_ssl.c:1006)

The above exception was the direct cause of the following exception:

Traceback (most recent call last):
  File "C:\Users\oasis\Aibybit_2\src\exchange\bybit_client.py", line 108, in _request
    async with session.get(url, params=request_params, headers=headers) as response:
  File "C:\Users\oasis\Aibybit_2\.venv\Lib\site-packages\aiohttp\client.py", line 1425, in __aenter__
    self._resp: _RetType = await self._coro
                           ^^^^^^^^^^^^^^^^
  File "C:\Users\oasis\Aibybit_2\.venv\Lib\site-packages\aiohttp\client.py", line 703, in _request
    conn = await self._connector.connect(
           ^^^^^^^^^^^^^^^^^^^^^^^^^^^^^^
  File "C:\Users\oasis\Aibybit_2\.venv\Lib\site-packages\aiohttp\connector.py", line 548, in connect
    proto = await self._create_connection(req, traces, timeout)
            ^^^^^^^^^^^^^^^^^^^^^^^^^^^^^^^^^^^^^^^^^^^^^^^^^^^
  File "C:\Users\oasis\Aibybit_2\.venv\Lib\site-packages\aiohttp\connector.py", line 1056, in _create_connection
    _, proto = await self._create_direct_connection(req, traces, timeout)
               ^^^^^^^^^^^^^^^^^^^^^^^^^^^^^^^^^^^^^^^^^^^^^^^^^^^^^^^^^^
  File "C:\Users\oasis\Aibybit_2\.venv\Lib\site-packages\aiohttp\connector.py", line 1411, in _create_direct_connection
    raise last_exc
  File "C:\Users\oasis\Aibybit_2\.venv\Lib\site-packages\aiohttp\connector.py", line 1380, in _create_direct_connection
    transp, proto = await self._wrap_create_connection(
                    ^^^^^^^^^^^^^^^^^^^^^^^^^^^^^^^^^^^
  File "C:\Users\oasis\Aibybit_2\.venv\Lib\site-packages\aiohttp\connector.py", line 1129, in _wrap_create_connection
    raise ClientConnectorCertificateError(req.connection_key, exc) from exc
aiohttp.client_exceptions.ClientConnectorCertificateError: Cannot connect to host api-testnet.bybit.com:443 ssl:True [SSLCertVerificationError: (1, '[SSL: CERTIFICATE_VERIFY_FAILED] certificate verify failed: unable to get local issuer certificate (_ssl.c:1006)')]

2025-02-27 15:36:10,268 - exchange.bybit_client - ERROR - API 요청 실패: Cannot connect to host api-testnet.bybit.com:443 ssl:True [SSLCertVerificationError: (1, '[SSL: CERTIFICATE_VERIFY_FAILED] certificate verify failed: unable to get local issuer certificate (_ssl.c:1006)')]
2025-02-27 15:36:10,270 - exchange.bybit_client - ERROR - Traceback (most recent call last):
  File "C:\Users\oasis\Aibybit_2\.venv\Lib\site-packages\aiohttp\connector.py", line 1123, in _wrap_create_connection
    connection = await self._loop.create_connection(
                 ^^^^^^^^^^^^^^^^^^^^^^^^^^^^^^^^^^^
  File "C:\Program Files\Python311\Lib\asyncio\base_events.py", line 1112, in create_connection
    transport, protocol = await self._create_connection_transport(
                          ^^^^^^^^^^^^^^^^^^^^^^^^^^^^^^^^^^^^^^^^
  File "C:\Program Files\Python311\Lib\asyncio\base_events.py", line 1145, in _create_connection_transport
    await waiter
  File "C:\Program Files\Python311\Lib\asyncio\sslproto.py", line 575, in _on_handshake_complete
    raise handshake_exc
  File "C:\Program Files\Python311\Lib\asyncio\sslproto.py", line 557, in _do_handshake
    self._sslobj.do_handshake()
  File "C:\Program Files\Python311\Lib\ssl.py", line 979, in do_handshake
    self._sslobj.do_handshake()
ssl.SSLCertVerificationError: [SSL: CERTIFICATE_VERIFY_FAILED] certificate verify failed: unable to get local issuer certificate (_ssl.c:1006)

The above exception was the direct cause of the following exception:

Traceback (most recent call last):
  File "C:\Users\oasis\Aibybit_2\src\exchange\bybit_client.py", line 108, in _request
    async with session.get(url, params=request_params, headers=headers) as response:
  File "C:\Users\oasis\Aibybit_2\.venv\Lib\site-packages\aiohttp\client.py", line 1425, in __aenter__
    self._resp: _RetType = await self._coro
                           ^^^^^^^^^^^^^^^^
  File "C:\Users\oasis\Aibybit_2\.venv\Lib\site-packages\aiohttp\client.py", line 703, in _request
    conn = await self._connector.connect(
           ^^^^^^^^^^^^^^^^^^^^^^^^^^^^^^
  File "C:\Users\oasis\Aibybit_2\.venv\Lib\site-packages\aiohttp\connector.py", line 548, in connect
    proto = await self._create_connection(req, traces, timeout)
            ^^^^^^^^^^^^^^^^^^^^^^^^^^^^^^^^^^^^^^^^^^^^^^^^^^^
  File "C:\Users\oasis\Aibybit_2\.venv\Lib\site-packages\aiohttp\connector.py", line 1056, in _create_connection
    _, proto = await self._create_direct_connection(req, traces, timeout)
               ^^^^^^^^^^^^^^^^^^^^^^^^^^^^^^^^^^^^^^^^^^^^^^^^^^^^^^^^^^
  File "C:\Users\oasis\Aibybit_2\.venv\Lib\site-packages\aiohttp\connector.py", line 1411, in _create_direct_connection
    raise last_exc
  File "C:\Users\oasis\Aibybit_2\.venv\Lib\site-packages\aiohttp\connector.py", line 1380, in _create_direct_connection
    transp, proto = await self._wrap_create_connection(
                    ^^^^^^^^^^^^^^^^^^^^^^^^^^^^^^^^^^^
  File "C:\Users\oasis\Aibybit_2\.venv\Lib\site-packages\aiohttp\connector.py", line 1129, in _wrap_create_connection
    raise ClientConnectorCertificateError(req.connection_key, exc) from exc
aiohttp.client_exceptions.ClientConnectorCertificateError: Cannot connect to host api-testnet.bybit.com:443 ssl:True [SSLCertVerificationError: (1, '[SSL: CERTIFICATE_VERIFY_FAILED] certificate verify failed: unable to get local issuer certificate (_ssl.c:1006)')]

2025-02-27 15:36:11,367 - exchange.bybit_client - ERROR - API 요청 실패: Cannot connect to host api-testnet.bybit.com:443 ssl:True [SSLCertVerificationError: (1, '[SSL: CERTIFICATE_VERIFY_FAILED] certificate verify failed: unable to get local issuer certificate (_ssl.c:1006)')]
2025-02-27 15:36:11,370 - exchange.bybit_client - ERROR - Traceback (most recent call last):
  File "C:\Users\oasis\Aibybit_2\.venv\Lib\site-packages\aiohttp\connector.py", line 1123, in _wrap_create_connection
    connection = await self._loop.create_connection(
                 ^^^^^^^^^^^^^^^^^^^^^^^^^^^^^^^^^^^
  File "C:\Program Files\Python311\Lib\asyncio\base_events.py", line 1112, in create_connection
    transport, protocol = await self._create_connection_transport(
                          ^^^^^^^^^^^^^^^^^^^^^^^^^^^^^^^^^^^^^^^^
  File "C:\Program Files\Python311\Lib\asyncio\base_events.py", line 1145, in _create_connection_transport
    await waiter
  File "C:\Program Files\Python311\Lib\asyncio\sslproto.py", line 575, in _on_handshake_complete
    raise handshake_exc
  File "C:\Program Files\Python311\Lib\asyncio\sslproto.py", line 557, in _do_handshake
    self._sslobj.do_handshake()
  File "C:\Program Files\Python311\Lib\ssl.py", line 979, in do_handshake
    self._sslobj.do_handshake()
ssl.SSLCertVerificationError: [SSL: CERTIFICATE_VERIFY_FAILED] certificate verify failed: unable to get local issuer certificate (_ssl.c:1006)

The above exception was the direct cause of the following exception:

Traceback (most recent call last):
  File "C:\Users\oasis\Aibybit_2\src\exchange\bybit_client.py", line 108, in _request
    async with session.get(url, params=request_params, headers=headers) as response:
  File "C:\Users\oasis\Aibybit_2\.venv\Lib\site-packages\aiohttp\client.py", line 1425, in __aenter__
    self._resp: _RetType = await self._coro
                           ^^^^^^^^^^^^^^^^
  File "C:\Users\oasis\Aibybit_2\.venv\Lib\site-packages\aiohttp\client.py", line 703, in _request
    conn = await self._connector.connect(
           ^^^^^^^^^^^^^^^^^^^^^^^^^^^^^^
  File "C:\Users\oasis\Aibybit_2\.venv\Lib\site-packages\aiohttp\connector.py", line 548, in connect
    proto = await self._create_connection(req, traces, timeout)
            ^^^^^^^^^^^^^^^^^^^^^^^^^^^^^^^^^^^^^^^^^^^^^^^^^^^
  File "C:\Users\oasis\Aibybit_2\.venv\Lib\site-packages\aiohttp\connector.py", line 1056, in _create_connection
    _, proto = await self._create_direct_connection(req, traces, timeout)
               ^^^^^^^^^^^^^^^^^^^^^^^^^^^^^^^^^^^^^^^^^^^^^^^^^^^^^^^^^^
  File "C:\Users\oasis\Aibybit_2\.venv\Lib\site-packages\aiohttp\connector.py", line 1411, in _create_direct_connection
    raise last_exc
  File "C:\Users\oasis\Aibybit_2\.venv\Lib\site-packages\aiohttp\connector.py", line 1380, in _create_direct_connection
    transp, proto = await self._wrap_create_connection(
                    ^^^^^^^^^^^^^^^^^^^^^^^^^^^^^^^^^^^
  File "C:\Users\oasis\Aibybit_2\.venv\Lib\site-packages\aiohttp\connector.py", line 1129, in _wrap_create_connection
    raise ClientConnectorCertificateError(req.connection_key, exc) from exc
aiohttp.client_exceptions.ClientConnectorCertificateError: Cannot connect to host api-testnet.bybit.com:443 ssl:True [SSLCertVerificationError: (1, '[SSL: CERTIFICATE_VERIFY_FAILED] certificate verify failed: unable to get local issuer certificate (_ssl.c:1006)')]

2025-02-27 15:53:23,175 - exchange.bybit_client - ERROR - API 요청 실패: Cannot connect to host api-testnet.bybit.com:443 ssl:True [SSLCertVerificationError: (1, '[SSL: CERTIFICATE_VERIFY_FAILED] certificate verify failed: unable to get local issuer certificate (_ssl.c:1006)')]
2025-02-27 15:53:23,183 - exchange.bybit_client - ERROR - Traceback (most recent call last):
  File "C:\Users\oasis\Aibybit_2\.venv\Lib\site-packages\aiohttp\connector.py", line 1123, in _wrap_create_connection
    connection = await self._loop.create_connection(
                 ^^^^^^^^^^^^^^^^^^^^^^^^^^^^^^^^^^^
  File "C:\Program Files\Python311\Lib\asyncio\base_events.py", line 1112, in create_connection
    transport, protocol = await self._create_connection_transport(
                          ^^^^^^^^^^^^^^^^^^^^^^^^^^^^^^^^^^^^^^^^
  File "C:\Program Files\Python311\Lib\asyncio\base_events.py", line 1145, in _create_connection_transport
    await waiter
  File "C:\Program Files\Python311\Lib\asyncio\sslproto.py", line 575, in _on_handshake_complete
    raise handshake_exc
  File "C:\Program Files\Python311\Lib\asyncio\sslproto.py", line 557, in _do_handshake
    self._sslobj.do_handshake()
  File "C:\Program Files\Python311\Lib\ssl.py", line 979, in do_handshake
    self._sslobj.do_handshake()
ssl.SSLCertVerificationError: [SSL: CERTIFICATE_VERIFY_FAILED] certificate verify failed: unable to get local issuer certificate (_ssl.c:1006)

The above exception was the direct cause of the following exception:

Traceback (most recent call last):
  File "C:\Users\oasis\Aibybit_2\src\exchange\bybit_client.py", line 108, in _request
    async with session.get(url, params=request_params, headers=headers) as response:
  File "C:\Users\oasis\Aibybit_2\.venv\Lib\site-packages\aiohttp\client.py", line 1425, in __aenter__
    self._resp: _RetType = await self._coro
                           ^^^^^^^^^^^^^^^^
  File "C:\Users\oasis\Aibybit_2\.venv\Lib\site-packages\aiohttp\client.py", line 703, in _request
    conn = await self._connector.connect(
           ^^^^^^^^^^^^^^^^^^^^^^^^^^^^^^
  File "C:\Users\oasis\Aibybit_2\.venv\Lib\site-packages\aiohttp\connector.py", line 548, in connect
    proto = await self._create_connection(req, traces, timeout)
            ^^^^^^^^^^^^^^^^^^^^^^^^^^^^^^^^^^^^^^^^^^^^^^^^^^^
  File "C:\Users\oasis\Aibybit_2\.venv\Lib\site-packages\aiohttp\connector.py", line 1056, in _create_connection
    _, proto = await self._create_direct_connection(req, traces, timeout)
               ^^^^^^^^^^^^^^^^^^^^^^^^^^^^^^^^^^^^^^^^^^^^^^^^^^^^^^^^^^
  File "C:\Users\oasis\Aibybit_2\.venv\Lib\site-packages\aiohttp\connector.py", line 1411, in _create_direct_connection
    raise last_exc
  File "C:\Users\oasis\Aibybit_2\.venv\Lib\site-packages\aiohttp\connector.py", line 1380, in _create_direct_connection
    transp, proto = await self._wrap_create_connection(
                    ^^^^^^^^^^^^^^^^^^^^^^^^^^^^^^^^^^^
  File "C:\Users\oasis\Aibybit_2\.venv\Lib\site-packages\aiohttp\connector.py", line 1129, in _wrap_create_connection
    raise ClientConnectorCertificateError(req.connection_key, exc) from exc
aiohttp.client_exceptions.ClientConnectorCertificateError: Cannot connect to host api-testnet.bybit.com:443 ssl:True [SSLCertVerificationError: (1, '[SSL: CERTIFICATE_VERIFY_FAILED] certificate verify failed: unable to get local issuer certificate (_ssl.c:1006)')]

2025-02-27 15:53:24,298 - exchange.bybit_client - ERROR - API 요청 실패: Cannot connect to host api-testnet.bybit.com:443 ssl:True [SSLCertVerificationError: (1, '[SSL: CERTIFICATE_VERIFY_FAILED] certificate verify failed: unable to get local issuer certificate (_ssl.c:1006)')]
2025-02-27 15:53:24,299 - exchange.bybit_client - ERROR - Traceback (most recent call last):
  File "C:\Users\oasis\Aibybit_2\.venv\Lib\site-packages\aiohttp\connector.py", line 1123, in _wrap_create_connection
    connection = await self._loop.create_connection(
                 ^^^^^^^^^^^^^^^^^^^^^^^^^^^^^^^^^^^
  File "C:\Program Files\Python311\Lib\asyncio\base_events.py", line 1112, in create_connection
    transport, protocol = await self._create_connection_transport(
                          ^^^^^^^^^^^^^^^^^^^^^^^^^^^^^^^^^^^^^^^^
  File "C:\Program Files\Python311\Lib\asyncio\base_events.py", line 1145, in _create_connection_transport
    await waiter
  File "C:\Program Files\Python311\Lib\asyncio\sslproto.py", line 575, in _on_handshake_complete
    raise handshake_exc
  File "C:\Program Files\Python311\Lib\asyncio\sslproto.py", line 557, in _do_handshake
    self._sslobj.do_handshake()
  File "C:\Program Files\Python311\Lib\ssl.py", line 979, in do_handshake
    self._sslobj.do_handshake()
ssl.SSLCertVerificationError: [SSL: CERTIFICATE_VERIFY_FAILED] certificate verify failed: unable to get local issuer certificate (_ssl.c:1006)

The above exception was the direct cause of the following exception:

Traceback (most recent call last):
  File "C:\Users\oasis\Aibybit_2\src\exchange\bybit_client.py", line 108, in _request
    async with session.get(url, params=request_params, headers=headers) as response:
  File "C:\Users\oasis\Aibybit_2\.venv\Lib\site-packages\aiohttp\client.py", line 1425, in __aenter__
    self._resp: _RetType = await self._coro
                           ^^^^^^^^^^^^^^^^
  File "C:\Users\oasis\Aibybit_2\.venv\Lib\site-packages\aiohttp\client.py", line 703, in _request
    conn = await self._connector.connect(
           ^^^^^^^^^^^^^^^^^^^^^^^^^^^^^^
  File "C:\Users\oasis\Aibybit_2\.venv\Lib\site-packages\aiohttp\connector.py", line 548, in connect
    proto = await self._create_connection(req, traces, timeout)
            ^^^^^^^^^^^^^^^^^^^^^^^^^^^^^^^^^^^^^^^^^^^^^^^^^^^
  File "C:\Users\oasis\Aibybit_2\.venv\Lib\site-packages\aiohttp\connector.py", line 1056, in _create_connection
    _, proto = await self._create_direct_connection(req, traces, timeout)
               ^^^^^^^^^^^^^^^^^^^^^^^^^^^^^^^^^^^^^^^^^^^^^^^^^^^^^^^^^^
  File "C:\Users\oasis\Aibybit_2\.venv\Lib\site-packages\aiohttp\connector.py", line 1411, in _create_direct_connection
    raise last_exc
  File "C:\Users\oasis\Aibybit_2\.venv\Lib\site-packages\aiohttp\connector.py", line 1380, in _create_direct_connection
    transp, proto = await self._wrap_create_connection(
                    ^^^^^^^^^^^^^^^^^^^^^^^^^^^^^^^^^^^
  File "C:\Users\oasis\Aibybit_2\.venv\Lib\site-packages\aiohttp\connector.py", line 1129, in _wrap_create_connection
    raise ClientConnectorCertificateError(req.connection_key, exc) from exc
aiohttp.client_exceptions.ClientConnectorCertificateError: Cannot connect to host api-testnet.bybit.com:443 ssl:True [SSLCertVerificationError: (1, '[SSL: CERTIFICATE_VERIFY_FAILED] certificate verify failed: unable to get local issuer certificate (_ssl.c:1006)')]

2025-02-27 15:53:25,450 - exchange.bybit_client - ERROR - API 요청 실패: Cannot connect to host api-testnet.bybit.com:443 ssl:True [SSLCertVerificationError: (1, '[SSL: CERTIFICATE_VERIFY_FAILED] certificate verify failed: unable to get local issuer certificate (_ssl.c:1006)')]
2025-02-27 15:53:25,454 - exchange.bybit_client - ERROR - Traceback (most recent call last):
  File "C:\Users\oasis\Aibybit_2\.venv\Lib\site-packages\aiohttp\connector.py", line 1123, in _wrap_create_connection
    connection = await self._loop.create_connection(
                 ^^^^^^^^^^^^^^^^^^^^^^^^^^^^^^^^^^^
  File "C:\Program Files\Python311\Lib\asyncio\base_events.py", line 1112, in create_connection
    transport, protocol = await self._create_connection_transport(
                          ^^^^^^^^^^^^^^^^^^^^^^^^^^^^^^^^^^^^^^^^
  File "C:\Program Files\Python311\Lib\asyncio\base_events.py", line 1145, in _create_connection_transport
    await waiter
  File "C:\Program Files\Python311\Lib\asyncio\sslproto.py", line 575, in _on_handshake_complete
    raise handshake_exc
  File "C:\Program Files\Python311\Lib\asyncio\sslproto.py", line 557, in _do_handshake
    self._sslobj.do_handshake()
  File "C:\Program Files\Python311\Lib\ssl.py", line 979, in do_handshake
    self._sslobj.do_handshake()
ssl.SSLCertVerificationError: [SSL: CERTIFICATE_VERIFY_FAILED] certificate verify failed: unable to get local issuer certificate (_ssl.c:1006)

The above exception was the direct cause of the following exception:

Traceback (most recent call last):
  File "C:\Users\oasis\Aibybit_2\src\exchange\bybit_client.py", line 108, in _request
    async with session.get(url, params=request_params, headers=headers) as response:
  File "C:\Users\oasis\Aibybit_2\.venv\Lib\site-packages\aiohttp\client.py", line 1425, in __aenter__
    self._resp: _RetType = await self._coro
                           ^^^^^^^^^^^^^^^^
  File "C:\Users\oasis\Aibybit_2\.venv\Lib\site-packages\aiohttp\client.py", line 703, in _request
    conn = await self._connector.connect(
           ^^^^^^^^^^^^^^^^^^^^^^^^^^^^^^
  File "C:\Users\oasis\Aibybit_2\.venv\Lib\site-packages\aiohttp\connector.py", line 548, in connect
    proto = await self._create_connection(req, traces, timeout)
            ^^^^^^^^^^^^^^^^^^^^^^^^^^^^^^^^^^^^^^^^^^^^^^^^^^^
  File "C:\Users\oasis\Aibybit_2\.venv\Lib\site-packages\aiohttp\connector.py", line 1056, in _create_connection
    _, proto = await self._create_direct_connection(req, traces, timeout)
               ^^^^^^^^^^^^^^^^^^^^^^^^^^^^^^^^^^^^^^^^^^^^^^^^^^^^^^^^^^
  File "C:\Users\oasis\Aibybit_2\.venv\Lib\site-packages\aiohttp\connector.py", line 1411, in _create_direct_connection
    raise last_exc
  File "C:\Users\oasis\Aibybit_2\.venv\Lib\site-packages\aiohttp\connector.py", line 1380, in _create_direct_connection
    transp, proto = await self._wrap_create_connection(
                    ^^^^^^^^^^^^^^^^^^^^^^^^^^^^^^^^^^^
  File "C:\Users\oasis\Aibybit_2\.venv\Lib\site-packages\aiohttp\connector.py", line 1129, in _wrap_create_connection
    raise ClientConnectorCertificateError(req.connection_key, exc) from exc
aiohttp.client_exceptions.ClientConnectorCertificateError: Cannot connect to host api-testnet.bybit.com:443 ssl:True [SSLCertVerificationError: (1, '[SSL: CERTIFICATE_VERIFY_FAILED] certificate verify failed: unable to get local issuer certificate (_ssl.c:1006)')]

2025-02-27 15:53:26,591 - exchange.bybit_client - ERROR - API 요청 실패: Cannot connect to host api-testnet.bybit.com:443 ssl:True [SSLCertVerificationError: (1, '[SSL: CERTIFICATE_VERIFY_FAILED] certificate verify failed: unable to get local issuer certificate (_ssl.c:1006)')]
2025-02-27 15:53:26,595 - exchange.bybit_client - ERROR - Traceback (most recent call last):
  File "C:\Users\oasis\Aibybit_2\.venv\Lib\site-packages\aiohttp\connector.py", line 1123, in _wrap_create_connection
    connection = await self._loop.create_connection(
                 ^^^^^^^^^^^^^^^^^^^^^^^^^^^^^^^^^^^
  File "C:\Program Files\Python311\Lib\asyncio\base_events.py", line 1112, in create_connection
    transport, protocol = await self._create_connection_transport(
                          ^^^^^^^^^^^^^^^^^^^^^^^^^^^^^^^^^^^^^^^^
  File "C:\Program Files\Python311\Lib\asyncio\base_events.py", line 1145, in _create_connection_transport
    await waiter
  File "C:\Program Files\Python311\Lib\asyncio\sslproto.py", line 575, in _on_handshake_complete
    raise handshake_exc
  File "C:\Program Files\Python311\Lib\asyncio\sslproto.py", line 557, in _do_handshake
    self._sslobj.do_handshake()
  File "C:\Program Files\Python311\Lib\ssl.py", line 979, in do_handshake
    self._sslobj.do_handshake()
ssl.SSLCertVerificationError: [SSL: CERTIFICATE_VERIFY_FAILED] certificate verify failed: unable to get local issuer certificate (_ssl.c:1006)

The above exception was the direct cause of the following exception:

Traceback (most recent call last):
  File "C:\Users\oasis\Aibybit_2\src\exchange\bybit_client.py", line 108, in _request
    async with session.get(url, params=request_params, headers=headers) as response:
  File "C:\Users\oasis\Aibybit_2\.venv\Lib\site-packages\aiohttp\client.py", line 1425, in __aenter__
    self._resp: _RetType = await self._coro
                           ^^^^^^^^^^^^^^^^
  File "C:\Users\oasis\Aibybit_2\.venv\Lib\site-packages\aiohttp\client.py", line 703, in _request
    conn = await self._connector.connect(
           ^^^^^^^^^^^^^^^^^^^^^^^^^^^^^^
  File "C:\Users\oasis\Aibybit_2\.venv\Lib\site-packages\aiohttp\connector.py", line 548, in connect
    proto = await self._create_connection(req, traces, timeout)
            ^^^^^^^^^^^^^^^^^^^^^^^^^^^^^^^^^^^^^^^^^^^^^^^^^^^
  File "C:\Users\oasis\Aibybit_2\.venv\Lib\site-packages\aiohttp\connector.py", line 1056, in _create_connection
    _, proto = await self._create_direct_connection(req, traces, timeout)
               ^^^^^^^^^^^^^^^^^^^^^^^^^^^^^^^^^^^^^^^^^^^^^^^^^^^^^^^^^^
  File "C:\Users\oasis\Aibybit_2\.venv\Lib\site-packages\aiohttp\connector.py", line 1411, in _create_direct_connection
    raise last_exc
  File "C:\Users\oasis\Aibybit_2\.venv\Lib\site-packages\aiohttp\connector.py", line 1380, in _create_direct_connection
    transp, proto = await self._wrap_create_connection(
                    ^^^^^^^^^^^^^^^^^^^^^^^^^^^^^^^^^^^
  File "C:\Users\oasis\Aibybit_2\.venv\Lib\site-packages\aiohttp\connector.py", line 1129, in _wrap_create_connection
    raise ClientConnectorCertificateError(req.connection_key, exc) from exc
aiohttp.client_exceptions.ClientConnectorCertificateError: Cannot connect to host api-testnet.bybit.com:443 ssl:True [SSLCertVerificationError: (1, '[SSL: CERTIFICATE_VERIFY_FAILED] certificate verify failed: unable to get local issuer certificate (_ssl.c:1006)')]

2025-02-27 15:53:27,756 - exchange.bybit_client - ERROR - API 요청 실패: Cannot connect to host api-testnet.bybit.com:443 ssl:True [SSLCertVerificationError: (1, '[SSL: CERTIFICATE_VERIFY_FAILED] certificate verify failed: unable to get local issuer certificate (_ssl.c:1006)')]
2025-02-27 15:53:27,758 - exchange.bybit_client - ERROR - Traceback (most recent call last):
  File "C:\Users\oasis\Aibybit_2\.venv\Lib\site-packages\aiohttp\connector.py", line 1123, in _wrap_create_connection
    connection = await self._loop.create_connection(
                 ^^^^^^^^^^^^^^^^^^^^^^^^^^^^^^^^^^^
  File "C:\Program Files\Python311\Lib\asyncio\base_events.py", line 1112, in create_connection
    transport, protocol = await self._create_connection_transport(
                          ^^^^^^^^^^^^^^^^^^^^^^^^^^^^^^^^^^^^^^^^
  File "C:\Program Files\Python311\Lib\asyncio\base_events.py", line 1145, in _create_connection_transport
    await waiter
  File "C:\Program Files\Python311\Lib\asyncio\sslproto.py", line 575, in _on_handshake_complete
    raise handshake_exc
  File "C:\Program Files\Python311\Lib\asyncio\sslproto.py", line 557, in _do_handshake
    self._sslobj.do_handshake()
  File "C:\Program Files\Python311\Lib\ssl.py", line 979, in do_handshake
    self._sslobj.do_handshake()
ssl.SSLCertVerificationError: [SSL: CERTIFICATE_VERIFY_FAILED] certificate verify failed: unable to get local issuer certificate (_ssl.c:1006)

The above exception was the direct cause of the following exception:

Traceback (most recent call last):
  File "C:\Users\oasis\Aibybit_2\src\exchange\bybit_client.py", line 108, in _request
    async with session.get(url, params=request_params, headers=headers) as response:
  File "C:\Users\oasis\Aibybit_2\.venv\Lib\site-packages\aiohttp\client.py", line 1425, in __aenter__
    self._resp: _RetType = await self._coro
                           ^^^^^^^^^^^^^^^^
  File "C:\Users\oasis\Aibybit_2\.venv\Lib\site-packages\aiohttp\client.py", line 703, in _request
    conn = await self._connector.connect(
           ^^^^^^^^^^^^^^^^^^^^^^^^^^^^^^
  File "C:\Users\oasis\Aibybit_2\.venv\Lib\site-packages\aiohttp\connector.py", line 548, in connect
    proto = await self._create_connection(req, traces, timeout)
            ^^^^^^^^^^^^^^^^^^^^^^^^^^^^^^^^^^^^^^^^^^^^^^^^^^^
  File "C:\Users\oasis\Aibybit_2\.venv\Lib\site-packages\aiohttp\connector.py", line 1056, in _create_connection
    _, proto = await self._create_direct_connection(req, traces, timeout)
               ^^^^^^^^^^^^^^^^^^^^^^^^^^^^^^^^^^^^^^^^^^^^^^^^^^^^^^^^^^
  File "C:\Users\oasis\Aibybit_2\.venv\Lib\site-packages\aiohttp\connector.py", line 1411, in _create_direct_connection
    raise last_exc
  File "C:\Users\oasis\Aibybit_2\.venv\Lib\site-packages\aiohttp\connector.py", line 1380, in _create_direct_connection
    transp, proto = await self._wrap_create_connection(
                    ^^^^^^^^^^^^^^^^^^^^^^^^^^^^^^^^^^^
  File "C:\Users\oasis\Aibybit_2\.venv\Lib\site-packages\aiohttp\connector.py", line 1129, in _wrap_create_connection
    raise ClientConnectorCertificateError(req.connection_key, exc) from exc
aiohttp.client_exceptions.ClientConnectorCertificateError: Cannot connect to host api-testnet.bybit.com:443 ssl:True [SSLCertVerificationError: (1, '[SSL: CERTIFICATE_VERIFY_FAILED] certificate verify failed: unable to get local issuer certificate (_ssl.c:1006)')]

2025-02-27 15:53:28,866 - exchange.bybit_client - ERROR - API 요청 실패: Cannot connect to host api-testnet.bybit.com:443 ssl:True [SSLCertVerificationError: (1, '[SSL: CERTIFICATE_VERIFY_FAILED] certificate verify failed: unable to get local issuer certificate (_ssl.c:1006)')]
2025-02-27 15:53:28,870 - exchange.bybit_client - ERROR - Traceback (most recent call last):
  File "C:\Users\oasis\Aibybit_2\.venv\Lib\site-packages\aiohttp\connector.py", line 1123, in _wrap_create_connection
    connection = await self._loop.create_connection(
                 ^^^^^^^^^^^^^^^^^^^^^^^^^^^^^^^^^^^
  File "C:\Program Files\Python311\Lib\asyncio\base_events.py", line 1112, in create_connection
    transport, protocol = await self._create_connection_transport(
                          ^^^^^^^^^^^^^^^^^^^^^^^^^^^^^^^^^^^^^^^^
  File "C:\Program Files\Python311\Lib\asyncio\base_events.py", line 1145, in _create_connection_transport
    await waiter
  File "C:\Program Files\Python311\Lib\asyncio\sslproto.py", line 575, in _on_handshake_complete
    raise handshake_exc
  File "C:\Program Files\Python311\Lib\asyncio\sslproto.py", line 557, in _do_handshake
    self._sslobj.do_handshake()
  File "C:\Program Files\Python311\Lib\ssl.py", line 979, in do_handshake
    self._sslobj.do_handshake()
ssl.SSLCertVerificationError: [SSL: CERTIFICATE_VERIFY_FAILED] certificate verify failed: unable to get local issuer certificate (_ssl.c:1006)

The above exception was the direct cause of the following exception:

Traceback (most recent call last):
  File "C:\Users\oasis\Aibybit_2\src\exchange\bybit_client.py", line 108, in _request
    async with session.get(url, params=request_params, headers=headers) as response:
  File "C:\Users\oasis\Aibybit_2\.venv\Lib\site-packages\aiohttp\client.py", line 1425, in __aenter__
    self._resp: _RetType = await self._coro
                           ^^^^^^^^^^^^^^^^
  File "C:\Users\oasis\Aibybit_2\.venv\Lib\site-packages\aiohttp\client.py", line 703, in _request
    conn = await self._connector.connect(
           ^^^^^^^^^^^^^^^^^^^^^^^^^^^^^^
  File "C:\Users\oasis\Aibybit_2\.venv\Lib\site-packages\aiohttp\connector.py", line 548, in connect
    proto = await self._create_connection(req, traces, timeout)
            ^^^^^^^^^^^^^^^^^^^^^^^^^^^^^^^^^^^^^^^^^^^^^^^^^^^
  File "C:\Users\oasis\Aibybit_2\.venv\Lib\site-packages\aiohttp\connector.py", line 1056, in _create_connection
    _, proto = await self._create_direct_connection(req, traces, timeout)
               ^^^^^^^^^^^^^^^^^^^^^^^^^^^^^^^^^^^^^^^^^^^^^^^^^^^^^^^^^^
  File "C:\Users\oasis\Aibybit_2\.venv\Lib\site-packages\aiohttp\connector.py", line 1411, in _create_direct_connection
    raise last_exc
  File "C:\Users\oasis\Aibybit_2\.venv\Lib\site-packages\aiohttp\connector.py", line 1380, in _create_direct_connection
    transp, proto = await self._wrap_create_connection(
                    ^^^^^^^^^^^^^^^^^^^^^^^^^^^^^^^^^^^
  File "C:\Users\oasis\Aibybit_2\.venv\Lib\site-packages\aiohttp\connector.py", line 1129, in _wrap_create_connection
    raise ClientConnectorCertificateError(req.connection_key, exc) from exc
aiohttp.client_exceptions.ClientConnectorCertificateError: Cannot connect to host api-testnet.bybit.com:443 ssl:True [SSLCertVerificationError: (1, '[SSL: CERTIFICATE_VERIFY_FAILED] certificate verify failed: unable to get local issuer certificate (_ssl.c:1006)')]

2025-02-27 15:53:29,987 - exchange.bybit_client - ERROR - API 요청 실패: Cannot connect to host api-testnet.bybit.com:443 ssl:True [SSLCertVerificationError: (1, '[SSL: CERTIFICATE_VERIFY_FAILED] certificate verify failed: unable to get local issuer certificate (_ssl.c:1006)')]
2025-02-27 15:53:29,989 - exchange.bybit_client - ERROR - Traceback (most recent call last):
  File "C:\Users\oasis\Aibybit_2\.venv\Lib\site-packages\aiohttp\connector.py", line 1123, in _wrap_create_connection
    connection = await self._loop.create_connection(
                 ^^^^^^^^^^^^^^^^^^^^^^^^^^^^^^^^^^^
  File "C:\Program Files\Python311\Lib\asyncio\base_events.py", line 1112, in create_connection
    transport, protocol = await self._create_connection_transport(
                          ^^^^^^^^^^^^^^^^^^^^^^^^^^^^^^^^^^^^^^^^
  File "C:\Program Files\Python311\Lib\asyncio\base_events.py", line 1145, in _create_connection_transport
    await waiter
  File "C:\Program Files\Python311\Lib\asyncio\sslproto.py", line 575, in _on_handshake_complete
    raise handshake_exc
  File "C:\Program Files\Python311\Lib\asyncio\sslproto.py", line 557, in _do_handshake
    self._sslobj.do_handshake()
  File "C:\Program Files\Python311\Lib\ssl.py", line 979, in do_handshake
    self._sslobj.do_handshake()
ssl.SSLCertVerificationError: [SSL: CERTIFICATE_VERIFY_FAILED] certificate verify failed: unable to get local issuer certificate (_ssl.c:1006)

The above exception was the direct cause of the following exception:

Traceback (most recent call last):
  File "C:\Users\oasis\Aibybit_2\src\exchange\bybit_client.py", line 108, in _request
    async with session.get(url, params=request_params, headers=headers) as response:
  File "C:\Users\oasis\Aibybit_2\.venv\Lib\site-packages\aiohttp\client.py", line 1425, in __aenter__
    self._resp: _RetType = await self._coro
                           ^^^^^^^^^^^^^^^^
  File "C:\Users\oasis\Aibybit_2\.venv\Lib\site-packages\aiohttp\client.py", line 703, in _request
    conn = await self._connector.connect(
           ^^^^^^^^^^^^^^^^^^^^^^^^^^^^^^
  File "C:\Users\oasis\Aibybit_2\.venv\Lib\site-packages\aiohttp\connector.py", line 548, in connect
    proto = await self._create_connection(req, traces, timeout)
            ^^^^^^^^^^^^^^^^^^^^^^^^^^^^^^^^^^^^^^^^^^^^^^^^^^^
  File "C:\Users\oasis\Aibybit_2\.venv\Lib\site-packages\aiohttp\connector.py", line 1056, in _create_connection
    _, proto = await self._create_direct_connection(req, traces, timeout)
               ^^^^^^^^^^^^^^^^^^^^^^^^^^^^^^^^^^^^^^^^^^^^^^^^^^^^^^^^^^
  File "C:\Users\oasis\Aibybit_2\.venv\Lib\site-packages\aiohttp\connector.py", line 1411, in _create_direct_connection
    raise last_exc
  File "C:\Users\oasis\Aibybit_2\.venv\Lib\site-packages\aiohttp\connector.py", line 1380, in _create_direct_connection
    transp, proto = await self._wrap_create_connection(
                    ^^^^^^^^^^^^^^^^^^^^^^^^^^^^^^^^^^^
  File "C:\Users\oasis\Aibybit_2\.venv\Lib\site-packages\aiohttp\connector.py", line 1129, in _wrap_create_connection
    raise ClientConnectorCertificateError(req.connection_key, exc) from exc
aiohttp.client_exceptions.ClientConnectorCertificateError: Cannot connect to host api-testnet.bybit.com:443 ssl:True [SSLCertVerificationError: (1, '[SSL: CERTIFICATE_VERIFY_FAILED] certificate verify failed: unable to get local issuer certificate (_ssl.c:1006)')]

2025-02-27 15:53:31,098 - exchange.bybit_client - ERROR - API 요청 실패: Cannot connect to host api-testnet.bybit.com:443 ssl:True [SSLCertVerificationError: (1, '[SSL: CERTIFICATE_VERIFY_FAILED] certificate verify failed: unable to get local issuer certificate (_ssl.c:1006)')]
2025-02-27 15:53:31,100 - exchange.bybit_client - ERROR - Traceback (most recent call last):
  File "C:\Users\oasis\Aibybit_2\.venv\Lib\site-packages\aiohttp\connector.py", line 1123, in _wrap_create_connection
    connection = await self._loop.create_connection(
                 ^^^^^^^^^^^^^^^^^^^^^^^^^^^^^^^^^^^
  File "C:\Program Files\Python311\Lib\asyncio\base_events.py", line 1112, in create_connection
    transport, protocol = await self._create_connection_transport(
                          ^^^^^^^^^^^^^^^^^^^^^^^^^^^^^^^^^^^^^^^^
  File "C:\Program Files\Python311\Lib\asyncio\base_events.py", line 1145, in _create_connection_transport
    await waiter
  File "C:\Program Files\Python311\Lib\asyncio\sslproto.py", line 575, in _on_handshake_complete
    raise handshake_exc
  File "C:\Program Files\Python311\Lib\asyncio\sslproto.py", line 557, in _do_handshake
    self._sslobj.do_handshake()
  File "C:\Program Files\Python311\Lib\ssl.py", line 979, in do_handshake
    self._sslobj.do_handshake()
ssl.SSLCertVerificationError: [SSL: CERTIFICATE_VERIFY_FAILED] certificate verify failed: unable to get local issuer certificate (_ssl.c:1006)

The above exception was the direct cause of the following exception:

Traceback (most recent call last):
  File "C:\Users\oasis\Aibybit_2\src\exchange\bybit_client.py", line 108, in _request
    async with session.get(url, params=request_params, headers=headers) as response:
  File "C:\Users\oasis\Aibybit_2\.venv\Lib\site-packages\aiohttp\client.py", line 1425, in __aenter__
    self._resp: _RetType = await self._coro
                           ^^^^^^^^^^^^^^^^
  File "C:\Users\oasis\Aibybit_2\.venv\Lib\site-packages\aiohttp\client.py", line 703, in _request
    conn = await self._connector.connect(
           ^^^^^^^^^^^^^^^^^^^^^^^^^^^^^^
  File "C:\Users\oasis\Aibybit_2\.venv\Lib\site-packages\aiohttp\connector.py", line 548, in connect
    proto = await self._create_connection(req, traces, timeout)
            ^^^^^^^^^^^^^^^^^^^^^^^^^^^^^^^^^^^^^^^^^^^^^^^^^^^
  File "C:\Users\oasis\Aibybit_2\.venv\Lib\site-packages\aiohttp\connector.py", line 1056, in _create_connection
    _, proto = await self._create_direct_connection(req, traces, timeout)
               ^^^^^^^^^^^^^^^^^^^^^^^^^^^^^^^^^^^^^^^^^^^^^^^^^^^^^^^^^^
  File "C:\Users\oasis\Aibybit_2\.venv\Lib\site-packages\aiohttp\connector.py", line 1411, in _create_direct_connection
    raise last_exc
  File "C:\Users\oasis\Aibybit_2\.venv\Lib\site-packages\aiohttp\connector.py", line 1380, in _create_direct_connection
    transp, proto = await self._wrap_create_connection(
                    ^^^^^^^^^^^^^^^^^^^^^^^^^^^^^^^^^^^
  File "C:\Users\oasis\Aibybit_2\.venv\Lib\site-packages\aiohttp\connector.py", line 1129, in _wrap_create_connection
    raise ClientConnectorCertificateError(req.connection_key, exc) from exc
aiohttp.client_exceptions.ClientConnectorCertificateError: Cannot connect to host api-testnet.bybit.com:443 ssl:True [SSLCertVerificationError: (1, '[SSL: CERTIFICATE_VERIFY_FAILED] certificate verify failed: unable to get local issuer certificate (_ssl.c:1006)')]

2025-02-27 15:53:32,216 - exchange.bybit_client - ERROR - API 요청 실패: Cannot connect to host api-testnet.bybit.com:443 ssl:True [SSLCertVerificationError: (1, '[SSL: CERTIFICATE_VERIFY_FAILED] certificate verify failed: unable to get local issuer certificate (_ssl.c:1006)')]
2025-02-27 15:53:32,218 - exchange.bybit_client - ERROR - Traceback (most recent call last):
  File "C:\Users\oasis\Aibybit_2\.venv\Lib\site-packages\aiohttp\connector.py", line 1123, in _wrap_create_connection
    connection = await self._loop.create_connection(
                 ^^^^^^^^^^^^^^^^^^^^^^^^^^^^^^^^^^^
  File "C:\Program Files\Python311\Lib\asyncio\base_events.py", line 1112, in create_connection
    transport, protocol = await self._create_connection_transport(
                          ^^^^^^^^^^^^^^^^^^^^^^^^^^^^^^^^^^^^^^^^
  File "C:\Program Files\Python311\Lib\asyncio\base_events.py", line 1145, in _create_connection_transport
    await waiter
  File "C:\Program Files\Python311\Lib\asyncio\sslproto.py", line 575, in _on_handshake_complete
    raise handshake_exc
  File "C:\Program Files\Python311\Lib\asyncio\sslproto.py", line 557, in _do_handshake
    self._sslobj.do_handshake()
  File "C:\Program Files\Python311\Lib\ssl.py", line 979, in do_handshake
    self._sslobj.do_handshake()
ssl.SSLCertVerificationError: [SSL: CERTIFICATE_VERIFY_FAILED] certificate verify failed: unable to get local issuer certificate (_ssl.c:1006)

The above exception was the direct cause of the following exception:

Traceback (most recent call last):
  File "C:\Users\oasis\Aibybit_2\src\exchange\bybit_client.py", line 108, in _request
    async with session.get(url, params=request_params, headers=headers) as response:
  File "C:\Users\oasis\Aibybit_2\.venv\Lib\site-packages\aiohttp\client.py", line 1425, in __aenter__
    self._resp: _RetType = await self._coro
                           ^^^^^^^^^^^^^^^^
  File "C:\Users\oasis\Aibybit_2\.venv\Lib\site-packages\aiohttp\client.py", line 703, in _request
    conn = await self._connector.connect(
           ^^^^^^^^^^^^^^^^^^^^^^^^^^^^^^
  File "C:\Users\oasis\Aibybit_2\.venv\Lib\site-packages\aiohttp\connector.py", line 548, in connect
    proto = await self._create_connection(req, traces, timeout)
            ^^^^^^^^^^^^^^^^^^^^^^^^^^^^^^^^^^^^^^^^^^^^^^^^^^^
  File "C:\Users\oasis\Aibybit_2\.venv\Lib\site-packages\aiohttp\connector.py", line 1056, in _create_connection
    _, proto = await self._create_direct_connection(req, traces, timeout)
               ^^^^^^^^^^^^^^^^^^^^^^^^^^^^^^^^^^^^^^^^^^^^^^^^^^^^^^^^^^
  File "C:\Users\oasis\Aibybit_2\.venv\Lib\site-packages\aiohttp\connector.py", line 1411, in _create_direct_connection
    raise last_exc
  File "C:\Users\oasis\Aibybit_2\.venv\Lib\site-packages\aiohttp\connector.py", line 1380, in _create_direct_connection
    transp, proto = await self._wrap_create_connection(
                    ^^^^^^^^^^^^^^^^^^^^^^^^^^^^^^^^^^^
  File "C:\Users\oasis\Aibybit_2\.venv\Lib\site-packages\aiohttp\connector.py", line 1129, in _wrap_create_connection
    raise ClientConnectorCertificateError(req.connection_key, exc) from exc
aiohttp.client_exceptions.ClientConnectorCertificateError: Cannot connect to host api-testnet.bybit.com:443 ssl:True [SSLCertVerificationError: (1, '[SSL: CERTIFICATE_VERIFY_FAILED] certificate verify failed: unable to get local issuer certificate (_ssl.c:1006)')]

2025-02-27 15:53:33,300 - exchange.bybit_client - ERROR - API 요청 실패: Cannot connect to host api-testnet.bybit.com:443 ssl:True [SSLCertVerificationError: (1, '[SSL: CERTIFICATE_VERIFY_FAILED] certificate verify failed: unable to get local issuer certificate (_ssl.c:1006)')]
2025-02-27 15:53:33,301 - exchange.bybit_client - ERROR - Traceback (most recent call last):
  File "C:\Users\oasis\Aibybit_2\.venv\Lib\site-packages\aiohttp\connector.py", line 1123, in _wrap_create_connection
    connection = await self._loop.create_connection(
                 ^^^^^^^^^^^^^^^^^^^^^^^^^^^^^^^^^^^
  File "C:\Program Files\Python311\Lib\asyncio\base_events.py", line 1112, in create_connection
    transport, protocol = await self._create_connection_transport(
                          ^^^^^^^^^^^^^^^^^^^^^^^^^^^^^^^^^^^^^^^^
  File "C:\Program Files\Python311\Lib\asyncio\base_events.py", line 1145, in _create_connection_transport
    await waiter
  File "C:\Program Files\Python311\Lib\asyncio\sslproto.py", line 575, in _on_handshake_complete
    raise handshake_exc
  File "C:\Program Files\Python311\Lib\asyncio\sslproto.py", line 557, in _do_handshake
    self._sslobj.do_handshake()
  File "C:\Program Files\Python311\Lib\ssl.py", line 979, in do_handshake
    self._sslobj.do_handshake()
ssl.SSLCertVerificationError: [SSL: CERTIFICATE_VERIFY_FAILED] certificate verify failed: unable to get local issuer certificate (_ssl.c:1006)

The above exception was the direct cause of the following exception:

Traceback (most recent call last):
  File "C:\Users\oasis\Aibybit_2\src\exchange\bybit_client.py", line 108, in _request
    async with session.get(url, params=request_params, headers=headers) as response:
  File "C:\Users\oasis\Aibybit_2\.venv\Lib\site-packages\aiohttp\client.py", line 1425, in __aenter__
    self._resp: _RetType = await self._coro
                           ^^^^^^^^^^^^^^^^
  File "C:\Users\oasis\Aibybit_2\.venv\Lib\site-packages\aiohttp\client.py", line 703, in _request
    conn = await self._connector.connect(
           ^^^^^^^^^^^^^^^^^^^^^^^^^^^^^^
  File "C:\Users\oasis\Aibybit_2\.venv\Lib\site-packages\aiohttp\connector.py", line 548, in connect
    proto = await self._create_connection(req, traces, timeout)
            ^^^^^^^^^^^^^^^^^^^^^^^^^^^^^^^^^^^^^^^^^^^^^^^^^^^
  File "C:\Users\oasis\Aibybit_2\.venv\Lib\site-packages\aiohttp\connector.py", line 1056, in _create_connection
    _, proto = await self._create_direct_connection(req, traces, timeout)
               ^^^^^^^^^^^^^^^^^^^^^^^^^^^^^^^^^^^^^^^^^^^^^^^^^^^^^^^^^^
  File "C:\Users\oasis\Aibybit_2\.venv\Lib\site-packages\aiohttp\connector.py", line 1411, in _create_direct_connection
    raise last_exc
  File "C:\Users\oasis\Aibybit_2\.venv\Lib\site-packages\aiohttp\connector.py", line 1380, in _create_direct_connection
    transp, proto = await self._wrap_create_connection(
                    ^^^^^^^^^^^^^^^^^^^^^^^^^^^^^^^^^^^
  File "C:\Users\oasis\Aibybit_2\.venv\Lib\site-packages\aiohttp\connector.py", line 1129, in _wrap_create_connection
    raise ClientConnectorCertificateError(req.connection_key, exc) from exc
aiohttp.client_exceptions.ClientConnectorCertificateError: Cannot connect to host api-testnet.bybit.com:443 ssl:True [SSLCertVerificationError: (1, '[SSL: CERTIFICATE_VERIFY_FAILED] certificate verify failed: unable to get local issuer certificate (_ssl.c:1006)')]

2025-02-27 15:53:34,390 - exchange.bybit_client - ERROR - API 요청 실패: Cannot connect to host api-testnet.bybit.com:443 ssl:True [SSLCertVerificationError: (1, '[SSL: CERTIFICATE_VERIFY_FAILED] certificate verify failed: unable to get local issuer certificate (_ssl.c:1006)')]
2025-02-27 15:53:34,392 - exchange.bybit_client - ERROR - Traceback (most recent call last):
  File "C:\Users\oasis\Aibybit_2\.venv\Lib\site-packages\aiohttp\connector.py", line 1123, in _wrap_create_connection
    connection = await self._loop.create_connection(
                 ^^^^^^^^^^^^^^^^^^^^^^^^^^^^^^^^^^^
  File "C:\Program Files\Python311\Lib\asyncio\base_events.py", line 1112, in create_connection
    transport, protocol = await self._create_connection_transport(
                          ^^^^^^^^^^^^^^^^^^^^^^^^^^^^^^^^^^^^^^^^
  File "C:\Program Files\Python311\Lib\asyncio\base_events.py", line 1145, in _create_connection_transport
    await waiter
  File "C:\Program Files\Python311\Lib\asyncio\sslproto.py", line 575, in _on_handshake_complete
    raise handshake_exc
  File "C:\Program Files\Python311\Lib\asyncio\sslproto.py", line 557, in _do_handshake
    self._sslobj.do_handshake()
  File "C:\Program Files\Python311\Lib\ssl.py", line 979, in do_handshake
    self._sslobj.do_handshake()
ssl.SSLCertVerificationError: [SSL: CERTIFICATE_VERIFY_FAILED] certificate verify failed: unable to get local issuer certificate (_ssl.c:1006)

The above exception was the direct cause of the following exception:

Traceback (most recent call last):
  File "C:\Users\oasis\Aibybit_2\src\exchange\bybit_client.py", line 108, in _request
    async with session.get(url, params=request_params, headers=headers) as response:
  File "C:\Users\oasis\Aibybit_2\.venv\Lib\site-packages\aiohttp\client.py", line 1425, in __aenter__
    self._resp: _RetType = await self._coro
                           ^^^^^^^^^^^^^^^^
  File "C:\Users\oasis\Aibybit_2\.venv\Lib\site-packages\aiohttp\client.py", line 703, in _request
    conn = await self._connector.connect(
           ^^^^^^^^^^^^^^^^^^^^^^^^^^^^^^
  File "C:\Users\oasis\Aibybit_2\.venv\Lib\site-packages\aiohttp\connector.py", line 548, in connect
    proto = await self._create_connection(req, traces, timeout)
            ^^^^^^^^^^^^^^^^^^^^^^^^^^^^^^^^^^^^^^^^^^^^^^^^^^^
  File "C:\Users\oasis\Aibybit_2\.venv\Lib\site-packages\aiohttp\connector.py", line 1056, in _create_connection
    _, proto = await self._create_direct_connection(req, traces, timeout)
               ^^^^^^^^^^^^^^^^^^^^^^^^^^^^^^^^^^^^^^^^^^^^^^^^^^^^^^^^^^
  File "C:\Users\oasis\Aibybit_2\.venv\Lib\site-packages\aiohttp\connector.py", line 1411, in _create_direct_connection
    raise last_exc
  File "C:\Users\oasis\Aibybit_2\.venv\Lib\site-packages\aiohttp\connector.py", line 1380, in _create_direct_connection
    transp, proto = await self._wrap_create_connection(
                    ^^^^^^^^^^^^^^^^^^^^^^^^^^^^^^^^^^^
  File "C:\Users\oasis\Aibybit_2\.venv\Lib\site-packages\aiohttp\connector.py", line 1129, in _wrap_create_connection
    raise ClientConnectorCertificateError(req.connection_key, exc) from exc
aiohttp.client_exceptions.ClientConnectorCertificateError: Cannot connect to host api-testnet.bybit.com:443 ssl:True [SSLCertVerificationError: (1, '[SSL: CERTIFICATE_VERIFY_FAILED] certificate verify failed: unable to get local issuer certificate (_ssl.c:1006)')]

2025-02-27 15:53:35,492 - exchange.bybit_client - ERROR - API 요청 실패: Cannot connect to host api-testnet.bybit.com:443 ssl:True [SSLCertVerificationError: (1, '[SSL: CERTIFICATE_VERIFY_FAILED] certificate verify failed: unable to get local issuer certificate (_ssl.c:1006)')]
2025-02-27 15:53:35,493 - exchange.bybit_client - ERROR - Traceback (most recent call last):
  File "C:\Users\oasis\Aibybit_2\.venv\Lib\site-packages\aiohttp\connector.py", line 1123, in _wrap_create_connection
    connection = await self._loop.create_connection(
                 ^^^^^^^^^^^^^^^^^^^^^^^^^^^^^^^^^^^
  File "C:\Program Files\Python311\Lib\asyncio\base_events.py", line 1112, in create_connection
    transport, protocol = await self._create_connection_transport(
                          ^^^^^^^^^^^^^^^^^^^^^^^^^^^^^^^^^^^^^^^^
  File "C:\Program Files\Python311\Lib\asyncio\base_events.py", line 1145, in _create_connection_transport
    await waiter
  File "C:\Program Files\Python311\Lib\asyncio\sslproto.py", line 575, in _on_handshake_complete
    raise handshake_exc
  File "C:\Program Files\Python311\Lib\asyncio\sslproto.py", line 557, in _do_handshake
    self._sslobj.do_handshake()
  File "C:\Program Files\Python311\Lib\ssl.py", line 979, in do_handshake
    self._sslobj.do_handshake()
ssl.SSLCertVerificationError: [SSL: CERTIFICATE_VERIFY_FAILED] certificate verify failed: unable to get local issuer certificate (_ssl.c:1006)

The above exception was the direct cause of the following exception:

Traceback (most recent call last):
  File "C:\Users\oasis\Aibybit_2\src\exchange\bybit_client.py", line 108, in _request
    async with session.get(url, params=request_params, headers=headers) as response:
  File "C:\Users\oasis\Aibybit_2\.venv\Lib\site-packages\aiohttp\client.py", line 1425, in __aenter__
    self._resp: _RetType = await self._coro
                           ^^^^^^^^^^^^^^^^
  File "C:\Users\oasis\Aibybit_2\.venv\Lib\site-packages\aiohttp\client.py", line 703, in _request
    conn = await self._connector.connect(
           ^^^^^^^^^^^^^^^^^^^^^^^^^^^^^^
  File "C:\Users\oasis\Aibybit_2\.venv\Lib\site-packages\aiohttp\connector.py", line 548, in connect
    proto = await self._create_connection(req, traces, timeout)
            ^^^^^^^^^^^^^^^^^^^^^^^^^^^^^^^^^^^^^^^^^^^^^^^^^^^
  File "C:\Users\oasis\Aibybit_2\.venv\Lib\site-packages\aiohttp\connector.py", line 1056, in _create_connection
    _, proto = await self._create_direct_connection(req, traces, timeout)
               ^^^^^^^^^^^^^^^^^^^^^^^^^^^^^^^^^^^^^^^^^^^^^^^^^^^^^^^^^^
  File "C:\Users\oasis\Aibybit_2\.venv\Lib\site-packages\aiohttp\connector.py", line 1411, in _create_direct_connection
    raise last_exc
  File "C:\Users\oasis\Aibybit_2\.venv\Lib\site-packages\aiohttp\connector.py", line 1380, in _create_direct_connection
    transp, proto = await self._wrap_create_connection(
                    ^^^^^^^^^^^^^^^^^^^^^^^^^^^^^^^^^^^
  File "C:\Users\oasis\Aibybit_2\.venv\Lib\site-packages\aiohttp\connector.py", line 1129, in _wrap_create_connection
    raise ClientConnectorCertificateError(req.connection_key, exc) from exc
aiohttp.client_exceptions.ClientConnectorCertificateError: Cannot connect to host api-testnet.bybit.com:443 ssl:True [SSLCertVerificationError: (1, '[SSL: CERTIFICATE_VERIFY_FAILED] certificate verify failed: unable to get local issuer certificate (_ssl.c:1006)')]

2025-02-27 15:53:36,651 - exchange.bybit_client - ERROR - API 요청 실패: Cannot connect to host api-testnet.bybit.com:443 ssl:True [SSLCertVerificationError: (1, '[SSL: CERTIFICATE_VERIFY_FAILED] certificate verify failed: unable to get local issuer certificate (_ssl.c:1006)')]
2025-02-27 15:53:36,653 - exchange.bybit_client - ERROR - Traceback (most recent call last):
  File "C:\Users\oasis\Aibybit_2\.venv\Lib\site-packages\aiohttp\connector.py", line 1123, in _wrap_create_connection
    connection = await self._loop.create_connection(
                 ^^^^^^^^^^^^^^^^^^^^^^^^^^^^^^^^^^^
  File "C:\Program Files\Python311\Lib\asyncio\base_events.py", line 1112, in create_connection
    transport, protocol = await self._create_connection_transport(
                          ^^^^^^^^^^^^^^^^^^^^^^^^^^^^^^^^^^^^^^^^
  File "C:\Program Files\Python311\Lib\asyncio\base_events.py", line 1145, in _create_connection_transport
    await waiter
  File "C:\Program Files\Python311\Lib\asyncio\sslproto.py", line 575, in _on_handshake_complete
    raise handshake_exc
  File "C:\Program Files\Python311\Lib\asyncio\sslproto.py", line 557, in _do_handshake
    self._sslobj.do_handshake()
  File "C:\Program Files\Python311\Lib\ssl.py", line 979, in do_handshake
    self._sslobj.do_handshake()
ssl.SSLCertVerificationError: [SSL: CERTIFICATE_VERIFY_FAILED] certificate verify failed: unable to get local issuer certificate (_ssl.c:1006)

The above exception was the direct cause of the following exception:

Traceback (most recent call last):
  File "C:\Users\oasis\Aibybit_2\src\exchange\bybit_client.py", line 108, in _request
    async with session.get(url, params=request_params, headers=headers) as response:
  File "C:\Users\oasis\Aibybit_2\.venv\Lib\site-packages\aiohttp\client.py", line 1425, in __aenter__
    self._resp: _RetType = await self._coro
                           ^^^^^^^^^^^^^^^^
  File "C:\Users\oasis\Aibybit_2\.venv\Lib\site-packages\aiohttp\client.py", line 703, in _request
    conn = await self._connector.connect(
           ^^^^^^^^^^^^^^^^^^^^^^^^^^^^^^
  File "C:\Users\oasis\Aibybit_2\.venv\Lib\site-packages\aiohttp\connector.py", line 548, in connect
    proto = await self._create_connection(req, traces, timeout)
            ^^^^^^^^^^^^^^^^^^^^^^^^^^^^^^^^^^^^^^^^^^^^^^^^^^^
  File "C:\Users\oasis\Aibybit_2\.venv\Lib\site-packages\aiohttp\connector.py", line 1056, in _create_connection
    _, proto = await self._create_direct_connection(req, traces, timeout)
               ^^^^^^^^^^^^^^^^^^^^^^^^^^^^^^^^^^^^^^^^^^^^^^^^^^^^^^^^^^
  File "C:\Users\oasis\Aibybit_2\.venv\Lib\site-packages\aiohttp\connector.py", line 1411, in _create_direct_connection
    raise last_exc
  File "C:\Users\oasis\Aibybit_2\.venv\Lib\site-packages\aiohttp\connector.py", line 1380, in _create_direct_connection
    transp, proto = await self._wrap_create_connection(
                    ^^^^^^^^^^^^^^^^^^^^^^^^^^^^^^^^^^^
  File "C:\Users\oasis\Aibybit_2\.venv\Lib\site-packages\aiohttp\connector.py", line 1129, in _wrap_create_connection
    raise ClientConnectorCertificateError(req.connection_key, exc) from exc
aiohttp.client_exceptions.ClientConnectorCertificateError: Cannot connect to host api-testnet.bybit.com:443 ssl:True [SSLCertVerificationError: (1, '[SSL: CERTIFICATE_VERIFY_FAILED] certificate verify failed: unable to get local issuer certificate (_ssl.c:1006)')]

2025-02-27 16:00:40,693 - exchange.bybit_client - ERROR - API 요청 실패: Cannot connect to host api-testnet.bybit.com:443 ssl:True [SSLCertVerificationError: (1, '[SSL: CERTIFICATE_VERIFY_FAILED] certificate verify failed: unable to get local issuer certificate (_ssl.c:1006)')]
2025-02-27 16:00:40,701 - exchange.bybit_client - ERROR - Traceback (most recent call last):
  File "C:\Users\oasis\Aibybit_2\.venv\Lib\site-packages\aiohttp\connector.py", line 1123, in _wrap_create_connection
    connection = await self._loop.create_connection(
                 ^^^^^^^^^^^^^^^^^^^^^^^^^^^^^^^^^^^
  File "C:\Program Files\Python311\Lib\asyncio\base_events.py", line 1112, in create_connection
    transport, protocol = await self._create_connection_transport(
                          ^^^^^^^^^^^^^^^^^^^^^^^^^^^^^^^^^^^^^^^^
  File "C:\Program Files\Python311\Lib\asyncio\base_events.py", line 1145, in _create_connection_transport
    await waiter
  File "C:\Program Files\Python311\Lib\asyncio\sslproto.py", line 575, in _on_handshake_complete
    raise handshake_exc
  File "C:\Program Files\Python311\Lib\asyncio\sslproto.py", line 557, in _do_handshake
    self._sslobj.do_handshake()
  File "C:\Program Files\Python311\Lib\ssl.py", line 979, in do_handshake
    self._sslobj.do_handshake()
ssl.SSLCertVerificationError: [SSL: CERTIFICATE_VERIFY_FAILED] certificate verify failed: unable to get local issuer certificate (_ssl.c:1006)

The above exception was the direct cause of the following exception:

Traceback (most recent call last):
  File "C:\Users\oasis\Aibybit_2\src\exchange\bybit_client.py", line 108, in _request
    async with session.get(url, params=request_params, headers=headers) as response:
  File "C:\Users\oasis\Aibybit_2\.venv\Lib\site-packages\aiohttp\client.py", line 1425, in __aenter__
    self._resp: _RetType = await self._coro
                           ^^^^^^^^^^^^^^^^
  File "C:\Users\oasis\Aibybit_2\.venv\Lib\site-packages\aiohttp\client.py", line 703, in _request
    conn = await self._connector.connect(
           ^^^^^^^^^^^^^^^^^^^^^^^^^^^^^^
  File "C:\Users\oasis\Aibybit_2\.venv\Lib\site-packages\aiohttp\connector.py", line 548, in connect
    proto = await self._create_connection(req, traces, timeout)
            ^^^^^^^^^^^^^^^^^^^^^^^^^^^^^^^^^^^^^^^^^^^^^^^^^^^
  File "C:\Users\oasis\Aibybit_2\.venv\Lib\site-packages\aiohttp\connector.py", line 1056, in _create_connection
    _, proto = await self._create_direct_connection(req, traces, timeout)
               ^^^^^^^^^^^^^^^^^^^^^^^^^^^^^^^^^^^^^^^^^^^^^^^^^^^^^^^^^^
  File "C:\Users\oasis\Aibybit_2\.venv\Lib\site-packages\aiohttp\connector.py", line 1411, in _create_direct_connection
    raise last_exc
  File "C:\Users\oasis\Aibybit_2\.venv\Lib\site-packages\aiohttp\connector.py", line 1380, in _create_direct_connection
    transp, proto = await self._wrap_create_connection(
                    ^^^^^^^^^^^^^^^^^^^^^^^^^^^^^^^^^^^
  File "C:\Users\oasis\Aibybit_2\.venv\Lib\site-packages\aiohttp\connector.py", line 1129, in _wrap_create_connection
    raise ClientConnectorCertificateError(req.connection_key, exc) from exc
aiohttp.client_exceptions.ClientConnectorCertificateError: Cannot connect to host api-testnet.bybit.com:443 ssl:True [SSLCertVerificationError: (1, '[SSL: CERTIFICATE_VERIFY_FAILED] certificate verify failed: unable to get local issuer certificate (_ssl.c:1006)')]

2025-02-27 16:00:41,799 - exchange.bybit_client - ERROR - API 요청 실패: Cannot connect to host api-testnet.bybit.com:443 ssl:True [SSLCertVerificationError: (1, '[SSL: CERTIFICATE_VERIFY_FAILED] certificate verify failed: unable to get local issuer certificate (_ssl.c:1006)')]
2025-02-27 16:00:41,801 - exchange.bybit_client - ERROR - Traceback (most recent call last):
  File "C:\Users\oasis\Aibybit_2\.venv\Lib\site-packages\aiohttp\connector.py", line 1123, in _wrap_create_connection
    connection = await self._loop.create_connection(
                 ^^^^^^^^^^^^^^^^^^^^^^^^^^^^^^^^^^^
  File "C:\Program Files\Python311\Lib\asyncio\base_events.py", line 1112, in create_connection
    transport, protocol = await self._create_connection_transport(
                          ^^^^^^^^^^^^^^^^^^^^^^^^^^^^^^^^^^^^^^^^
  File "C:\Program Files\Python311\Lib\asyncio\base_events.py", line 1145, in _create_connection_transport
    await waiter
  File "C:\Program Files\Python311\Lib\asyncio\sslproto.py", line 575, in _on_handshake_complete
    raise handshake_exc
  File "C:\Program Files\Python311\Lib\asyncio\sslproto.py", line 557, in _do_handshake
    self._sslobj.do_handshake()
  File "C:\Program Files\Python311\Lib\ssl.py", line 979, in do_handshake
    self._sslobj.do_handshake()
ssl.SSLCertVerificationError: [SSL: CERTIFICATE_VERIFY_FAILED] certificate verify failed: unable to get local issuer certificate (_ssl.c:1006)

The above exception was the direct cause of the following exception:

Traceback (most recent call last):
  File "C:\Users\oasis\Aibybit_2\src\exchange\bybit_client.py", line 108, in _request
    async with session.get(url, params=request_params, headers=headers) as response:
  File "C:\Users\oasis\Aibybit_2\.venv\Lib\site-packages\aiohttp\client.py", line 1425, in __aenter__
    self._resp: _RetType = await self._coro
                           ^^^^^^^^^^^^^^^^
  File "C:\Users\oasis\Aibybit_2\.venv\Lib\site-packages\aiohttp\client.py", line 703, in _request
    conn = await self._connector.connect(
           ^^^^^^^^^^^^^^^^^^^^^^^^^^^^^^
  File "C:\Users\oasis\Aibybit_2\.venv\Lib\site-packages\aiohttp\connector.py", line 548, in connect
    proto = await self._create_connection(req, traces, timeout)
            ^^^^^^^^^^^^^^^^^^^^^^^^^^^^^^^^^^^^^^^^^^^^^^^^^^^
  File "C:\Users\oasis\Aibybit_2\.venv\Lib\site-packages\aiohttp\connector.py", line 1056, in _create_connection
    _, proto = await self._create_direct_connection(req, traces, timeout)
               ^^^^^^^^^^^^^^^^^^^^^^^^^^^^^^^^^^^^^^^^^^^^^^^^^^^^^^^^^^
  File "C:\Users\oasis\Aibybit_2\.venv\Lib\site-packages\aiohttp\connector.py", line 1411, in _create_direct_connection
    raise last_exc
  File "C:\Users\oasis\Aibybit_2\.venv\Lib\site-packages\aiohttp\connector.py", line 1380, in _create_direct_connection
    transp, proto = await self._wrap_create_connection(
                    ^^^^^^^^^^^^^^^^^^^^^^^^^^^^^^^^^^^
  File "C:\Users\oasis\Aibybit_2\.venv\Lib\site-packages\aiohttp\connector.py", line 1129, in _wrap_create_connection
    raise ClientConnectorCertificateError(req.connection_key, exc) from exc
aiohttp.client_exceptions.ClientConnectorCertificateError: Cannot connect to host api-testnet.bybit.com:443 ssl:True [SSLCertVerificationError: (1, '[SSL: CERTIFICATE_VERIFY_FAILED] certificate verify failed: unable to get local issuer certificate (_ssl.c:1006)')]

2025-02-27 16:00:42,898 - exchange.bybit_client - ERROR - API 요청 실패: Cannot connect to host api-testnet.bybit.com:443 ssl:True [SSLCertVerificationError: (1, '[SSL: CERTIFICATE_VERIFY_FAILED] certificate verify failed: unable to get local issuer certificate (_ssl.c:1006)')]
2025-02-27 16:00:42,901 - exchange.bybit_client - ERROR - Traceback (most recent call last):
  File "C:\Users\oasis\Aibybit_2\.venv\Lib\site-packages\aiohttp\connector.py", line 1123, in _wrap_create_connection
    connection = await self._loop.create_connection(
                 ^^^^^^^^^^^^^^^^^^^^^^^^^^^^^^^^^^^
  File "C:\Program Files\Python311\Lib\asyncio\base_events.py", line 1112, in create_connection
    transport, protocol = await self._create_connection_transport(
                          ^^^^^^^^^^^^^^^^^^^^^^^^^^^^^^^^^^^^^^^^
  File "C:\Program Files\Python311\Lib\asyncio\base_events.py", line 1145, in _create_connection_transport
    await waiter
  File "C:\Program Files\Python311\Lib\asyncio\sslproto.py", line 575, in _on_handshake_complete
    raise handshake_exc
  File "C:\Program Files\Python311\Lib\asyncio\sslproto.py", line 557, in _do_handshake
    self._sslobj.do_handshake()
  File "C:\Program Files\Python311\Lib\ssl.py", line 979, in do_handshake
    self._sslobj.do_handshake()
ssl.SSLCertVerificationError: [SSL: CERTIFICATE_VERIFY_FAILED] certificate verify failed: unable to get local issuer certificate (_ssl.c:1006)

The above exception was the direct cause of the following exception:

Traceback (most recent call last):
  File "C:\Users\oasis\Aibybit_2\src\exchange\bybit_client.py", line 108, in _request
    async with session.get(url, params=request_params, headers=headers) as response:
  File "C:\Users\oasis\Aibybit_2\.venv\Lib\site-packages\aiohttp\client.py", line 1425, in __aenter__
    self._resp: _RetType = await self._coro
                           ^^^^^^^^^^^^^^^^
  File "C:\Users\oasis\Aibybit_2\.venv\Lib\site-packages\aiohttp\client.py", line 703, in _request
    conn = await self._connector.connect(
           ^^^^^^^^^^^^^^^^^^^^^^^^^^^^^^
  File "C:\Users\oasis\Aibybit_2\.venv\Lib\site-packages\aiohttp\connector.py", line 548, in connect
    proto = await self._create_connection(req, traces, timeout)
            ^^^^^^^^^^^^^^^^^^^^^^^^^^^^^^^^^^^^^^^^^^^^^^^^^^^
  File "C:\Users\oasis\Aibybit_2\.venv\Lib\site-packages\aiohttp\connector.py", line 1056, in _create_connection
    _, proto = await self._create_direct_connection(req, traces, timeout)
               ^^^^^^^^^^^^^^^^^^^^^^^^^^^^^^^^^^^^^^^^^^^^^^^^^^^^^^^^^^
  File "C:\Users\oasis\Aibybit_2\.venv\Lib\site-packages\aiohttp\connector.py", line 1411, in _create_direct_connection
    raise last_exc
  File "C:\Users\oasis\Aibybit_2\.venv\Lib\site-packages\aiohttp\connector.py", line 1380, in _create_direct_connection
    transp, proto = await self._wrap_create_connection(
                    ^^^^^^^^^^^^^^^^^^^^^^^^^^^^^^^^^^^
  File "C:\Users\oasis\Aibybit_2\.venv\Lib\site-packages\aiohttp\connector.py", line 1129, in _wrap_create_connection
    raise ClientConnectorCertificateError(req.connection_key, exc) from exc
aiohttp.client_exceptions.ClientConnectorCertificateError: Cannot connect to host api-testnet.bybit.com:443 ssl:True [SSLCertVerificationError: (1, '[SSL: CERTIFICATE_VERIFY_FAILED] certificate verify failed: unable to get local issuer certificate (_ssl.c:1006)')]

2025-02-27 16:00:44,023 - exchange.bybit_client - ERROR - API 요청 실패: Cannot connect to host api-testnet.bybit.com:443 ssl:True [SSLCertVerificationError: (1, '[SSL: CERTIFICATE_VERIFY_FAILED] certificate verify failed: unable to get local issuer certificate (_ssl.c:1006)')]
2025-02-27 16:00:44,026 - exchange.bybit_client - ERROR - Traceback (most recent call last):
  File "C:\Users\oasis\Aibybit_2\.venv\Lib\site-packages\aiohttp\connector.py", line 1123, in _wrap_create_connection
    connection = await self._loop.create_connection(
                 ^^^^^^^^^^^^^^^^^^^^^^^^^^^^^^^^^^^
  File "C:\Program Files\Python311\Lib\asyncio\base_events.py", line 1112, in create_connection
    transport, protocol = await self._create_connection_transport(
                          ^^^^^^^^^^^^^^^^^^^^^^^^^^^^^^^^^^^^^^^^
  File "C:\Program Files\Python311\Lib\asyncio\base_events.py", line 1145, in _create_connection_transport
    await waiter
  File "C:\Program Files\Python311\Lib\asyncio\sslproto.py", line 575, in _on_handshake_complete
    raise handshake_exc
  File "C:\Program Files\Python311\Lib\asyncio\sslproto.py", line 557, in _do_handshake
    self._sslobj.do_handshake()
  File "C:\Program Files\Python311\Lib\ssl.py", line 979, in do_handshake
    self._sslobj.do_handshake()
ssl.SSLCertVerificationError: [SSL: CERTIFICATE_VERIFY_FAILED] certificate verify failed: unable to get local issuer certificate (_ssl.c:1006)

The above exception was the direct cause of the following exception:

Traceback (most recent call last):
  File "C:\Users\oasis\Aibybit_2\src\exchange\bybit_client.py", line 108, in _request
    async with session.get(url, params=request_params, headers=headers) as response:
  File "C:\Users\oasis\Aibybit_2\.venv\Lib\site-packages\aiohttp\client.py", line 1425, in __aenter__
    self._resp: _RetType = await self._coro
                           ^^^^^^^^^^^^^^^^
  File "C:\Users\oasis\Aibybit_2\.venv\Lib\site-packages\aiohttp\client.py", line 703, in _request
    conn = await self._connector.connect(
           ^^^^^^^^^^^^^^^^^^^^^^^^^^^^^^
  File "C:\Users\oasis\Aibybit_2\.venv\Lib\site-packages\aiohttp\connector.py", line 548, in connect
    proto = await self._create_connection(req, traces, timeout)
            ^^^^^^^^^^^^^^^^^^^^^^^^^^^^^^^^^^^^^^^^^^^^^^^^^^^
  File "C:\Users\oasis\Aibybit_2\.venv\Lib\site-packages\aiohttp\connector.py", line 1056, in _create_connection
    _, proto = await self._create_direct_connection(req, traces, timeout)
               ^^^^^^^^^^^^^^^^^^^^^^^^^^^^^^^^^^^^^^^^^^^^^^^^^^^^^^^^^^
  File "C:\Users\oasis\Aibybit_2\.venv\Lib\site-packages\aiohttp\connector.py", line 1411, in _create_direct_connection
    raise last_exc
  File "C:\Users\oasis\Aibybit_2\.venv\Lib\site-packages\aiohttp\connector.py", line 1380, in _create_direct_connection
    transp, proto = await self._wrap_create_connection(
                    ^^^^^^^^^^^^^^^^^^^^^^^^^^^^^^^^^^^
  File "C:\Users\oasis\Aibybit_2\.venv\Lib\site-packages\aiohttp\connector.py", line 1129, in _wrap_create_connection
    raise ClientConnectorCertificateError(req.connection_key, exc) from exc
aiohttp.client_exceptions.ClientConnectorCertificateError: Cannot connect to host api-testnet.bybit.com:443 ssl:True [SSLCertVerificationError: (1, '[SSL: CERTIFICATE_VERIFY_FAILED] certificate verify failed: unable to get local issuer certificate (_ssl.c:1006)')]

2025-02-27 16:00:45,170 - exchange.bybit_client - ERROR - API 요청 실패: Cannot connect to host api-testnet.bybit.com:443 ssl:True [SSLCertVerificationError: (1, '[SSL: CERTIFICATE_VERIFY_FAILED] certificate verify failed: unable to get local issuer certificate (_ssl.c:1006)')]
2025-02-27 16:00:45,174 - exchange.bybit_client - ERROR - Traceback (most recent call last):
  File "C:\Users\oasis\Aibybit_2\.venv\Lib\site-packages\aiohttp\connector.py", line 1123, in _wrap_create_connection
    connection = await self._loop.create_connection(
                 ^^^^^^^^^^^^^^^^^^^^^^^^^^^^^^^^^^^
  File "C:\Program Files\Python311\Lib\asyncio\base_events.py", line 1112, in create_connection
    transport, protocol = await self._create_connection_transport(
                          ^^^^^^^^^^^^^^^^^^^^^^^^^^^^^^^^^^^^^^^^
  File "C:\Program Files\Python311\Lib\asyncio\base_events.py", line 1145, in _create_connection_transport
    await waiter
  File "C:\Program Files\Python311\Lib\asyncio\sslproto.py", line 575, in _on_handshake_complete
    raise handshake_exc
  File "C:\Program Files\Python311\Lib\asyncio\sslproto.py", line 557, in _do_handshake
    self._sslobj.do_handshake()
  File "C:\Program Files\Python311\Lib\ssl.py", line 979, in do_handshake
    self._sslobj.do_handshake()
ssl.SSLCertVerificationError: [SSL: CERTIFICATE_VERIFY_FAILED] certificate verify failed: unable to get local issuer certificate (_ssl.c:1006)

The above exception was the direct cause of the following exception:

Traceback (most recent call last):
  File "C:\Users\oasis\Aibybit_2\src\exchange\bybit_client.py", line 108, in _request
    async with session.get(url, params=request_params, headers=headers) as response:
  File "C:\Users\oasis\Aibybit_2\.venv\Lib\site-packages\aiohttp\client.py", line 1425, in __aenter__
    self._resp: _RetType = await self._coro
                           ^^^^^^^^^^^^^^^^
  File "C:\Users\oasis\Aibybit_2\.venv\Lib\site-packages\aiohttp\client.py", line 703, in _request
    conn = await self._connector.connect(
           ^^^^^^^^^^^^^^^^^^^^^^^^^^^^^^
  File "C:\Users\oasis\Aibybit_2\.venv\Lib\site-packages\aiohttp\connector.py", line 548, in connect
    proto = await self._create_connection(req, traces, timeout)
            ^^^^^^^^^^^^^^^^^^^^^^^^^^^^^^^^^^^^^^^^^^^^^^^^^^^
  File "C:\Users\oasis\Aibybit_2\.venv\Lib\site-packages\aiohttp\connector.py", line 1056, in _create_connection
    _, proto = await self._create_direct_connection(req, traces, timeout)
               ^^^^^^^^^^^^^^^^^^^^^^^^^^^^^^^^^^^^^^^^^^^^^^^^^^^^^^^^^^
  File "C:\Users\oasis\Aibybit_2\.venv\Lib\site-packages\aiohttp\connector.py", line 1411, in _create_direct_connection
    raise last_exc
  File "C:\Users\oasis\Aibybit_2\.venv\Lib\site-packages\aiohttp\connector.py", line 1380, in _create_direct_connection
    transp, proto = await self._wrap_create_connection(
                    ^^^^^^^^^^^^^^^^^^^^^^^^^^^^^^^^^^^
  File "C:\Users\oasis\Aibybit_2\.venv\Lib\site-packages\aiohttp\connector.py", line 1129, in _wrap_create_connection
    raise ClientConnectorCertificateError(req.connection_key, exc) from exc
aiohttp.client_exceptions.ClientConnectorCertificateError: Cannot connect to host api-testnet.bybit.com:443 ssl:True [SSLCertVerificationError: (1, '[SSL: CERTIFICATE_VERIFY_FAILED] certificate verify failed: unable to get local issuer certificate (_ssl.c:1006)')]

2025-02-27 16:00:46,269 - exchange.bybit_client - ERROR - API 요청 실패: Cannot connect to host api-testnet.bybit.com:443 ssl:True [SSLCertVerificationError: (1, '[SSL: CERTIFICATE_VERIFY_FAILED] certificate verify failed: unable to get local issuer certificate (_ssl.c:1006)')]
2025-02-27 16:00:46,272 - exchange.bybit_client - ERROR - Traceback (most recent call last):
  File "C:\Users\oasis\Aibybit_2\.venv\Lib\site-packages\aiohttp\connector.py", line 1123, in _wrap_create_connection
    connection = await self._loop.create_connection(
                 ^^^^^^^^^^^^^^^^^^^^^^^^^^^^^^^^^^^
  File "C:\Program Files\Python311\Lib\asyncio\base_events.py", line 1112, in create_connection
    transport, protocol = await self._create_connection_transport(
                          ^^^^^^^^^^^^^^^^^^^^^^^^^^^^^^^^^^^^^^^^
  File "C:\Program Files\Python311\Lib\asyncio\base_events.py", line 1145, in _create_connection_transport
    await waiter
  File "C:\Program Files\Python311\Lib\asyncio\sslproto.py", line 575, in _on_handshake_complete
    raise handshake_exc
  File "C:\Program Files\Python311\Lib\asyncio\sslproto.py", line 557, in _do_handshake
    self._sslobj.do_handshake()
  File "C:\Program Files\Python311\Lib\ssl.py", line 979, in do_handshake
    self._sslobj.do_handshake()
ssl.SSLCertVerificationError: [SSL: CERTIFICATE_VERIFY_FAILED] certificate verify failed: unable to get local issuer certificate (_ssl.c:1006)

The above exception was the direct cause of the following exception:

Traceback (most recent call last):
  File "C:\Users\oasis\Aibybit_2\src\exchange\bybit_client.py", line 108, in _request
    async with session.get(url, params=request_params, headers=headers) as response:
  File "C:\Users\oasis\Aibybit_2\.venv\Lib\site-packages\aiohttp\client.py", line 1425, in __aenter__
    self._resp: _RetType = await self._coro
                           ^^^^^^^^^^^^^^^^
  File "C:\Users\oasis\Aibybit_2\.venv\Lib\site-packages\aiohttp\client.py", line 703, in _request
    conn = await self._connector.connect(
           ^^^^^^^^^^^^^^^^^^^^^^^^^^^^^^
  File "C:\Users\oasis\Aibybit_2\.venv\Lib\site-packages\aiohttp\connector.py", line 548, in connect
    proto = await self._create_connection(req, traces, timeout)
            ^^^^^^^^^^^^^^^^^^^^^^^^^^^^^^^^^^^^^^^^^^^^^^^^^^^
  File "C:\Users\oasis\Aibybit_2\.venv\Lib\site-packages\aiohttp\connector.py", line 1056, in _create_connection
    _, proto = await self._create_direct_connection(req, traces, timeout)
               ^^^^^^^^^^^^^^^^^^^^^^^^^^^^^^^^^^^^^^^^^^^^^^^^^^^^^^^^^^
  File "C:\Users\oasis\Aibybit_2\.venv\Lib\site-packages\aiohttp\connector.py", line 1411, in _create_direct_connection
    raise last_exc
  File "C:\Users\oasis\Aibybit_2\.venv\Lib\site-packages\aiohttp\connector.py", line 1380, in _create_direct_connection
    transp, proto = await self._wrap_create_connection(
                    ^^^^^^^^^^^^^^^^^^^^^^^^^^^^^^^^^^^
  File "C:\Users\oasis\Aibybit_2\.venv\Lib\site-packages\aiohttp\connector.py", line 1129, in _wrap_create_connection
    raise ClientConnectorCertificateError(req.connection_key, exc) from exc
aiohttp.client_exceptions.ClientConnectorCertificateError: Cannot connect to host api-testnet.bybit.com:443 ssl:True [SSLCertVerificationError: (1, '[SSL: CERTIFICATE_VERIFY_FAILED] certificate verify failed: unable to get local issuer certificate (_ssl.c:1006)')]

2025-02-27 16:00:47,369 - exchange.bybit_client - ERROR - API 요청 실패: Cannot connect to host api-testnet.bybit.com:443 ssl:True [SSLCertVerificationError: (1, '[SSL: CERTIFICATE_VERIFY_FAILED] certificate verify failed: unable to get local issuer certificate (_ssl.c:1006)')]
2025-02-27 16:00:47,370 - exchange.bybit_client - ERROR - Traceback (most recent call last):
  File "C:\Users\oasis\Aibybit_2\.venv\Lib\site-packages\aiohttp\connector.py", line 1123, in _wrap_create_connection
    connection = await self._loop.create_connection(
                 ^^^^^^^^^^^^^^^^^^^^^^^^^^^^^^^^^^^
  File "C:\Program Files\Python311\Lib\asyncio\base_events.py", line 1112, in create_connection
    transport, protocol = await self._create_connection_transport(
                          ^^^^^^^^^^^^^^^^^^^^^^^^^^^^^^^^^^^^^^^^
  File "C:\Program Files\Python311\Lib\asyncio\base_events.py", line 1145, in _create_connection_transport
    await waiter
  File "C:\Program Files\Python311\Lib\asyncio\sslproto.py", line 575, in _on_handshake_complete
    raise handshake_exc
  File "C:\Program Files\Python311\Lib\asyncio\sslproto.py", line 557, in _do_handshake
    self._sslobj.do_handshake()
  File "C:\Program Files\Python311\Lib\ssl.py", line 979, in do_handshake
    self._sslobj.do_handshake()
ssl.SSLCertVerificationError: [SSL: CERTIFICATE_VERIFY_FAILED] certificate verify failed: unable to get local issuer certificate (_ssl.c:1006)

The above exception was the direct cause of the following exception:

Traceback (most recent call last):
  File "C:\Users\oasis\Aibybit_2\src\exchange\bybit_client.py", line 108, in _request
    async with session.get(url, params=request_params, headers=headers) as response:
  File "C:\Users\oasis\Aibybit_2\.venv\Lib\site-packages\aiohttp\client.py", line 1425, in __aenter__
    self._resp: _RetType = await self._coro
                           ^^^^^^^^^^^^^^^^
  File "C:\Users\oasis\Aibybit_2\.venv\Lib\site-packages\aiohttp\client.py", line 703, in _request
    conn = await self._connector.connect(
           ^^^^^^^^^^^^^^^^^^^^^^^^^^^^^^
  File "C:\Users\oasis\Aibybit_2\.venv\Lib\site-packages\aiohttp\connector.py", line 548, in connect
    proto = await self._create_connection(req, traces, timeout)
            ^^^^^^^^^^^^^^^^^^^^^^^^^^^^^^^^^^^^^^^^^^^^^^^^^^^
  File "C:\Users\oasis\Aibybit_2\.venv\Lib\site-packages\aiohttp\connector.py", line 1056, in _create_connection
    _, proto = await self._create_direct_connection(req, traces, timeout)
               ^^^^^^^^^^^^^^^^^^^^^^^^^^^^^^^^^^^^^^^^^^^^^^^^^^^^^^^^^^
  File "C:\Users\oasis\Aibybit_2\.venv\Lib\site-packages\aiohttp\connector.py", line 1411, in _create_direct_connection
    raise last_exc
  File "C:\Users\oasis\Aibybit_2\.venv\Lib\site-packages\aiohttp\connector.py", line 1380, in _create_direct_connection
    transp, proto = await self._wrap_create_connection(
                    ^^^^^^^^^^^^^^^^^^^^^^^^^^^^^^^^^^^
  File "C:\Users\oasis\Aibybit_2\.venv\Lib\site-packages\aiohttp\connector.py", line 1129, in _wrap_create_connection
    raise ClientConnectorCertificateError(req.connection_key, exc) from exc
aiohttp.client_exceptions.ClientConnectorCertificateError: Cannot connect to host api-testnet.bybit.com:443 ssl:True [SSLCertVerificationError: (1, '[SSL: CERTIFICATE_VERIFY_FAILED] certificate verify failed: unable to get local issuer certificate (_ssl.c:1006)')]

2025-02-27 16:00:48,492 - exchange.bybit_client - ERROR - API 요청 실패: Cannot connect to host api-testnet.bybit.com:443 ssl:True [SSLCertVerificationError: (1, '[SSL: CERTIFICATE_VERIFY_FAILED] certificate verify failed: unable to get local issuer certificate (_ssl.c:1006)')]
2025-02-27 16:00:48,494 - exchange.bybit_client - ERROR - Traceback (most recent call last):
  File "C:\Users\oasis\Aibybit_2\.venv\Lib\site-packages\aiohttp\connector.py", line 1123, in _wrap_create_connection
    connection = await self._loop.create_connection(
                 ^^^^^^^^^^^^^^^^^^^^^^^^^^^^^^^^^^^
  File "C:\Program Files\Python311\Lib\asyncio\base_events.py", line 1112, in create_connection
    transport, protocol = await self._create_connection_transport(
                          ^^^^^^^^^^^^^^^^^^^^^^^^^^^^^^^^^^^^^^^^
  File "C:\Program Files\Python311\Lib\asyncio\base_events.py", line 1145, in _create_connection_transport
    await waiter
  File "C:\Program Files\Python311\Lib\asyncio\sslproto.py", line 575, in _on_handshake_complete
    raise handshake_exc
  File "C:\Program Files\Python311\Lib\asyncio\sslproto.py", line 557, in _do_handshake
    self._sslobj.do_handshake()
  File "C:\Program Files\Python311\Lib\ssl.py", line 979, in do_handshake
    self._sslobj.do_handshake()
ssl.SSLCertVerificationError: [SSL: CERTIFICATE_VERIFY_FAILED] certificate verify failed: unable to get local issuer certificate (_ssl.c:1006)

The above exception was the direct cause of the following exception:

Traceback (most recent call last):
  File "C:\Users\oasis\Aibybit_2\src\exchange\bybit_client.py", line 108, in _request
    async with session.get(url, params=request_params, headers=headers) as response:
  File "C:\Users\oasis\Aibybit_2\.venv\Lib\site-packages\aiohttp\client.py", line 1425, in __aenter__
    self._resp: _RetType = await self._coro
                           ^^^^^^^^^^^^^^^^
  File "C:\Users\oasis\Aibybit_2\.venv\Lib\site-packages\aiohttp\client.py", line 703, in _request
    conn = await self._connector.connect(
           ^^^^^^^^^^^^^^^^^^^^^^^^^^^^^^
  File "C:\Users\oasis\Aibybit_2\.venv\Lib\site-packages\aiohttp\connector.py", line 548, in connect
    proto = await self._create_connection(req, traces, timeout)
            ^^^^^^^^^^^^^^^^^^^^^^^^^^^^^^^^^^^^^^^^^^^^^^^^^^^
  File "C:\Users\oasis\Aibybit_2\.venv\Lib\site-packages\aiohttp\connector.py", line 1056, in _create_connection
    _, proto = await self._create_direct_connection(req, traces, timeout)
               ^^^^^^^^^^^^^^^^^^^^^^^^^^^^^^^^^^^^^^^^^^^^^^^^^^^^^^^^^^
  File "C:\Users\oasis\Aibybit_2\.venv\Lib\site-packages\aiohttp\connector.py", line 1411, in _create_direct_connection
    raise last_exc
  File "C:\Users\oasis\Aibybit_2\.venv\Lib\site-packages\aiohttp\connector.py", line 1380, in _create_direct_connection
    transp, proto = await self._wrap_create_connection(
                    ^^^^^^^^^^^^^^^^^^^^^^^^^^^^^^^^^^^
  File "C:\Users\oasis\Aibybit_2\.venv\Lib\site-packages\aiohttp\connector.py", line 1129, in _wrap_create_connection
    raise ClientConnectorCertificateError(req.connection_key, exc) from exc
aiohttp.client_exceptions.ClientConnectorCertificateError: Cannot connect to host api-testnet.bybit.com:443 ssl:True [SSLCertVerificationError: (1, '[SSL: CERTIFICATE_VERIFY_FAILED] certificate verify failed: unable to get local issuer certificate (_ssl.c:1006)')]

2025-02-27 16:00:49,650 - exchange.bybit_client - ERROR - API 요청 실패: Cannot connect to host api-testnet.bybit.com:443 ssl:True [SSLCertVerificationError: (1, '[SSL: CERTIFICATE_VERIFY_FAILED] certificate verify failed: unable to get local issuer certificate (_ssl.c:1006)')]
2025-02-27 16:00:49,652 - exchange.bybit_client - ERROR - Traceback (most recent call last):
  File "C:\Users\oasis\Aibybit_2\.venv\Lib\site-packages\aiohttp\connector.py", line 1123, in _wrap_create_connection
    connection = await self._loop.create_connection(
                 ^^^^^^^^^^^^^^^^^^^^^^^^^^^^^^^^^^^
  File "C:\Program Files\Python311\Lib\asyncio\base_events.py", line 1112, in create_connection
    transport, protocol = await self._create_connection_transport(
                          ^^^^^^^^^^^^^^^^^^^^^^^^^^^^^^^^^^^^^^^^
  File "C:\Program Files\Python311\Lib\asyncio\base_events.py", line 1145, in _create_connection_transport
    await waiter
  File "C:\Program Files\Python311\Lib\asyncio\sslproto.py", line 575, in _on_handshake_complete
    raise handshake_exc
  File "C:\Program Files\Python311\Lib\asyncio\sslproto.py", line 557, in _do_handshake
    self._sslobj.do_handshake()
  File "C:\Program Files\Python311\Lib\ssl.py", line 979, in do_handshake
    self._sslobj.do_handshake()
ssl.SSLCertVerificationError: [SSL: CERTIFICATE_VERIFY_FAILED] certificate verify failed: unable to get local issuer certificate (_ssl.c:1006)

The above exception was the direct cause of the following exception:

Traceback (most recent call last):
  File "C:\Users\oasis\Aibybit_2\src\exchange\bybit_client.py", line 108, in _request
    async with session.get(url, params=request_params, headers=headers) as response:
  File "C:\Users\oasis\Aibybit_2\.venv\Lib\site-packages\aiohttp\client.py", line 1425, in __aenter__
    self._resp: _RetType = await self._coro
                           ^^^^^^^^^^^^^^^^
  File "C:\Users\oasis\Aibybit_2\.venv\Lib\site-packages\aiohttp\client.py", line 703, in _request
    conn = await self._connector.connect(
           ^^^^^^^^^^^^^^^^^^^^^^^^^^^^^^
  File "C:\Users\oasis\Aibybit_2\.venv\Lib\site-packages\aiohttp\connector.py", line 548, in connect
    proto = await self._create_connection(req, traces, timeout)
            ^^^^^^^^^^^^^^^^^^^^^^^^^^^^^^^^^^^^^^^^^^^^^^^^^^^
  File "C:\Users\oasis\Aibybit_2\.venv\Lib\site-packages\aiohttp\connector.py", line 1056, in _create_connection
    _, proto = await self._create_direct_connection(req, traces, timeout)
               ^^^^^^^^^^^^^^^^^^^^^^^^^^^^^^^^^^^^^^^^^^^^^^^^^^^^^^^^^^
  File "C:\Users\oasis\Aibybit_2\.venv\Lib\site-packages\aiohttp\connector.py", line 1411, in _create_direct_connection
    raise last_exc
  File "C:\Users\oasis\Aibybit_2\.venv\Lib\site-packages\aiohttp\connector.py", line 1380, in _create_direct_connection
    transp, proto = await self._wrap_create_connection(
                    ^^^^^^^^^^^^^^^^^^^^^^^^^^^^^^^^^^^
  File "C:\Users\oasis\Aibybit_2\.venv\Lib\site-packages\aiohttp\connector.py", line 1129, in _wrap_create_connection
    raise ClientConnectorCertificateError(req.connection_key, exc) from exc
aiohttp.client_exceptions.ClientConnectorCertificateError: Cannot connect to host api-testnet.bybit.com:443 ssl:True [SSLCertVerificationError: (1, '[SSL: CERTIFICATE_VERIFY_FAILED] certificate verify failed: unable to get local issuer certificate (_ssl.c:1006)')]

2025-02-27 16:00:50,761 - exchange.bybit_client - ERROR - API 요청 실패: Cannot connect to host api-testnet.bybit.com:443 ssl:True [SSLCertVerificationError: (1, '[SSL: CERTIFICATE_VERIFY_FAILED] certificate verify failed: unable to get local issuer certificate (_ssl.c:1006)')]
2025-02-27 16:00:50,763 - exchange.bybit_client - ERROR - Traceback (most recent call last):
  File "C:\Users\oasis\Aibybit_2\.venv\Lib\site-packages\aiohttp\connector.py", line 1123, in _wrap_create_connection
    connection = await self._loop.create_connection(
                 ^^^^^^^^^^^^^^^^^^^^^^^^^^^^^^^^^^^
  File "C:\Program Files\Python311\Lib\asyncio\base_events.py", line 1112, in create_connection
    transport, protocol = await self._create_connection_transport(
                          ^^^^^^^^^^^^^^^^^^^^^^^^^^^^^^^^^^^^^^^^
  File "C:\Program Files\Python311\Lib\asyncio\base_events.py", line 1145, in _create_connection_transport
    await waiter
  File "C:\Program Files\Python311\Lib\asyncio\sslproto.py", line 575, in _on_handshake_complete
    raise handshake_exc
  File "C:\Program Files\Python311\Lib\asyncio\sslproto.py", line 557, in _do_handshake
    self._sslobj.do_handshake()
  File "C:\Program Files\Python311\Lib\ssl.py", line 979, in do_handshake
    self._sslobj.do_handshake()
ssl.SSLCertVerificationError: [SSL: CERTIFICATE_VERIFY_FAILED] certificate verify failed: unable to get local issuer certificate (_ssl.c:1006)

The above exception was the direct cause of the following exception:

Traceback (most recent call last):
  File "C:\Users\oasis\Aibybit_2\src\exchange\bybit_client.py", line 108, in _request
    async with session.get(url, params=request_params, headers=headers) as response:
  File "C:\Users\oasis\Aibybit_2\.venv\Lib\site-packages\aiohttp\client.py", line 1425, in __aenter__
    self._resp: _RetType = await self._coro
                           ^^^^^^^^^^^^^^^^
  File "C:\Users\oasis\Aibybit_2\.venv\Lib\site-packages\aiohttp\client.py", line 703, in _request
    conn = await self._connector.connect(
           ^^^^^^^^^^^^^^^^^^^^^^^^^^^^^^
  File "C:\Users\oasis\Aibybit_2\.venv\Lib\site-packages\aiohttp\connector.py", line 548, in connect
    proto = await self._create_connection(req, traces, timeout)
            ^^^^^^^^^^^^^^^^^^^^^^^^^^^^^^^^^^^^^^^^^^^^^^^^^^^
  File "C:\Users\oasis\Aibybit_2\.venv\Lib\site-packages\aiohttp\connector.py", line 1056, in _create_connection
    _, proto = await self._create_direct_connection(req, traces, timeout)
               ^^^^^^^^^^^^^^^^^^^^^^^^^^^^^^^^^^^^^^^^^^^^^^^^^^^^^^^^^^
  File "C:\Users\oasis\Aibybit_2\.venv\Lib\site-packages\aiohttp\connector.py", line 1411, in _create_direct_connection
    raise last_exc
  File "C:\Users\oasis\Aibybit_2\.venv\Lib\site-packages\aiohttp\connector.py", line 1380, in _create_direct_connection
    transp, proto = await self._wrap_create_connection(
                    ^^^^^^^^^^^^^^^^^^^^^^^^^^^^^^^^^^^
  File "C:\Users\oasis\Aibybit_2\.venv\Lib\site-packages\aiohttp\connector.py", line 1129, in _wrap_create_connection
    raise ClientConnectorCertificateError(req.connection_key, exc) from exc
aiohttp.client_exceptions.ClientConnectorCertificateError: Cannot connect to host api-testnet.bybit.com:443 ssl:True [SSLCertVerificationError: (1, '[SSL: CERTIFICATE_VERIFY_FAILED] certificate verify failed: unable to get local issuer certificate (_ssl.c:1006)')]

2025-02-27 16:00:51,851 - exchange.bybit_client - ERROR - API 요청 실패: Cannot connect to host api-testnet.bybit.com:443 ssl:True [SSLCertVerificationError: (1, '[SSL: CERTIFICATE_VERIFY_FAILED] certificate verify failed: unable to get local issuer certificate (_ssl.c:1006)')]
2025-02-27 16:00:51,853 - exchange.bybit_client - ERROR - Traceback (most recent call last):
  File "C:\Users\oasis\Aibybit_2\.venv\Lib\site-packages\aiohttp\connector.py", line 1123, in _wrap_create_connection
    connection = await self._loop.create_connection(
                 ^^^^^^^^^^^^^^^^^^^^^^^^^^^^^^^^^^^
  File "C:\Program Files\Python311\Lib\asyncio\base_events.py", line 1112, in create_connection
    transport, protocol = await self._create_connection_transport(
                          ^^^^^^^^^^^^^^^^^^^^^^^^^^^^^^^^^^^^^^^^
  File "C:\Program Files\Python311\Lib\asyncio\base_events.py", line 1145, in _create_connection_transport
    await waiter
  File "C:\Program Files\Python311\Lib\asyncio\sslproto.py", line 575, in _on_handshake_complete
    raise handshake_exc
  File "C:\Program Files\Python311\Lib\asyncio\sslproto.py", line 557, in _do_handshake
    self._sslobj.do_handshake()
  File "C:\Program Files\Python311\Lib\ssl.py", line 979, in do_handshake
    self._sslobj.do_handshake()
ssl.SSLCertVerificationError: [SSL: CERTIFICATE_VERIFY_FAILED] certificate verify failed: unable to get local issuer certificate (_ssl.c:1006)

The above exception was the direct cause of the following exception:

Traceback (most recent call last):
  File "C:\Users\oasis\Aibybit_2\src\exchange\bybit_client.py", line 108, in _request
    async with session.get(url, params=request_params, headers=headers) as response:
  File "C:\Users\oasis\Aibybit_2\.venv\Lib\site-packages\aiohttp\client.py", line 1425, in __aenter__
    self._resp: _RetType = await self._coro
                           ^^^^^^^^^^^^^^^^
  File "C:\Users\oasis\Aibybit_2\.venv\Lib\site-packages\aiohttp\client.py", line 703, in _request
    conn = await self._connector.connect(
           ^^^^^^^^^^^^^^^^^^^^^^^^^^^^^^
  File "C:\Users\oasis\Aibybit_2\.venv\Lib\site-packages\aiohttp\connector.py", line 548, in connect
    proto = await self._create_connection(req, traces, timeout)
            ^^^^^^^^^^^^^^^^^^^^^^^^^^^^^^^^^^^^^^^^^^^^^^^^^^^
  File "C:\Users\oasis\Aibybit_2\.venv\Lib\site-packages\aiohttp\connector.py", line 1056, in _create_connection
    _, proto = await self._create_direct_connection(req, traces, timeout)
               ^^^^^^^^^^^^^^^^^^^^^^^^^^^^^^^^^^^^^^^^^^^^^^^^^^^^^^^^^^
  File "C:\Users\oasis\Aibybit_2\.venv\Lib\site-packages\aiohttp\connector.py", line 1411, in _create_direct_connection
    raise last_exc
  File "C:\Users\oasis\Aibybit_2\.venv\Lib\site-packages\aiohttp\connector.py", line 1380, in _create_direct_connection
    transp, proto = await self._wrap_create_connection(
                    ^^^^^^^^^^^^^^^^^^^^^^^^^^^^^^^^^^^
  File "C:\Users\oasis\Aibybit_2\.venv\Lib\site-packages\aiohttp\connector.py", line 1129, in _wrap_create_connection
    raise ClientConnectorCertificateError(req.connection_key, exc) from exc
aiohttp.client_exceptions.ClientConnectorCertificateError: Cannot connect to host api-testnet.bybit.com:443 ssl:True [SSLCertVerificationError: (1, '[SSL: CERTIFICATE_VERIFY_FAILED] certificate verify failed: unable to get local issuer certificate (_ssl.c:1006)')]

2025-02-27 16:00:53,027 - exchange.bybit_client - ERROR - API 요청 실패: Cannot connect to host api-testnet.bybit.com:443 ssl:True [SSLCertVerificationError: (1, '[SSL: CERTIFICATE_VERIFY_FAILED] certificate verify failed: unable to get local issuer certificate (_ssl.c:1006)')]
2025-02-27 16:00:53,031 - exchange.bybit_client - ERROR - Traceback (most recent call last):
  File "C:\Users\oasis\Aibybit_2\.venv\Lib\site-packages\aiohttp\connector.py", line 1123, in _wrap_create_connection
    connection = await self._loop.create_connection(
                 ^^^^^^^^^^^^^^^^^^^^^^^^^^^^^^^^^^^
  File "C:\Program Files\Python311\Lib\asyncio\base_events.py", line 1112, in create_connection
    transport, protocol = await self._create_connection_transport(
                          ^^^^^^^^^^^^^^^^^^^^^^^^^^^^^^^^^^^^^^^^
  File "C:\Program Files\Python311\Lib\asyncio\base_events.py", line 1145, in _create_connection_transport
    await waiter
  File "C:\Program Files\Python311\Lib\asyncio\sslproto.py", line 575, in _on_handshake_complete
    raise handshake_exc
  File "C:\Program Files\Python311\Lib\asyncio\sslproto.py", line 557, in _do_handshake
    self._sslobj.do_handshake()
  File "C:\Program Files\Python311\Lib\ssl.py", line 979, in do_handshake
    self._sslobj.do_handshake()
ssl.SSLCertVerificationError: [SSL: CERTIFICATE_VERIFY_FAILED] certificate verify failed: unable to get local issuer certificate (_ssl.c:1006)

The above exception was the direct cause of the following exception:

Traceback (most recent call last):
  File "C:\Users\oasis\Aibybit_2\src\exchange\bybit_client.py", line 108, in _request
    async with session.get(url, params=request_params, headers=headers) as response:
  File "C:\Users\oasis\Aibybit_2\.venv\Lib\site-packages\aiohttp\client.py", line 1425, in __aenter__
    self._resp: _RetType = await self._coro
                           ^^^^^^^^^^^^^^^^
  File "C:\Users\oasis\Aibybit_2\.venv\Lib\site-packages\aiohttp\client.py", line 703, in _request
    conn = await self._connector.connect(
           ^^^^^^^^^^^^^^^^^^^^^^^^^^^^^^
  File "C:\Users\oasis\Aibybit_2\.venv\Lib\site-packages\aiohttp\connector.py", line 548, in connect
    proto = await self._create_connection(req, traces, timeout)
            ^^^^^^^^^^^^^^^^^^^^^^^^^^^^^^^^^^^^^^^^^^^^^^^^^^^
  File "C:\Users\oasis\Aibybit_2\.venv\Lib\site-packages\aiohttp\connector.py", line 1056, in _create_connection
    _, proto = await self._create_direct_connection(req, traces, timeout)
               ^^^^^^^^^^^^^^^^^^^^^^^^^^^^^^^^^^^^^^^^^^^^^^^^^^^^^^^^^^
  File "C:\Users\oasis\Aibybit_2\.venv\Lib\site-packages\aiohttp\connector.py", line 1411, in _create_direct_connection
    raise last_exc
  File "C:\Users\oasis\Aibybit_2\.venv\Lib\site-packages\aiohttp\connector.py", line 1380, in _create_direct_connection
    transp, proto = await self._wrap_create_connection(
                    ^^^^^^^^^^^^^^^^^^^^^^^^^^^^^^^^^^^
  File "C:\Users\oasis\Aibybit_2\.venv\Lib\site-packages\aiohttp\connector.py", line 1129, in _wrap_create_connection
    raise ClientConnectorCertificateError(req.connection_key, exc) from exc
aiohttp.client_exceptions.ClientConnectorCertificateError: Cannot connect to host api-testnet.bybit.com:443 ssl:True [SSLCertVerificationError: (1, '[SSL: CERTIFICATE_VERIFY_FAILED] certificate verify failed: unable to get local issuer certificate (_ssl.c:1006)')]

2025-02-27 16:00:54,180 - exchange.bybit_client - ERROR - API 요청 실패: Cannot connect to host api-testnet.bybit.com:443 ssl:True [SSLCertVerificationError: (1, '[SSL: CERTIFICATE_VERIFY_FAILED] certificate verify failed: unable to get local issuer certificate (_ssl.c:1006)')]
2025-02-27 16:00:54,184 - exchange.bybit_client - ERROR - Traceback (most recent call last):
  File "C:\Users\oasis\Aibybit_2\.venv\Lib\site-packages\aiohttp\connector.py", line 1123, in _wrap_create_connection
    connection = await self._loop.create_connection(
                 ^^^^^^^^^^^^^^^^^^^^^^^^^^^^^^^^^^^
  File "C:\Program Files\Python311\Lib\asyncio\base_events.py", line 1112, in create_connection
    transport, protocol = await self._create_connection_transport(
                          ^^^^^^^^^^^^^^^^^^^^^^^^^^^^^^^^^^^^^^^^
  File "C:\Program Files\Python311\Lib\asyncio\base_events.py", line 1145, in _create_connection_transport
    await waiter
  File "C:\Program Files\Python311\Lib\asyncio\sslproto.py", line 575, in _on_handshake_complete
    raise handshake_exc
  File "C:\Program Files\Python311\Lib\asyncio\sslproto.py", line 557, in _do_handshake
    self._sslobj.do_handshake()
  File "C:\Program Files\Python311\Lib\ssl.py", line 979, in do_handshake
    self._sslobj.do_handshake()
ssl.SSLCertVerificationError: [SSL: CERTIFICATE_VERIFY_FAILED] certificate verify failed: unable to get local issuer certificate (_ssl.c:1006)

The above exception was the direct cause of the following exception:

Traceback (most recent call last):
  File "C:\Users\oasis\Aibybit_2\src\exchange\bybit_client.py", line 108, in _request
    async with session.get(url, params=request_params, headers=headers) as response:
  File "C:\Users\oasis\Aibybit_2\.venv\Lib\site-packages\aiohttp\client.py", line 1425, in __aenter__
    self._resp: _RetType = await self._coro
                           ^^^^^^^^^^^^^^^^
  File "C:\Users\oasis\Aibybit_2\.venv\Lib\site-packages\aiohttp\client.py", line 703, in _request
    conn = await self._connector.connect(
           ^^^^^^^^^^^^^^^^^^^^^^^^^^^^^^
  File "C:\Users\oasis\Aibybit_2\.venv\Lib\site-packages\aiohttp\connector.py", line 548, in connect
    proto = await self._create_connection(req, traces, timeout)
            ^^^^^^^^^^^^^^^^^^^^^^^^^^^^^^^^^^^^^^^^^^^^^^^^^^^
  File "C:\Users\oasis\Aibybit_2\.venv\Lib\site-packages\aiohttp\connector.py", line 1056, in _create_connection
    _, proto = await self._create_direct_connection(req, traces, timeout)
               ^^^^^^^^^^^^^^^^^^^^^^^^^^^^^^^^^^^^^^^^^^^^^^^^^^^^^^^^^^
  File "C:\Users\oasis\Aibybit_2\.venv\Lib\site-packages\aiohttp\connector.py", line 1411, in _create_direct_connection
    raise last_exc
  File "C:\Users\oasis\Aibybit_2\.venv\Lib\site-packages\aiohttp\connector.py", line 1380, in _create_direct_connection
    transp, proto = await self._wrap_create_connection(
                    ^^^^^^^^^^^^^^^^^^^^^^^^^^^^^^^^^^^
  File "C:\Users\oasis\Aibybit_2\.venv\Lib\site-packages\aiohttp\connector.py", line 1129, in _wrap_create_connection
    raise ClientConnectorCertificateError(req.connection_key, exc) from exc
aiohttp.client_exceptions.ClientConnectorCertificateError: Cannot connect to host api-testnet.bybit.com:443 ssl:True [SSLCertVerificationError: (1, '[SSL: CERTIFICATE_VERIFY_FAILED] certificate verify failed: unable to get local issuer certificate (_ssl.c:1006)')]

