2025-01-01 17:00:26,487 - ai.gpt_client - ERROR - GPT 응답 JSON 파싱 실패: No valid JSON objects found: line 1 column 1 (char 0)
2025-01-01 17:00:26,488 - ai.gpt_client - ERROR - 원본 응답: {
    "market_summary": {
        "market_phase": "상승",
        "overall_sentiment": "긍정적",
        "short_term_sentiment": "중립",
        "risk_level": "중간",
        "volume_trend": "중립",
        "confidence": 80
    },
    "technical_analysis": {
        "trend": "횡보",
        "strength": 50,
        "indicators": {
            "rsi": 50,
            "macd": "하락",
            "bollinger": "중단",
            "divergence": {
                "type": "없음",
                "description": "다이버전스 설명",
                "timeframe": "1h"
            }
        }
    },
    "trading_strategy": {
        "position": "매수",
        "entry_points": [93643.9],
        "targets": [95516.8, 97389.7],
        "stop_loss": 91771.022,
        "leverage": 1,
        "position_size": 1,
    }
}
2025-01-01 17:00:26,493 - telegram_bot.monitors.auto_analyzer - ERROR - 1h 분석 실패
2025-01-01 17:00:51,080 - telegram_bot.monitors.auto_analyzer - ERROR - Final 분석 중 오류: 'GPTAnalyzer' object has no attribute 'run_complete_analysis'
2025-01-01 17:00:51,097 - telegram_bot.monitors.auto_analyzer - ERROR - Traceback (most recent call last):
  File "C:\Users\oasis\Aibybit\src\telegram_bot\monitors\auto_analyzer.py", line 185, in _run_final_analysis
    final_analysis = await self.bot.ai_trader.gpt_analyzer.run_complete_analysis(analyses)
                           ^^^^^^^^^^^^^^^^^^^^^^^^^^^^^^^^^^^^^^^^^^^^^^^^^^^^^
AttributeError: 'GPTAnalyzer' object has no attribute 'run_complete_analysis'

2025-01-01 21:41:57,671 - ai.gpt_analyzer - ERROR - Final 분석 중 오류: GPTAnalyzer._create_final_analysis_prompt() missing 1 required positional argument: 'current_price'
2025-01-01 21:41:57,671 - ai.ai_trader - ERROR - 최종 분석 생성 실패
2025-01-01 21:45:00,164 - ai.gpt_analyzer - ERROR - 15m 분석 중 오류: The truth value of a DataFrame is ambiguous. Use a.empty, a.bool(), a.item(), a.any() or a.all().
2025-01-01 21:45:00,235 - ai.gpt_analyzer - ERROR - Traceback (most recent call last):
  File "C:\Users\oasis\Aibybit\src\ai\gpt_analyzer.py", line 1189, in analyze_market
    if not klines or len(klines) == 0:
           ^^^^^^
  File "C:\Users\oasis\Aibybit\.venv\Lib\site-packages\pandas\core\generic.py", line 1466, in __nonzero__
    raise ValueError(
ValueError: The truth value of a DataFrame is ambiguous. Use a.empty, a.bool(), a.item(), a.any() or a.all().

2025-01-01 21:45:00,236 - telegram_bot.monitors.auto_analyzer - ERROR - 15m 분석 실패
2025-01-01 22:00:00,250 - ai.gpt_analyzer - ERROR - 15m 분석 중 오류: The truth value of a DataFrame is ambiguous. Use a.empty, a.bool(), a.item(), a.any() or a.all().
2025-01-01 22:00:00,252 - ai.gpt_analyzer - ERROR - Traceback (most recent call last):
  File "C:\Users\oasis\Aibybit\src\ai\gpt_analyzer.py", line 1189, in analyze_market
    try:
         
  File "C:\Users\oasis\Aibybit\.venv\Lib\site-packages\pandas\core\generic.py", line 1466, in __nonzero__
    raise ValueError(
ValueError: The truth value of a DataFrame is ambiguous. Use a.empty, a.bool(), a.item(), a.any() or a.all().

2025-01-01 22:00:00,253 - telegram_bot.monitors.auto_analyzer - ERROR - 15m 분석 실패
2025-01-01 22:00:00,391 - ai.gpt_analyzer - ERROR - 1h 분석 중 오류: The truth value of a DataFrame is ambiguous. Use a.empty, a.bool(), a.item(), a.any() or a.all().
2025-01-01 22:00:00,392 - ai.gpt_analyzer - ERROR - Traceback (most recent call last):
  File "C:\Users\oasis\Aibybit\src\ai\gpt_analyzer.py", line 1189, in analyze_market
    try:
         
  File "C:\Users\oasis\Aibybit\.venv\Lib\site-packages\pandas\core\generic.py", line 1466, in __nonzero__
    raise ValueError(
ValueError: The truth value of a DataFrame is ambiguous. Use a.empty, a.bool(), a.item(), a.any() or a.all().

2025-01-01 22:00:00,393 - telegram_bot.monitors.auto_analyzer - ERROR - 1h 분석 실패
2025-01-01 22:03:30,320 - telegram_bot.formatters.storage_formatter - ERROR - 분석 결과 저장 중 오류: Object of type bool_ is not JSON serializable
2025-01-01 22:05:47,782 - telegram_bot.formatters.storage_formatter - ERROR - 분석 결과 로드 중 오류: Expecting value: line 36 column 18 (char 715)
2025-01-01 22:08:02,187 - telegram_bot.bot - ERROR - 메시지 전송 실패: Timed out
2025-01-01 22:08:02,312 - telegram_bot.bot - ERROR - Traceback (most recent call last):
  File "C:\Users\oasis\Aibybit\.venv\Lib\site-packages\httpx\_transports\default.py", line 66, in map_httpcore_exceptions
    yield
  File "C:\Users\oasis\Aibybit\.venv\Lib\site-packages\httpx\_transports\default.py", line 366, in handle_async_request
    resp = await self._pool.handle_async_request(req)
           ^^^^^^^^^^^^^^^^^^^^^^^^^^^^^^^^^^^^^^^^^^
  File "C:\Users\oasis\Aibybit\.venv\Lib\site-packages\httpcore\_async\connection_pool.py", line 256, in handle_async_request
    raise exc from None
  File "C:\Users\oasis\Aibybit\.venv\Lib\site-packages\httpcore\_async\connection_pool.py", line 236, in handle_async_request
    response = await connection.handle_async_request(
               ^^^^^^^^^^^^^^^^^^^^^^^^^^^^^^^^^^^^^^
  File "C:\Users\oasis\Aibybit\.venv\Lib\site-packages\httpcore\_async\connection.py", line 101, in handle_async_request
    raise exc
  File "C:\Users\oasis\Aibybit\.venv\Lib\site-packages\httpcore\_async\connection.py", line 78, in handle_async_request
    stream = await self._connect(request)
             ^^^^^^^^^^^^^^^^^^^^^^^^^^^^
  File "C:\Users\oasis\Aibybit\.venv\Lib\site-packages\httpcore\_async\connection.py", line 156, in _connect
    stream = await stream.start_tls(**kwargs)
             ^^^^^^^^^^^^^^^^^^^^^^^^^^^^^^^^
  File "C:\Users\oasis\Aibybit\.venv\Lib\site-packages\httpcore\_backends\anyio.py", line 67, in start_tls
    with map_exceptions(exc_map):
         ^^^^^^^^^^^^^^^^^^^^^^^
  File "C:\Python312\Lib\contextlib.py", line 158, in __exit__
    self.gen.throw(value)
  File "C:\Users\oasis\Aibybit\.venv\Lib\site-packages\httpcore\_exceptions.py", line 14, in map_exceptions
    raise to_exc(exc) from exc
httpcore.ConnectTimeout

The above exception was the direct cause of the following exception:

Traceback (most recent call last):
  File "C:\Users\oasis\Aibybit\.venv\Lib\site-packages\telegram\request\_httpxrequest.py", line 268, in do_request
    res = await self._client.request(
          ^^^^^^^^^^^^^^^^^^^^^^^^^^^
  File "C:\Users\oasis\Aibybit\.venv\Lib\site-packages\httpx\_client.py", line 1530, in request
    return await self.send(request, auth=auth, follow_redirects=follow_redirects)
           ^^^^^^^^^^^^^^^^^^^^^^^^^^^^^^^^^^^^^^^^^^^^^^^^^^^^^^^^^^^^^^^^^^^^^^
  File "C:\Users\oasis\Aibybit\.venv\Lib\site-packages\httpx\_client.py", line 1617, in send
    response = await self._send_handling_auth(
               ^^^^^^^^^^^^^^^^^^^^^^^^^^^^^^^
  File "C:\Users\oasis\Aibybit\.venv\Lib\site-packages\httpx\_client.py", line 1645, in _send_handling_auth
    response = await self._send_handling_redirects(
               ^^^^^^^^^^^^^^^^^^^^^^^^^^^^^^^^^^^^
  File "C:\Users\oasis\Aibybit\.venv\Lib\site-packages\httpx\_client.py", line 1682, in _send_handling_redirects
    response = await self._send_single_request(request)
               ^^^^^^^^^^^^^^^^^^^^^^^^^^^^^^^^^^^^^^^^
  File "C:\Users\oasis\Aibybit\.venv\Lib\site-packages\httpx\_client.py", line 1719, in _send_single_request
    response = await transport.handle_async_request(request)
               ^^^^^^^^^^^^^^^^^^^^^^^^^^^^^^^^^^^^^^^^^^^^^
  File "C:\Users\oasis\Aibybit\.venv\Lib\site-packages\httpx\_transports\default.py", line 365, in handle_async_request
    with map_httpcore_exceptions():
         ^^^^^^^^^^^^^^^^^^^^^^^^^
  File "C:\Python312\Lib\contextlib.py", line 158, in __exit__
    self.gen.throw(value)
  File "C:\Users\oasis\Aibybit\.venv\Lib\site-packages\httpx\_transports\default.py", line 83, in map_httpcore_exceptions
    raise mapped_exc(message) from exc
httpx.ConnectTimeout

The above exception was the direct cause of the following exception:

Traceback (most recent call last):
  File "C:\Users\oasis\Aibybit\src\telegram_bot\bot.py", line 92, in send_message_to_all
    await self.application.bot.send_message(
  File "C:\Users\oasis\Aibybit\.venv\Lib\site-packages\telegram\ext\_extbot.py", line 2624, in send_message
    return await super().send_message(
           ^^^^^^^^^^^^^^^^^^^^^^^^^^^
  File "C:\Users\oasis\Aibybit\.venv\Lib\site-packages\telegram\_bot.py", line 525, in decorator
    result = await func(self, *args, **kwargs)  # skipcq: PYL-E1102
             ^^^^^^^^^^^^^^^^^^^^^^^^^^^^^^^^^
  File "C:\Users\oasis\Aibybit\.venv\Lib\site-packages\telegram\_bot.py", line 846, in send_message
    return await self._send_message(
           ^^^^^^^^^^^^^^^^^^^^^^^^^
  File "C:\Users\oasis\Aibybit\.venv\Lib\site-packages\telegram\ext\_extbot.py", line 522, in _send_message
    result = await super()._send_message(
             ^^^^^^^^^^^^^^^^^^^^^^^^^^^^
  File "C:\Users\oasis\Aibybit\.venv\Lib\site-packages\telegram\_bot.py", line 703, in _send_message
    result = await self._post(
             ^^^^^^^^^^^^^^^^^
  File "C:\Users\oasis\Aibybit\.venv\Lib\site-packages\telegram\_bot.py", line 613, in _post
    return await self._do_post(
           ^^^^^^^^^^^^^^^^^^^^
  File "C:\Users\oasis\Aibybit\.venv\Lib\site-packages\telegram\ext\_extbot.py", line 340, in _do_post
    return await super()._do_post(
           ^^^^^^^^^^^^^^^^^^^^^^^
  File "C:\Users\oasis\Aibybit\.venv\Lib\site-packages\telegram\_bot.py", line 641, in _do_post
    return await request.post(
           ^^^^^^^^^^^^^^^^^^^
  File "C:\Users\oasis\Aibybit\.venv\Lib\site-packages\telegram\request\_baserequest.py", line 200, in post
    result = await self._request_wrapper(
             ^^^^^^^^^^^^^^^^^^^^^^^^^^^^
  File "C:\Users\oasis\Aibybit\.venv\Lib\site-packages\telegram\request\_baserequest.py", line 340, in _request_wrapper
    raise exc
  File "C:\Users\oasis\Aibybit\.venv\Lib\site-packages\telegram\request\_baserequest.py", line 330, in _request_wrapper
    code, payload = await self.do_request(
                    ^^^^^^^^^^^^^^^^^^^^^^
  File "C:\Users\oasis\Aibybit\.venv\Lib\site-packages\telegram\request\_httpxrequest.py", line 285, in do_request
    raise TimedOut from err
telegram.error.TimedOut: Timed out

2025-01-01 22:13:34,066 - telegram_bot.bot - ERROR - 봇 초기화 중 오류: Timed out
2025-01-01 22:13:34,067 - telegram_bot.bot - ERROR - 봇 초기화 실패
2025-01-01 22:15:00,180 - ai.gpt_analyzer - ERROR - 15m 분석 중 오류: The truth value of a DataFrame is ambiguous. Use a.empty, a.bool(), a.item(), a.any() or a.all().
2025-01-01 22:15:00,199 - ai.gpt_analyzer - ERROR - Traceback (most recent call last):
  File "C:\Users\oasis\Aibybit\src\ai\gpt_analyzer.py", line 1162, in analyze_market
    if not klines or len(klines) == 0:
           ^^^^^^
  File "C:\Users\oasis\Aibybit\.venv\Lib\site-packages\pandas\core\generic.py", line 1466, in __nonzero__
    raise ValueError(
ValueError: The truth value of a DataFrame is ambiguous. Use a.empty, a.bool(), a.item(), a.any() or a.all().

2025-01-01 22:15:00,202 - telegram_bot.monitors.auto_analyzer - ERROR - 15m 분석 실패
2025-01-01 22:19:30,072 - telegram_bot.bot - ERROR - 메시지 전송 실패: Timed out
2025-01-01 22:19:30,100 - telegram_bot.bot - ERROR - Traceback (most recent call last):
  File "C:\Users\oasis\Aibybit\.venv\Lib\site-packages\httpx\_transports\default.py", line 66, in map_httpcore_exceptions
    yield
  File "C:\Users\oasis\Aibybit\.venv\Lib\site-packages\httpx\_transports\default.py", line 366, in handle_async_request
    resp = await self._pool.handle_async_request(req)
           ^^^^^^^^^^^^^^^^^^^^^^^^^^^^^^^^^^^^^^^^^^
  File "C:\Users\oasis\Aibybit\.venv\Lib\site-packages\httpcore\_async\connection_pool.py", line 256, in handle_async_request
    raise exc from None
  File "C:\Users\oasis\Aibybit\.venv\Lib\site-packages\httpcore\_async\connection_pool.py", line 236, in handle_async_request
    response = await connection.handle_async_request(
               ^^^^^^^^^^^^^^^^^^^^^^^^^^^^^^^^^^^^^^
  File "C:\Users\oasis\Aibybit\.venv\Lib\site-packages\httpcore\_async\connection.py", line 101, in handle_async_request
    raise exc
  File "C:\Users\oasis\Aibybit\.venv\Lib\site-packages\httpcore\_async\connection.py", line 78, in handle_async_request
    stream = await self._connect(request)
             ^^^^^^^^^^^^^^^^^^^^^^^^^^^^
  File "C:\Users\oasis\Aibybit\.venv\Lib\site-packages\httpcore\_async\connection.py", line 156, in _connect
    stream = await stream.start_tls(**kwargs)
             ^^^^^^^^^^^^^^^^^^^^^^^^^^^^^^^^
  File "C:\Users\oasis\Aibybit\.venv\Lib\site-packages\httpcore\_backends\anyio.py", line 67, in start_tls
    with map_exceptions(exc_map):
         ^^^^^^^^^^^^^^^^^^^^^^^
  File "C:\Python312\Lib\contextlib.py", line 158, in __exit__
    self.gen.throw(value)
  File "C:\Users\oasis\Aibybit\.venv\Lib\site-packages\httpcore\_exceptions.py", line 14, in map_exceptions
    raise to_exc(exc) from exc
httpcore.ConnectTimeout

The above exception was the direct cause of the following exception:

Traceback (most recent call last):
  File "C:\Users\oasis\Aibybit\.venv\Lib\site-packages\telegram\request\_httpxrequest.py", line 268, in do_request
    res = await self._client.request(
          ^^^^^^^^^^^^^^^^^^^^^^^^^^^
  File "C:\Users\oasis\Aibybit\.venv\Lib\site-packages\httpx\_client.py", line 1530, in request
    return await self.send(request, auth=auth, follow_redirects=follow_redirects)
           ^^^^^^^^^^^^^^^^^^^^^^^^^^^^^^^^^^^^^^^^^^^^^^^^^^^^^^^^^^^^^^^^^^^^^^
  File "C:\Users\oasis\Aibybit\.venv\Lib\site-packages\httpx\_client.py", line 1617, in send
    response = await self._send_handling_auth(
               ^^^^^^^^^^^^^^^^^^^^^^^^^^^^^^^
  File "C:\Users\oasis\Aibybit\.venv\Lib\site-packages\httpx\_client.py", line 1645, in _send_handling_auth
    response = await self._send_handling_redirects(
               ^^^^^^^^^^^^^^^^^^^^^^^^^^^^^^^^^^^^
  File "C:\Users\oasis\Aibybit\.venv\Lib\site-packages\httpx\_client.py", line 1682, in _send_handling_redirects
    response = await self._send_single_request(request)
               ^^^^^^^^^^^^^^^^^^^^^^^^^^^^^^^^^^^^^^^^
  File "C:\Users\oasis\Aibybit\.venv\Lib\site-packages\httpx\_client.py", line 1719, in _send_single_request
    response = await transport.handle_async_request(request)
               ^^^^^^^^^^^^^^^^^^^^^^^^^^^^^^^^^^^^^^^^^^^^^
  File "C:\Users\oasis\Aibybit\.venv\Lib\site-packages\httpx\_transports\default.py", line 365, in handle_async_request
    with map_httpcore_exceptions():
         ^^^^^^^^^^^^^^^^^^^^^^^^^
  File "C:\Python312\Lib\contextlib.py", line 158, in __exit__
    self.gen.throw(value)
  File "C:\Users\oasis\Aibybit\.venv\Lib\site-packages\httpx\_transports\default.py", line 83, in map_httpcore_exceptions
    raise mapped_exc(message) from exc
httpx.ConnectTimeout

The above exception was the direct cause of the following exception:

Traceback (most recent call last):
  File "C:\Users\oasis\Aibybit\src\telegram_bot\bot.py", line 92, in send_message_to_all
    await self.application.bot.send_message(
  File "C:\Users\oasis\Aibybit\.venv\Lib\site-packages\telegram\ext\_extbot.py", line 2624, in send_message
    return await super().send_message(
           ^^^^^^^^^^^^^^^^^^^^^^^^^^^
  File "C:\Users\oasis\Aibybit\.venv\Lib\site-packages\telegram\_bot.py", line 525, in decorator
    result = await func(self, *args, **kwargs)  # skipcq: PYL-E1102
             ^^^^^^^^^^^^^^^^^^^^^^^^^^^^^^^^^
  File "C:\Users\oasis\Aibybit\.venv\Lib\site-packages\telegram\_bot.py", line 846, in send_message
    return await self._send_message(
           ^^^^^^^^^^^^^^^^^^^^^^^^^
  File "C:\Users\oasis\Aibybit\.venv\Lib\site-packages\telegram\ext\_extbot.py", line 522, in _send_message
    result = await super()._send_message(
             ^^^^^^^^^^^^^^^^^^^^^^^^^^^^
  File "C:\Users\oasis\Aibybit\.venv\Lib\site-packages\telegram\_bot.py", line 703, in _send_message
    result = await self._post(
             ^^^^^^^^^^^^^^^^^
  File "C:\Users\oasis\Aibybit\.venv\Lib\site-packages\telegram\_bot.py", line 613, in _post
    return await self._do_post(
           ^^^^^^^^^^^^^^^^^^^^
  File "C:\Users\oasis\Aibybit\.venv\Lib\site-packages\telegram\ext\_extbot.py", line 340, in _do_post
    return await super()._do_post(
           ^^^^^^^^^^^^^^^^^^^^^^^
  File "C:\Users\oasis\Aibybit\.venv\Lib\site-packages\telegram\_bot.py", line 641, in _do_post
    return await request.post(
           ^^^^^^^^^^^^^^^^^^^
  File "C:\Users\oasis\Aibybit\.venv\Lib\site-packages\telegram\request\_baserequest.py", line 200, in post
    result = await self._request_wrapper(
             ^^^^^^^^^^^^^^^^^^^^^^^^^^^^
  File "C:\Users\oasis\Aibybit\.venv\Lib\site-packages\telegram\request\_baserequest.py", line 340, in _request_wrapper
    raise exc
  File "C:\Users\oasis\Aibybit\.venv\Lib\site-packages\telegram\request\_baserequest.py", line 330, in _request_wrapper
    code, payload = await self.do_request(
                    ^^^^^^^^^^^^^^^^^^^^^^
  File "C:\Users\oasis\Aibybit\.venv\Lib\site-packages\telegram\request\_httpxrequest.py", line 285, in do_request
    raise TimedOut from err
telegram.error.TimedOut: Timed out

2025-01-01 23:45:00,314 - ai.gpt_analyzer - ERROR - 15m 분석 중 오류: 'GPTAnalyzer' object has no attribute '_create_interpretation_prompt'
2025-01-01 23:45:00,321 - ai.gpt_analyzer - ERROR - Traceback (most recent call last):
  File "C:\Users\oasis\Aibybit\src\ai\gpt_analyzer.py", line 1139, in analyze_market
    prompt = self._create_interpretation_prompt(df_with_indicators, technical_analysis, timeframe)
             ^^^^^^^^^^^^^^^^^^^^^^^^^^^^^^^^^^
AttributeError: 'GPTAnalyzer' object has no attribute '_create_interpretation_prompt'

2025-01-01 23:45:00,322 - telegram_bot.monitors.auto_analyzer - ERROR - 15m 분석 실패
